<?xml version='1.0' encoding='utf-8'?>
<robot name="revoarm_bimanual">
  
  <link name="world" />
  <link name="base_link">
    <inertial>
      <origin rpy="0 0 0" xyz="0.003663696599180355 -2.5667316999566106e-05 -0.6401483469000036" />
      <mass value="20.9229828634" />
      <inertia ixx="3.135500820935042" ixy="-2.2016142207388786e-05" ixz="-0.012267440867817107" iyy="3.1336352549313173" iyz="8.210944641820494e-05" izz="0.3525207926744888" />
    </inertial>
    <visual>
      <origin rpy="0 0 0" xyz="0 0 0" />
      <geometry>
        <mesh filename="../meshes/body/visual/bimanual/base_link.STL" />
      </geometry>
      <material name="">
        <color rgba="0.054902 0.054902 0.054902 1" />
      </material>
    </visual>
    <collision>
      <origin rpy="0 0 0" xyz="0 0 0" />
      <geometry>
        <mesh filename="../meshes/body/collision/bimanual/base_link.STL" />
      </geometry>
    </collision>
  </link>
  <joint name="world_to_base_joint" type="fixed">
    <parent link="world" />
    <child link="base_link" />
    <origin rpy="0 0 0" xyz="0 0 0" />
  </joint>
  <joint name="left_base_joint" type="fixed">
    <parent link="base_link" />
    <child link="left_base_link" />
    <origin rpy="0.17453 0 0" xyz="0.0055 0.10424 -0.038037" />
  </joint>
  <link name="left_base_link" />
  <link name="left_arm_link1">
    <inertial>
      <origin rpy="0 0 0" xyz="0.0014558952417556832 0.052716571861716806 -0.0012746925369990579" />
      <mass value="0.99862" />
      <inertia ixx="0.0013455582136954168" ixy="-7.831531833443126e-06" ixz="-1.1584640844290234e-06" iyy="0.0008358775975363909" iyz="-5.1116974592436684e-05" izz="0.0010339431564673298" />
    </inertial>
    <visual>
      <origin rpy="0 0 0" xyz="0 0 0" />
      <geometry>
        <mesh filename="../meshes/arm/visual/left_arm_link1.STL" />
      </geometry>
      <material name="">
        <color rgba="1 1 1 1" />
      </material>
    </visual>
    <collision>
      <origin rpy="0 0 0" xyz="0 0 0" />
      <geometry>
        <mesh filename="../meshes/arm/collision/left_arm_link1.STL" />
      </geometry>
    </collision>
  </link>
  <joint name="revoarm_left_joint1" type="revolute">
    <origin rpy="0 0.0 0" xyz="0 0 0" />
    <parent link="left_base_link" />
    <child link="left_arm_link1" />
    <axis xyz="0 1 0" />
    <limit effort="40" lower="-4.1015" upper="0.7854" velocity="2.792" />
  </joint>
  <link name="left_arm_link2">
    <inertial>
      <origin rpy="0 0 0" xyz="0.0003522335464279825 0.00038005451984361304 -0.027671836967634263" />
      <mass value="0.1942" />
      <inertia ixx="0.00037984612194445115" ixy="-1.4630943049862306e-06" ixz="1.603119961015182e-06" iyy="0.00036786946654754907" iyz="1.582395907574811e-06" izz="0.0002084532432667245" />
    </inertial>
    <visual>
      <origin rpy="0 0 0" xyz="0 0 0" />
      <geometry>
        <mesh filename="../meshes/arm/visual/left_arm_link2.STL" />
      </geometry>
      <material name="">
        <color rgba="1 1 1 1" />
      </material>
    </visual>
    <collision>
      <origin rpy="0 0 0" xyz="0 0 0" />
      <geometry>
        <mesh filename="../meshes/arm/collision/left_arm_link2.STL" />
      </geometry>
    </collision>
  </link>
  <joint name="revoarm_left_joint2" type="revolute">
    <origin rpy="-0.17453 0 0" xyz="0 0.06 0" />
    <parent link="left_arm_link1" />
    <child link="left_arm_link2" />
    <axis xyz="1 0 0" />
    <limit effort="40" lower="-0.1745" upper="3.3161" velocity="2.792" />
  </joint>
  <link name="left_arm_link3">
    <inertial>
      <origin rpy="0 0 0" xyz="-0.00038856719925421814 -1.856841337962366e-05 -0.0669511733195832" />
      <mass value="0.56897" />
      <inertia ixx="0.001347024509553418" ixy="3.824029645136789e-07" ixz="-1.080913497188802e-05" iyy="0.0013183781004236497" iyz="4.508896464373414e-07" izz="0.0004885001058002036" />
    </inertial>
    <visual>
      <origin rpy="0 0 0" xyz="0 0 0" />
      <geometry>
        <mesh filename="../meshes/arm/visual/left_arm_link3.STL" />
      </geometry>
      <material name="">
        <color rgba="1 1 1 1" />
      </material>
    </visual>
    <collision>
      <origin rpy="0 0 0" xyz="0 0 0" />
      <geometry>
        <mesh filename="../meshes/arm/collision/left_arm_link3.STL" />
      </geometry>
    </collision>
  </link>
  <joint name="revoarm_left_joint3" type="revolute">
    <origin rpy="0 0 0.0" xyz="0 0 -0.099" />
    <parent link="left_arm_link2" />
    <child link="left_arm_link3" />
    <axis xyz="0 0 -1" />
    <limit effort="27" lower="-3.6652" upper="0.5236" velocity="1.745" />
  </joint>
  <link name="left_arm_link4">
    <inertial>
      <origin rpy="0 0 0" xyz="-9.928907268251463e-05 -0.00035402152400401 -0.025368403210649232" />
      <mass value="0.43039" />
      <inertia ixx="0.0004717793537881475" ixy="-1.2442902049896903e-07" ixz="-7.688576107641954e-07" iyy="0.00047406778201506214" iyz="2.5261136738388584e-06" izz="0.00027664775194187767" />
    </inertial>
    <visual>
      <origin rpy="0 0 0" xyz="0 0 0" />
      <geometry>
        <mesh filename="../meshes/arm/visual/left_arm_link4.STL" />
      </geometry>
      <material name="">
        <color rgba="1 1 1 1" />
      </material>
    </visual>
    <collision>
      <origin rpy="0 0 0" xyz="0 0 0" />
      <geometry>
        <mesh filename="../meshes/arm/collision/left_arm_link4.STL" />
      </geometry>
    </collision>
  </link>
  <joint name="revoarm_left_joint4" type="revolute">
    <origin rpy="0 0.0 0" xyz="0 0 -0.121" />
    <parent link="left_arm_link3" />
    <child link="left_arm_link4" />
    <axis xyz="0 -1 0" />
    <limit effort="27" lower="-0.34907" upper="2.2166" velocity="1.745" />
  </joint>
  <link name="left_arm_link5">
    <inertial>
      <origin rpy="0 0 0" xyz="0.0009273109394114897 -0.00014084089093363534 -0.07442692427006262" />
      <mass value="0.80969" />
      <inertia ixx="0.0018262186167409072" ixy="1.4279441393496652e-08" ixz="2.781229306841082e-05" iyy="0.0018338945560489519" iyz="-2.8548278354889502e-06" izz="0.0005616240442547082" />
    </inertial>
    <visual>
      <origin rpy="0 0 0" xyz="0 0 0" />
      <geometry>
        <mesh filename="../meshes/arm/visual/left_arm_link5.STL" />
      </geometry>
      <material name="">
        <color rgba="1 1 1 1" />
      </material>
    </visual>
    <collision>
      <origin rpy="0 0 0" xyz="0 0 0" />
      <geometry>
        <mesh filename="../meshes/arm/collision/left_arm_link5.STL" />
      </geometry>
    </collision>
  </link>
  <joint name="revoarm_left_joint5" type="revolute">
    <origin rpy="0 0 0.0" xyz="0 0 -0.0635" />
    <parent link="left_arm_link4" />
    <child link="left_arm_link5" />
    <axis xyz="0 0 -1" />
    <limit effort="7" lower="-3.1444" upper="0.9044" velocity="6.98" />
  </joint>
  <link name="left_arm_link6">
    <inertial>
      <origin rpy="0 0 0" xyz="0.0001405267991875142 -0.001049427241263535 -2.2489628719575287e-05" />
      <mass value="0.31466" />
      <inertia ixx="0.00012100842021227848" ixy="-2.1489023911950789e-07" ixz="-6.95891723798596e-08" iyy="0.00013672911934102953" iyz="-2.010668451920477e-07" izz="0.00013781623418694094" />
    </inertial>
    <visual>
      <origin rpy="0 0 0" xyz="0 0 0" />
      <geometry>
        <mesh filename="../meshes/arm/visual/left_arm_link6.STL" />
      </geometry>
      <material name="">
        <color rgba="1 1 1 1" />
      </material>
    </visual>
    <collision>
      <origin rpy="0 0 0" xyz="0 0 0" />
      <geometry>
        <mesh filename="../meshes/arm/collision/left_arm_link6.STL" />
      </geometry>
    </collision>
  </link>
  <joint name="revoarm_left_joint6" type="revolute">
    <origin rpy="0.0 0 0" xyz="0 0 -0.1525" />
    <parent link="left_arm_link5" />
    <child link="left_arm_link6" />
    <axis xyz="-1 0 0" />
    <limit effort="7" lower="-0.64577" upper="0.64577" velocity="6.98" />
  </joint>
  
  <link name="left_arm_link7">
    <inertial>
      <origin rpy="0 0 0" xyz="0 0 0" />
      <mass value="0.0" />
      <inertia ixx="1e-09" ixy="0" ixz="0" iyy="1e-09" iyz="0" izz="1e-09" />
    </inertial>
  </link>
  <joint name="revoarm_left_joint7" type="revolute">
    <origin rpy="-0.0019404 0.0 0" xyz="0 0 0" />
    <parent link="left_arm_link6" />
    <child link="left_arm_link7" />
    <axis xyz="0 -1 0" />
    <limit effort="7" lower="-1.5708" upper="1.5708" velocity="6.98" />
  </joint>
  <joint name="right_base_joint" type="fixed">
    <parent link="base_link" />
    <child link="right_base_link" />
    <origin rpy="-0.17453 0 0" xyz="0.0055 -0.10424 -0.038037" />
  </joint>
  <link name="right_base_link" />
  <link name="right_arm_link1">
    <inertial>
      <origin rpy="0 0 0" xyz="0.001382612465367731 -0.052712342946782335 -0.0012165214801131664" />
      <mass value="0.99862" />
      <inertia ixx="0.0013454491322157436" ixy="9.357367309461081e-06" ixz="3.478204709148893e-07" iyy="0.0008341355869281277" iyz="4.903673631863885e-05" izz="0.0010334387005480317" />
    </inertial>
    <visual>
      <origin rpy="0 0 0" xyz="0 0 0" />
      <geometry>
        <mesh filename="../meshes/arm/visual/right_arm_link1.STL" />
      </geometry>
      <material name="">
        <color rgba="1 1 1 1" />
      </material>
    </visual>
    <collision>
      <origin rpy="0 0 0" xyz="0 0 0" />
      <geometry>
        <mesh filename="../meshes/arm/collision/right_arm_link1.STL" />
      </geometry>
    </collision>
  </link>
  <joint name="revoarm_right_joint1" type="revolute">
    <origin rpy="0 0.0 0" xyz="0 0 0" />
    <parent link="right_base_link" />
    <child link="right_arm_link1" />
    <axis xyz="0 1 0" />
    <limit effort="40" lower="-4.1015" upper="0.7854" velocity="2.792" />
  </joint>
  <link name="right_arm_link2">
    <inertial>
      <origin rpy="0 0 0" xyz="5.452832766175412e-06 -0.00028243118094375947 -0.026891342134806036" />
      <mass value="0.1942" />
      <inertia ixx="0.0003826255144247354" ixy="9.486795520508637e-07" ixz="-2.1848535528029543e-06" iyy="0.0003692337436614689" iyz="2.313823793144637e-06" izz="0.00020728050191330547" />
    </inertial>
    <visual>
      <origin rpy="0 0 0" xyz="0 0 0" />
      <geometry>
        <mesh filename="../meshes/arm/visual/right_arm_link2.STL" />
      </geometry>
      <material name="">
        <color rgba="1 1 1 1" />
      </material>
    </visual>
    <collision>
      <origin rpy="0 0 0" xyz="0 0 0" />
      <geometry>
        <mesh filename="../meshes/arm/collision/right_arm_link2.STL" />
      </geometry>
    </collision>
  </link>
  <joint name="revoarm_right_joint2" type="revolute">
    <origin rpy="0.17453 0 0" xyz="0 -0.06 0" />
    <parent link="right_arm_link1" />
    <child link="right_arm_link2" />
    <axis xyz="-1 0 0" />
    <limit effort="40" lower="-0.1745" upper="3.3161" velocity="2.792" />
  </joint>
  <link name="right_arm_link3">
    <inertial>
      <origin rpy="0 0 0" xyz="-0.0004545696147919951 3.124497872877622e-05 -0.06669396716612074" />
      <mass value="0.56897" />
      <inertia ixx="0.001342436554031375" ixy="-1.1015969569091774e-06" ixz="-8.986727133401938e-06" iyy="0.0013131089829151352" iyz="1.8766376444528735e-06" izz="0.0004921543202930038" />
    </inertial>
    <visual>
      <origin rpy="0 0 0" xyz="0 0 0" />
      <geometry>
        <mesh filename="../meshes/arm/visual/right_arm_link3.STL" />
      </geometry>
      <material name="">
        <color rgba="1 1 1 1" />
      </material>
    </visual>
    <collision>
      <origin rpy="0 0 0" xyz="0 0 0" />
      <geometry>
        <mesh filename="../meshes/arm/collision/right_arm_link3.STL" />
      </geometry>
    </collision>
  </link>
  <joint name="revoarm_right_joint3" type="revolute">
    <origin rpy="0 0 0.0" xyz="0 0 -0.099" />
    <parent link="right_arm_link2" />
    <child link="right_arm_link3" />
    <axis xyz="0 0 1" />
    <limit effort="27" lower="-3.6652" upper="0.5236" velocity="1.745" />
  </joint>
  <link name="right_arm_link4">
    <inertial>
      <origin rpy="0 0 0" xyz="-7.585570779113467e-06 0.0003510704511493275 -0.02538448707879066" />
      <mass value="0.43039" />
      <inertia ixx="0.00047306084260980287" ixy="1.3323690129685178e-07" ixz="-1.0905992016120662e-06" iyy="0.00047377939083966165" iyz="-2.6711329620963666e-06" izz="0.0002759998800131494" />
    </inertial>
    <visual>
      <origin rpy="0 0 0" xyz="0 0 0" />
      <geometry>
        <mesh filename="../meshes/arm/visual/right_arm_link4.STL" />
      </geometry>
      <material name="">
        <color rgba="1 1 1 1" />
      </material>
    </visual>
    <collision>
      <origin rpy="0 0 0" xyz="0 0 0" />
      <geometry>
        <mesh filename="../meshes/arm/collision/right_arm_link4.STL" />
      </geometry>
    </collision>
  </link>
  <joint name="revoarm_right_joint4" type="revolute">
    <origin rpy="0 0.0 0" xyz="0 0 -0.121" />
    <parent link="right_arm_link3" />
    <child link="right_arm_link4" />
    <axis xyz="0 -1 0" />
    <limit effort="27" lower="-0.34907" upper="2.2166" velocity="1.745" />
  </joint>
  <link name="right_arm_link5">
    <inertial>
      <origin rpy="0 0 0" xyz="0.0009150768289936717 1.834968667242696e-05 -0.07514702828445248" />
      <mass value="0.80969" />
      <inertia ixx="0.001829311510089025" ixy="9.374941322173225e-07" ixz="3.673713321385765e-05" iyy="0.0018345098956241942" iyz="-1.6270176108032502e-06" izz="0.000560869910640031" />
    </inertial>
    <visual>
      <origin rpy="0 0 0" xyz="0 0 0" />
      <geometry>
        <mesh filename="../meshes/arm/visual/right_arm_link5.STL" />
      </geometry>
      <material name="">
        <color rgba="1 1 1 1" />
      </material>
    </visual>
    <collision>
      <origin rpy="0 0 0" xyz="0 0 0" />
      <geometry>
        <mesh filename="../meshes/arm/collision/right_arm_link5.STL" />
      </geometry>
    </collision>
  </link>
  <joint name="revoarm_right_joint5" type="revolute">
    <origin rpy="0 0 0.0" xyz="0 0 -0.0635" />
    <parent link="right_arm_link4" />
    <child link="right_arm_link5" />
    <axis xyz="0 0 1" />
    <limit effort="7" lower="-3.1444" upper="0.9044" velocity="6.98" />
  </joint>
  <link name="right_arm_link6">
    <inertial>
      <origin rpy="0 0 0" xyz="0.00017945944403328923 0.0010005698320528372 -2.47524159457321e-05" />
      <mass value="0.31466" />
      <inertia ixx="0.00012089545378700789" ixy="2.385592039940795e-07" ixz="-7.17472862339045e-08" iyy="0.00013671438156731276" iyz="2.583665322590944e-07" izz="0.00013749574401418263" />
    </inertial>
    <visual>
      <origin rpy="0 0 0" xyz="0 0 0" />
      <geometry>
        <mesh filename="../meshes/arm/visual/right_arm_link6.STL" />
      </geometry>
      <material name="">
        <color rgba="1 1 1 1" />
      </material>
    </visual>
    <collision>
      <origin rpy="0 0 0" xyz="0 0 0" />
      <geometry>
        <mesh filename="../meshes/arm/collision/right_arm_link6.STL" />
      </geometry>
    </collision>
  </link>
  <joint name="revoarm_right_joint6" type="revolute">
    <origin rpy="0.0 0 0" xyz="0 0 -0.1525" />
    <parent link="right_arm_link5" />
    <child link="right_arm_link6" />
    <axis xyz="1 0 0" />
    <limit effort="7" lower="-0.64577" upper="0.64577" velocity="6.98" />
  </joint>
  
  <link name="right_arm_link7">
    <inertial>
      <origin rpy="0 0 0" xyz="0 0 0" />
      <mass value="0.0" />
      <inertia ixx="1e-09" ixy="0" ixz="0" iyy="1e-09" iyz="0" izz="1e-09" />
    </inertial>
  </link>
  <joint name="revoarm_right_joint7" type="revolute">
    <origin rpy="0.0019404 0.0 0" xyz="0 0 0" />
    <parent link="right_arm_link6" />
    <child link="right_arm_link7" />
    <axis xyz="0 -1 0" />
    <limit effort="7" lower="-1.5708" upper="1.5708" velocity="6.98" />
  </joint>
  
  <link name="left_connector_link">
    <inertial>
      <origin rpy="0 0 0" xyz="0.005118745362621232 0.0006367060365849771 -0.02674019826311511" />
      <mass value="0.49311" />
      <inertia ixx="0.00022442378409980932" ixy="4.1874361256991135e-06" ixz="6.488777698062572e-06" iyy="0.00029604403831446697" iyz="1.527999228564945e-05" izz="0.00020292508000928854" />
    </inertial>
    <visual>
      <origin rpy="0 0 0" xyz="0 0 0" />
      <geometry>
        <mesh filename="../meshes/connector/visual/left_revo2_connector.STL" />
      </geometry>
      <material name="">
        <color rgba="1.0 1.0 1.0 1.0" />
      </material>
    </visual>
    <collision>
      <origin rpy="0 0 0" xyz="0 0 0" />
      <geometry>
        <mesh filename="../meshes/connector/collision/left_revo2_connector.STL" />
      </geometry>
    </collision>
  </link>
  
  <joint name="left_connector_mount" type="fixed">
    <parent link="left_arm_link7" />
    <child link="left_connector_link" />
    <origin rpy="0 0 1.57" xyz="0 0 0" />
  </joint>
  
  <link name="left_connector_tip" />
  <joint name="left_connector_tip_joint" type="fixed">
    <parent link="left_connector_link" />
    <child link="left_connector_tip" />
    <origin rpy="0 3.14 -1.57" xyz="0.0000760 0.0001518 -0.0583" />
  </joint>
  
  <link name="right_connector_link">
    <inertial>
      <origin rpy="0 0 0" xyz="0.006302578116043444 -0.0034524031603394146 -0.02289223897323043" />
      <mass value="0.49311" />
      <inertia ixx="0.0002581914309571239" ixy="-2.802399391661571e-05" ixz="-1.0055594117070554e-05" iyy="0.0003077591971214832" iyz="-1.2780164528904748e-05" izz="0.00016268151583133218" />
    </inertial>
    <visual>
      <origin rpy="0 0 0" xyz="0 0 0" />
      <geometry>
        <mesh filename="../meshes/connector/visual/right_revo2_connector.STL" />
      </geometry>
      <material name="">
        <color rgba="1.0 1.0 1.0 1.0" />
      </material>
    </visual>
    <collision>
      <origin rpy="0 0 0" xyz="0 0 0" />
      <geometry>
        <mesh filename="../meshes/connector/collision/right_revo2_connector.STL" />
      </geometry>
    </collision>
  </link>
  
  <joint name="right_connector_mount" type="fixed">
    <parent link="right_arm_link7" />
    <child link="right_connector_link" />
    <origin rpy="0 0 -1.57" xyz="0 0 0" />
  </joint>
  
  <link name="right_connector_tip" />
  <joint name="right_connector_tip_joint" type="fixed">
    <parent link="right_connector_link" />
    <child link="right_connector_tip" />
    <origin rpy="0 3.14 1.57" xyz="0.0000760 -0.0001518 -0.0583" />
  </joint>
  
  <joint name="left_hand_base_joint" type="fixed">
    <parent link="left_connector_tip" />
    <child link="left_hand_base_link" />
    <origin rpy="0 0 0" xyz="0 0 -0.0118" />
  </joint>
  <link name="left_hand_base_link">
    <inertial>
      <origin rpy="0 0 0" xyz="-0.0050069196557942898 0.0031951498725952578 0.044048985017541092" />
      <mass value="0.23799999999999999" />
      <inertia ixx="0.00021243703191569629" ixy="-2.160578998863694e-06" ixz="3.6168810917662211e-06" iyy="0.00016014308936489096" iyz="1.2241686067591412e-05" izz="7.7420062865293511e-05" />
    </inertial>
    <visual>
      <origin rpy="0 0 0" xyz="0 0 0" />
      <geometry>
        <mesh filename="../meshes/hands/visual/left/left_base_link.STL" />
      </geometry>
      <material name="">
        <color rgba="1 1 1 1" />
      </material>
    </visual>
    <visual>
      <origin rpy="0 0 0" xyz="0 0 0" />
      <geometry>
        <mesh filename="../meshes/hands/visual/left/left_base_visual_link.STL" />
      </geometry>
      <material name="">
        <color rgba="1 1 1 1" />
      </material>
    </visual>
    <collision>
      <origin rpy="0 0 0" xyz="0 0 0" />
      <geometry>
        <mesh filename="../meshes/hands/collision/left/left_base_link.STL" />
      </geometry>
    </collision>
  </link>
  <link name="left_thumb_metacarpal_link">
    <inertial>
      <origin rpy="0 0 0" xyz="5.2448120648044896e-05 -0.0064127113564924525 -0.0038999285548428604" />
      <mass value="0.01" />
      <inertia ixx="1.0391374023389509e-06" ixy="2.6878105173942598e-08" ixz="3.1994739840723345e-09" iyy="9.9133648861034965e-07" iyz="8.0715388563913015e-08" izz="3.2287162991569446e-07" />
    </inertial>
    <visual>
      <origin rpy="0 0 0" xyz="0 0 0" />
      <geometry>
        <mesh filename="../meshes/hands/visual/left/left_thumb_metacarpal_link.STL" />
      </geometry>
      <material name="">
        <color rgba="1 1 1 1" />
      </material>
    </visual>
    <collision>
      <origin rpy="0 0 0" xyz="0 0 0" />
      <geometry>
        <mesh filename="../meshes/hands/collision/left/left_thumb_metacarpal_link.STL" />
      </geometry>
    </collision>
  </link>
  <joint name="left_thumb_metacarpal_joint" type="revolute">
    <origin rpy="0 0 0.16787" xyz="0.0045 -0.019 0.027825" />
    <parent link="left_hand_base_link" />
    <child link="left_thumb_metacarpal_link" />
    <axis xyz="0 0 1" />
    <limit effort="0.5" lower="0" upper="1.57" velocity="2.6175" />
  </joint>
  <link name="left_thumb_proximal_link">
    <inertial>
      <origin rpy="0 0 0" xyz="-5.3592746671882903e-07 -0.027910209963501159 -0.0021690604228547681" />
      <mass value="0.050000000000000003" />
      <inertia ixx="1.1041485159004667e-05" ixy="0" ixz="0" iyy="1.7787677179094888e-06" iyz="-2.7574629630040948e-08" izz="1.1565614290883625e-05" />
    </inertial>
    <visual>
      <origin rpy="0 0 0" xyz="0 0 0" />
      <geometry>
        <mesh filename="../meshes/hands/visual/left/left_thumb_proximal_link.STL" />
      </geometry>
      <material name="">
        <color rgba="1 1 1 1" />
      </material>
    </visual>
    <visual>
      <origin rpy="0 0 0" xyz="0 0 0" />
      <geometry>
        <mesh filename="../meshes/hands/visual/left/left_thumb_proximal_visual_link.STL" />
      </geometry>
      <material name="">
        <color rgba="1 1 1 1" />
      </material>
    </visual>
    <collision>
      <origin rpy="0 0 0" xyz="0 0 0" />
      <geometry>
        <mesh filename="../meshes/hands/collision/left/left_thumb_proximal_link.STL" />
      </geometry>
    </collision>
  </link>
  <joint name="left_thumb_proximal_joint" type="revolute">
    <origin rpy="-0.17488 0.23736 -0.16787" xyz="0 -0.014227 0" />
    <parent link="left_thumb_metacarpal_link" />
    <child link="left_thumb_proximal_link" />
    <axis xyz="-1 0 0" />
    <limit effort="1.1" lower="0" upper="1.03" velocity="2.5303" />
  </joint>
  <link name="left_thumb_distal_link">
    <inertial>
      <origin rpy="0 0 0" xyz="-9.3250353421736472e-07 -0.0092216958166139763 -0.0022464414712281789" />
      <mass value="0.01" />
      <inertia ixx="4.53439708081094e-07" ixy="0" ixz="0" iyy="2.6101216224350947e-07" iyz="-1.20090505524035e-08" izz="5.2010076079456636e-07" />
    </inertial>
    <visual>
      <origin rpy="0 0 0" xyz="0 0 0" />
      <geometry>
        <mesh filename="../meshes/hands/visual/left/left_thumb_distal_link.STL" />
      </geometry>
      <material name="">
        <color rgba="1 1 1 1" />
      </material>
    </visual>
    <collision>
      <origin rpy="0 0 0" xyz="0 0 0" />
      <geometry>
        <mesh filename="../meshes/hands/collision/left/left_thumb_distal_link.STL" />
      </geometry>
    </collision>
  </link>
  <joint name="left_thumb_distal_joint" type="revolute">
    <origin rpy="0 0 0" xyz="0 -0.052 0" />
    <parent link="left_thumb_proximal_link" />
    <child link="left_thumb_distal_link" />
    <axis xyz="-1 0 0" />
    <limit effort="1.1" lower="0" upper="1.03" velocity="2.5303" />
    <mimic joint="left_thumb_proximal_joint" multiplier="1" offset="0" />
  </joint>
  <link name="left_thumb_tip_link">
    </link>
  <joint name="left_thumb_tip_joint" type="fixed">
    <origin rpy="0.06675 0 0" xyz="0 -0.026529 -0.0017734" />
    <parent link="left_thumb_distal_link" />
    <child link="left_thumb_tip_link" />
    <axis xyz="0 0 0" />
  </joint>
  <link name="left_thumb_touch_link">
    <inertial>
      <origin rpy="0 0 0" xyz="-5.5105603595396999e-07 -0.0015679769969614223 -0.0056888113918425586" />
      <mass value="0.002" />
      <inertia ixx="6.9337608696321383e-08" ixy="0" ixz="0" iyy="5.6838789495101113e-08" iyz="-3.5148755380579443e-09" izz="1.0288222773007187e-07" />
    </inertial>
    <visual>
      <origin rpy="0 0 0" xyz="0 0 0" />
      <geometry>
        <mesh filename="../meshes/hands/visual/left/left_thumb_touch_link.STL" />
      </geometry>
      <material name="">
        <color rgba="1 1 1 1" />
      </material>
    </visual>
    <collision>
      <origin rpy="0 0 0" xyz="0 0 0" />
      <geometry>
        <mesh filename="../meshes/hands/collision/left/left_thumb_touch_link.STL" />
      </geometry>
    </collision>
  </link>
  <joint name="left_thumb_touch_joint" type="fixed">
    <origin rpy="0.17488 0 0" xyz="0 -0.013836 0.0076686" />
    <parent link="left_thumb_distal_link" />
    <child link="left_thumb_touch_link" />
    <axis xyz="0 0 0" />
  </joint>
  <link name="left_index_proximal_link">
    <inertial>
      <origin rpy="0 0 0" xyz="-0.0021095762185109556 -1.0018489057074859e-06 0.017433891986291937" />
      <mass value="0.0089999999999999993" />
      <inertia ixx="8.0725407014471423e-07" ixy="0" ixz="-1.8489857513645255e-08" iyy="7.6517802541226111e-07" iyz="0" izz="2.7130906026168039e-07" />
    </inertial>
    <visual>
      <origin rpy="0 0 0" xyz="0 0 0" />
      <geometry>
        <mesh filename="../meshes/hands/visual/left/left_index_proximal_link.STL" />
      </geometry>
      <material name="">
        <color rgba="1 1 1 1" />
      </material>
    </visual>
    <collision>
      <origin rpy="0 0 0" xyz="0 0 0" />
      <geometry>
        <mesh filename="../meshes/hands/collision/left/left_index_proximal_link.STL" />
      </geometry>
    </collision>
  </link>
  <joint name="left_index_proximal_joint" type="revolute">
    <origin rpy="0.11819 0.14743 0.17422" xyz="-0.0021349 -0.029578 0.080876" />
    <parent link="left_hand_base_link" />
    <child link="left_index_proximal_link" />
    <axis xyz="0 1 0" />
    <limit effort="2" lower="0" upper="1.41" velocity="2.2685" />
  </joint>
  <link name="left_index_distal_link">
    <inertial>
      <origin rpy="0 0 0" xyz="0.0034973861673681678 -8.6913011917289015e-08 0.014024367479174444" />
      <mass value="0.0089999999999999993" />
      <inertia ixx="9.573382382798683e-07" ixy="0" ixz="-2.9240822964098857e-07" iyy="1.0538009354304963e-06" iyz="0" izz="2.4208109624630676e-07" />
    </inertial>
    <visual>
      <origin rpy="0 0 0" xyz="0 0 0" />
      <geometry>
        <mesh filename="../meshes/hands/visual/left/left_index_distal_link.STL" />
      </geometry>
      <material name="">
        <color rgba="1 1 1 1" />
      </material>
    </visual>
    <collision>
      <origin rpy="0 0 0" xyz="0 0 0" />
      <geometry>
        <mesh filename="../meshes/hands/collision/left/left_index_distal_link.STL" />
      </geometry>
    </collision>
  </link>
  <joint name="left_index_distal_joint" type="revolute">
    <origin rpy="0 0 0" xyz="0 0 0.032" />
    <parent link="left_index_proximal_link" />
    <child link="left_index_distal_link" />
    <axis xyz="0 1 0" />
    <limit effort="2" lower="0" upper="1.63" velocity="2.2685" />
    <mimic joint="left_index_proximal_joint" multiplier="1.155" offset="0" />
  </joint>
  <link name="left_index_tip_link">
    </link>
  <joint name="left_index_tip_joint" type="fixed">
    <origin rpy="0 0.48723 0" xyz="0.011097 0 0.035739" />
    <parent link="left_index_distal_link" />
    <child link="left_index_tip_link" />
    <axis xyz="0 0 0" />
  </joint>
  <link name="left_index_touch_link">
    <inertial>
      <origin rpy="0 0 0" xyz="-0.0030756425070118062 -3.9046886263805012e-08 0.0026249048738638684" />
      <mass value="0.002" />
      <inertia ixx="3.6524673961438282e-08" ixy="0" ixz="8.6063395532046128e-09" iyy="2.9796812970068342e-08" iyz="0" izz="1.721545025385639e-08" />
    </inertial>
    <visual>
      <origin rpy="0 0 0" xyz="0 0 0" />
      <geometry>
        <mesh filename="../meshes/hands/visual/left/left_index_touch_link.STL" />
      </geometry>
      <material name="">
        <color rgba="1 1 1 1" />
      </material>
    </visual>
    <collision>
      <origin rpy="0 0 0" xyz="0 0 0" />
      <geometry>
        <mesh filename="../meshes/hands/collision/left/left_index_touch_link.STL" />
      </geometry>
    </collision>
  </link>
  <joint name="left_index_touch_joint" type="fixed">
    <origin rpy="0 0.4756 0" xyz="0.014497 0 0.023303" />
    <parent link="left_index_distal_link" />
    <child link="left_index_touch_link" />
    <axis xyz="0 0 0" />
  </joint>
  <link name="left_middle_proximal_link">
    <inertial>
      <origin rpy="0 0 0" xyz="-0.0021463337350766396 -1.4625211059774783e-06 0.020086308617024221" />
      <mass value="0.0089999999999999993" />
      <inertia ixx="9.948385373762115e-07" ixy="0" ixz="-2.4771872948759328e-08" iyy="9.6305285606291445e-07" iyz="0" izz="2.7511820938354049e-07" />
    </inertial>
    <visual>
      <origin rpy="0 0 0" xyz="0 0 0" />
      <geometry>
        <mesh filename="../meshes/hands/visual/left/left_middle_proximal_link.STL" />
      </geometry>
      <material name="">
        <color rgba="1 1 1 1" />
      </material>
    </visual>
    <collision>
      <origin rpy="0 0 0" xyz="0 0 0" />
      <geometry>
        <mesh filename="../meshes/hands/collision/left/left_middle_proximal_link.STL" />
      </geometry>
    </collision>
  </link>
  <joint name="left_middle_proximal_joint" type="revolute">
    <origin rpy="0.039468 0.1483 0.057975" xyz="-0.0045935 -0.010061 0.084993" />
    <parent link="left_hand_base_link" />
    <child link="left_middle_proximal_link" />
    <axis xyz="0 1 0" />
    <limit effort="2" lower="0" upper="1.41" velocity="2.2685" />
  </joint>
  <link name="left_middle_distal_link">
    <inertial>
      <origin rpy="0 0 0" xyz="0.0020908529801784512 -4.5736890814486051e-07 0.01671650106616987" />
      <mass value="0.0089999999999999993" />
      <inertia ixx="1.2569103327928516e-06" ixy="0" ixz="-2.401473206856006e-07" iyy="1.3028330363650818e-06" iyz="0" izz="1.9763470195018145e-07" />
    </inertial>
    <visual>
      <origin rpy="0 0 0" xyz="0 0 0" />
      <geometry>
        <mesh filename="../meshes/hands/visual/left/left_middle_distal_link.STL" />
      </geometry>
      <material name="">
        <color rgba="1 1 1 1" />
      </material>
    </visual>
    <collision>
      <origin rpy="0 0 0" xyz="0 0 0" />
      <geometry>
        <mesh filename="../meshes/hands/collision/left/left_middle_distal_link.STL" />
      </geometry>
    </collision>
  </link>
  <joint name="left_middle_distal_joint" type="revolute">
    <origin rpy="0 0.12654 0" xyz="0 0 0.037" />
    <parent link="left_middle_proximal_link" />
    <child link="left_middle_distal_link" />
    <axis xyz="0 1 0" />
    <limit effort="2" lower="0" upper="1.63" velocity="2.2685" />
    <mimic joint="left_middle_proximal_joint" multiplier="1.155" offset="0" />
  </joint>
  <link name="left_middle_tip_link">
    </link>
  <joint name="left_middle_tip_joint" type="fixed">
    <origin rpy="0 0.34907 0" xyz="0.0073534 0 0.041703" />
    <parent link="left_middle_distal_link" />
    <child link="left_middle_tip_link" />
    <axis xyz="0 0 0" />
  </joint>
  <link name="left_middle_touch_link">
    <inertial>
      <origin rpy="0 0 0" xyz="-0.0032264874449576693 -1.6464806441374979e-08 0.0030199156890812172" />
      <mass value="0.002" />
      <inertia ixx="4.3751562105730887e-08" ixy="0" ixz="1.0061853574977109e-08" iyy="3.6155257950531593e-08" iyz="0" izz="1.9203682361461601e-08" />
    </inertial>
    <visual>
      <origin rpy="0 0 0" xyz="0 0 0" />
      <geometry>
        <mesh filename="../meshes/hands/visual/left/left_middle_touch_link.STL" />
      </geometry>
      <material name="">
        <color rgba="1 1 1 1" />
      </material>
    </visual>
    <collision>
      <origin rpy="0 0 0" xyz="0 0 0" />
      <geometry>
        <mesh filename="../meshes/hands/collision/left/left_middle_touch_link.STL" />
      </geometry>
    </collision>
  </link>
  <joint name="left_middle_touch_joint" type="fixed">
    <origin rpy="0 0.34907 0" xyz="0.012493 0 0.028393" />
    <parent link="left_middle_distal_link" />
    <child link="left_middle_touch_link" />
    <axis xyz="0 0 0" />
  </joint>
  <link name="left_ring_proximal_link">
    <inertial>
      <origin rpy="0 0 0" xyz="-0.002241163016263785 -8.4923846884662759e-07 0.018974576063196438" />
      <mass value="0.0089999999999999993" />
      <inertia ixx="9.21960830860337e-07" ixy="0" ixz="-2.1402177757323032e-08" iyy="8.7978518100134324e-07" iyz="0" izz="2.6981238700334672e-07" />
    </inertial>
    <visual>
      <origin rpy="0 0 0" xyz="0 0 0" />
      <geometry>
        <mesh filename="../meshes/hands/visual/left/left_ring_proximal_link.STL" />
      </geometry>
      <material name="">
        <color rgba="1 1 1 1" />
      </material>
    </visual>
    <collision>
      <origin rpy="0 0 0" xyz="0 0 0" />
      <geometry>
        <mesh filename="../meshes/hands/collision/left/left_ring_proximal_link.STL" />
      </geometry>
    </collision>
  </link>
  <joint name="left_ring_proximal_joint" type="revolute">
    <origin rpy="-0.039462 0.14721 -0.057932" xyz="-0.0046877 0.010026 0.083982" />
    <parent link="left_hand_base_link" />
    <child link="left_ring_proximal_link" />
    <axis xyz="0 1 0" />
    <limit effort="2" lower="0" upper="1.41" velocity="2.2685" />
  </joint>
  <link name="left_ring_distal_link">
    <inertial>
      <origin rpy="0 0 0" xyz="0.0019691538124462942 -3.4712054827091547e-07 0.016229097338575658" />
      <mass value="0.0089999999999999993" />
      <inertia ixx="1.2032005239980334e-06" ixy="0" ixz="-2.3259339845713864e-07" iyy="1.2461108965833513e-06" iyz="0" izz="1.9261810732426007e-07" />
    </inertial>
    <visual>
      <origin rpy="0 0 0" xyz="0 0 0" />
      <geometry>
        <mesh filename="../meshes/hands/visual/left/left_ring_distal_link.STL" />
      </geometry>
      <material name="">
        <color rgba="1 1 1 1" />
      </material>
    </visual>
    <collision>
      <origin rpy="0 0 0" xyz="0 0 0" />
      <geometry>
        <mesh filename="../meshes/hands/collision/left/left_ring_distal_link.STL" />
      </geometry>
    </collision>
  </link>
  <joint name="left_ring_distal_joint" type="revolute">
    <origin rpy="0 0.12654 0" xyz="0 0 0.035" />
    <parent link="left_ring_proximal_link" />
    <child link="left_ring_distal_link" />
    <axis xyz="0 1 0" />
    <limit effort="2" lower="0" upper="1.63" velocity="2.2685" />
    <mimic joint="left_ring_proximal_joint" multiplier="1.155" offset="0" />
  </joint>
  <link name="left_ring_tip_link">
    </link>
  <joint name="left_ring_tip_joint" type="fixed">
    <origin rpy="0 0.34907 0" xyz="0.0071824 0 0.040734" />
    <parent link="left_ring_distal_link" />
    <child link="left_ring_tip_link" />
    <axis xyz="0 0 0" />
  </joint>
  <link name="left_ring_touch_link">
    <inertial>
      <origin rpy="0 0 0" xyz="-0.0030536856758857163 -2.2421376448217619e-08 0.0030774156162143426" />
      <mass value="0.002" />
      <inertia ixx="4.0792303970112657e-08" ixy="0" ixz="9.3093997531703186e-09" iyy="3.3284943655501508e-08" iyz="0" izz="1.7990091011534739e-08" />
    </inertial>
    <visual>
      <origin rpy="0 0 0" xyz="0 0 0" />
      <geometry>
        <mesh filename="../meshes/hands/visual/left/left_ring_touch_link.STL" />
      </geometry>
      <material name="">
        <color rgba="1 1 1 1" />
      </material>
    </visual>
    <collision>
      <origin rpy="0 0 0" xyz="0 0 0" />
      <geometry>
        <mesh filename="../meshes/hands/collision/left/left_ring_touch_link.STL" />
      </geometry>
    </collision>
  </link>
  <joint name="left_ring_touch_joint" type="fixed">
    <origin rpy="0 0.34907 0" xyz="0.012028 0 0.027796" />
    <parent link="left_ring_distal_link" />
    <child link="left_ring_touch_link" />
    <axis xyz="0 0 0" />
  </joint>
  <link name="left_pinky_proximal_link">
    <inertial>
      <origin rpy="0 0 0" xyz="-0.0019751463194913974 6.4981026612137112e-08 0.015824327842517756" />
      <mass value="0.0089999999999999993" />
      <inertia ixx="7.0779884784116139e-07" ixy="0" ixz="-1.3722323933888289e-08" iyy="6.6116859611754332e-07" iyz="0" izz="2.7015041652352649e-07" />
    </inertial>
    <visual>
      <origin rpy="0 0 0" xyz="0 0 0" />
      <geometry>
        <mesh filename="../meshes/hands/visual/left/left_pinky_proximal_link.STL" />
      </geometry>
      <material name="">
        <color rgba="1 1 1 1" />
      </material>
    </visual>
    <collision>
      <origin rpy="0 0 0" xyz="0 0 0" />
      <geometry>
        <mesh filename="../meshes/hands/collision/left/left_pinky_proximal_link.STL" />
      </geometry>
    </collision>
  </link>
  <joint name="left_pinky_proximal_joint" type="revolute">
    <origin rpy="-0.11815 0.14491 -0.17392" xyz="-0.0023733 0.029356 0.078694" />
    <parent link="left_hand_base_link" />
    <child link="left_pinky_proximal_link" />
    <axis xyz="0 1 0" />
    <limit effort="2" lower="0" upper="1.41" velocity="2.2685" />
  </joint>
  <link name="left_pinky_distal_link">
    <inertial>
      <origin rpy="0 0 0" xyz="0.0032566663967065887 6.0349934992072735e-08 0.012848446629738369" />
      <mass value="0.0089999999999999993" />
      <inertia ixx="8.4398368399810062e-07" ixy="0" ixz="-2.5703579314090776e-07" iyy="9.2770964490637625e-07" iyz="0" izz="2.2973324087645152e-07" />
    </inertial>
    <visual>
      <origin rpy="0 0 0" xyz="0 0 0" />
      <geometry>
        <mesh filename="../meshes/hands/visual/left/left_pinky_distal_link.STL" />
      </geometry>
      <material name="">
        <color rgba="1 1 1 1" />
      </material>
    </visual>
    <collision>
      <origin rpy="0 0 0" xyz="0 0 0" />
      <geometry>
        <mesh filename="../meshes/hands/collision/left/left_pinky_distal_link.STL" />
      </geometry>
    </collision>
  </link>
  <joint name="left_pinky_distal_joint" type="revolute">
    <origin rpy="0 0 0" xyz="0 0 0.029" />
    <parent link="left_pinky_proximal_link" />
    <child link="left_pinky_distal_link" />
    <axis xyz="0 1 0" />
    <limit effort="2" lower="0" upper="1.63" velocity="2.2685" />
    <mimic joint="left_pinky_proximal_joint" multiplier="1.155" offset="0" />
  </joint>
  <link name="left_pinky_tip_link">
    </link>
  <joint name="left_pinky_tip_joint" type="fixed">
    <origin rpy="0 0.4756 0" xyz="0.010221 0 0.032918" />
    <parent link="left_pinky_distal_link" />
    <child link="left_pinky_tip_link" />
    <axis xyz="0 0 0" />
  </joint>
  <link name="left_pinky_touch_link">
    <inertial>
      <origin rpy="0 0 0" xyz="-0.0028960060506516769 1.3502056552567891e-08 0.0016531329149271808" />
      <mass value="0.002" />
      <inertia ixx="3.6971683787748592e-08" ixy="0" ixz="7.6565030051316787e-09" iyy="2.8590110714915212e-08" iyz="0" izz="1.7539244571260405e-08" />
    </inertial>
    <visual>
      <origin rpy="0 0 0" xyz="0 0 0" />
      <geometry>
        <mesh filename="../meshes/hands/visual/left/left_pinky_touch_link.STL" />
      </geometry>
      <material name="">
        <color rgba="1 1 1 1" />
      </material>
    </visual>
    <collision>
      <origin rpy="0 0 0" xyz="0 0 0" />
      <geometry>
        <mesh filename="../meshes/hands/collision/left/left_pinky_touch_link.STL" />
      </geometry>
    </collision>
  </link>
  <joint name="left_pinky_touch_joint" type="fixed">
    <origin rpy="0 0.4756 0" xyz="0.01401 0 0.021124" />
    <parent link="left_pinky_distal_link" />
    <child link="left_pinky_touch_link" />
    <axis xyz="0 0 0" />
  </joint>
  
  <joint name="right_hand_base_joint" type="fixed">
    <parent link="right_connector_tip" />
    <child link="right_hand_base_link" />
    <origin rpy="0 0 0" xyz="0 0 -0.0118" />
  </joint>
  <link name="right_hand_base_link">
    <inertial>
      <origin rpy="0 0 0" xyz="-0.004990903997332514 -0.0032037440312034332 0.044050778456158846" />
      <mass value="0.23799999999999999" />
      <inertia ixx="0.0002124306908330478" ixy="2.1636756939780418e-06" ixz="3.6150282476209766e-06" iyy="0.00016013296706155058" iyz="-1.2235521367601028e-05" izz="7.7421962851898041e-05" />
    </inertial>
    <visual>
      <origin rpy="0 0 0" xyz="0 0 0" />
      <geometry>
        <mesh filename="../meshes/hands/visual/right/right_base_link.STL" />
      </geometry>
      <material name="">
        <color rgba="1 1 1 1" />
      </material>
    </visual>
    <visual>
      <origin rpy="0 0 0" xyz="0 0 0" />
      <geometry>
        <mesh filename="../meshes/hands/visual/right/right_base_visual_link.STL" />
      </geometry>
      <material name="">
        <color rgba="1 1 1 1" />
      </material>
    </visual>
    <collision>
      <origin rpy="0 0 0" xyz="0 0 0" />
      <geometry>
        <mesh filename="../meshes/hands/collision/right/right_base_link.STL" />
      </geometry>
    </collision>
  </link>
  <link name="right_thumb_metacarpal_link">
    <inertial>
      <origin rpy="0 0 0" xyz="5.2458020456317336e-05 0.0064128823181311681 -0.0038998195538025612" />
      <mass value="0.01" />
      <inertia ixx="1.0391225980670801e-06" ixy="-2.686608698988398e-08" ixz="3.1967028003029185e-09" iyy="9.9133972745252941e-07" iyz="-8.0682999171815212e-08" izz="3.2285483847306921e-07" />
    </inertial>
    <visual>
      <origin rpy="0 0 0" xyz="0 0 0" />
      <geometry>
        <mesh filename="../meshes/hands/visual/right/right_thumb_metacarpal_link.STL" />
      </geometry>
      <material name="">
        <color rgba="1 1 1 1" />
      </material>
    </visual>
    <collision>
      <origin rpy="0 0 0" xyz="0 0 0" />
      <geometry>
        <mesh filename="../meshes/hands/collision/right/right_thumb_metacarpal_link.STL" />
      </geometry>
    </collision>
  </link>
  <joint name="right_thumb_metacarpal_joint" type="revolute">
    <origin rpy="0 0 -0.16787" xyz="0.005619 0.019867 0.027825" />
    <parent link="right_hand_base_link" />
    <child link="right_thumb_metacarpal_link" />
    <axis xyz="0 0 -1" />
    <limit effort="0.5" lower="0" upper="1.57" velocity="2.6175" />
  </joint>
  <link name="right_thumb_proximal_link">
    <inertial>
      <origin rpy="0 0 0" xyz="-8.8976221451061982e-07 0.027909287394738479 -0.0021694010930280367" />
      <mass value="0.050000000000000003" />
      <inertia ixx="1.104123680739091e-05" ixy="0" ixz="0" iyy="1.7788117951772212e-06" iyz="2.7554239260883434e-08" izz="1.1565286467741584e-05" />
    </inertial>
    <visual>
      <origin rpy="0 0 0" xyz="0 0 0" />
      <geometry>
        <mesh filename="../meshes/hands/visual/right/right_thumb_proximal_visual_link.STL" />
      </geometry>
      <material name="">
        <color rgba="1 1 1 1" />
      </material>
    </visual>
    <collision>
      <origin rpy="0 0 0" xyz="0 0 0" />
      <geometry>
        <mesh filename="../meshes/hands/collision/right/right_thumb_proximal_link.STL" />
      </geometry>
    </collision>
  </link>
  <joint name="right_thumb_proximal_joint" type="revolute">
    <origin rpy="0.17488 0.23736 0.16787" xyz="0 0.014227 0" />
    <parent link="right_thumb_metacarpal_link" />
    <child link="right_thumb_proximal_link" />
    <axis xyz="1 0 0" />
    <limit effort="1.1" lower="0" upper="1.03" velocity="2.5303" />
  </joint>
  <link name="right_thumb_distal_link">
    <inertial>
      <origin rpy="0 0 0" xyz="1.4965529033365585e-05 0.0092285213242344049 -0.0022560307869527903" />
      <mass value="0.01" />
      <inertia ixx="4.533196792755254e-07" ixy="0" ixz="0" iyy="2.6015654118185334e-07" iyz="1.1609788284952737e-08" izz="5.1978354121297457e-07" />
    </inertial>
    <visual>
      <origin rpy="0 0 0" xyz="0 0 0" />
      <geometry>
        <mesh filename="../meshes/hands/visual/right/right_thumb_distal_link.STL" />
      </geometry>
      <material name="">
        <color rgba="1 1 1 1" />
      </material>
    </visual>
    <collision>
      <origin rpy="0 0 0" xyz="0 0 0" />
      <geometry>
        <mesh filename="../meshes/hands/collision/right/right_thumb_distal_link.STL" />
      </geometry>
    </collision>
  </link>
  <joint name="right_thumb_distal_joint" type="revolute">
    <origin rpy="0 0 0" xyz="0 0.052 0" />
    <parent link="right_thumb_proximal_link" />
    <child link="right_thumb_distal_link" />
    <axis xyz="1 0 0" />
    <limit effort="1.1" lower="0" upper="1.03" velocity="2.5303" />
    <mimic joint="right_thumb_proximal_joint" multiplier="1" offset="0" />
  </joint>
  <link name="right_thumb_tip_link" />
  <joint name="right_thumb_tip_joint" type="fixed">
    <origin rpy="-0.0667504507189062 0 0" xyz="0 0.0265287811635831 -0.00177344281307929" />
    <parent link="right_thumb_distal_link" />
    <child link="right_thumb_tip_link" />
    <axis xyz="0 0 0" />
  </joint>
  <link name="right_thumb_touch_link">
    <inertial>
      <origin rpy="0 0 0" xyz="5.6813574638317635e-08 0.00098883010262015912 -0.005830397007602595" />
      <mass value="0.002" />
      <inertia ixx="6.9328304217138168e-08" ixy="0" ixz="0" iyy="5.8128553580518415e-08" iyz="8.374835965466018e-09" izz="1.0158078425950607e-07" />
    </inertial>
    <visual>
      <origin rpy="0 0 0" xyz="0 0 0" />
      <geometry>
        <mesh filename="../meshes/hands/visual/right/right_thumb_touch_link.STL" />
      </geometry>
      <material name="">
        <color rgba="1 1 1 1" />
      </material>
    </visual>
    <collision>
      <origin rpy="0 0 0" xyz="0 0 0" />
      <geometry>
        <mesh filename="../meshes/hands/collision/right/right_thumb_touch_link.STL" />
      </geometry>
    </collision>
  </link>
  <joint name="right_thumb_touch_joint" type="fixed">
    <origin rpy="-0.0667504507189062 0 0" xyz="0 0.0137927522748974 0.00767659940411662" />
    <parent link="right_thumb_distal_link" />
    <child link="right_thumb_touch_link" />
    <axis xyz="0 0 0" />
  </joint>
  <link name="right_index_proximal_link">
    <inertial>
      <origin rpy="0 0 0" xyz="-0.0021097272761044172 7.6306416407769004e-07 0.01743348206585104" />
      <mass value="0.0089999999999999993" />
      <inertia ixx="8.0730313716784787e-07" ixy="0" ixz="-1.848299774099326e-08" iyy="7.6522456398412412e-07" iyz="0" izz="2.7130639796167395e-07" />
    </inertial>
    <visual>
      <origin rpy="0 0 0" xyz="0 0 0" />
      <geometry>
        <mesh filename="../meshes/hands/visual/right/right_index_proximal_link.STL" />
      </geometry>
      <material name="">
        <color rgba="1 1 1 1" />
      </material>
    </visual>
    <collision>
      <origin rpy="0 0 0" xyz="0 0 0" />
      <geometry>
        <mesh filename="../meshes/hands/collision/right/right_index_proximal_link.STL" />
      </geometry>
    </collision>
  </link>
  <joint name="right_index_proximal_joint" type="revolute">
    <origin rpy="-0.11819 0.14743 -0.17422" xyz="-0.0021181 0.029568 0.080876" />
    <parent link="right_hand_base_link" />
    <child link="right_index_proximal_link" />
    <axis xyz="0 1 0" />
    <limit effort="2" lower="0" upper="1.41" velocity="2.2685" />
  </joint>
  <link name="right_index_distal_link">
    <inertial>
      <origin rpy="0 0 0" xyz="0.0034973237026168936 -2.4397073674875195e-08 0.014024109720633237" />
      <mass value="0.0089999999999999993" />
      <inertia ixx="9.5735623721861486e-07" ixy="0" ixz="-2.9241583816658407e-07" iyy="1.0538246961086644e-06" iyz="0" izz="2.42079607880269e-07" />
    </inertial>
    <visual>
      <origin rpy="0 0 0" xyz="0 0 0" />
      <geometry>
        <mesh filename="../meshes/hands/visual/right/right_index_distal_link.STL" />
      </geometry>
      <material name="">
        <color rgba="1 1 1 1" />
      </material>
    </visual>
    <collision>
      <origin rpy="0 0 0" xyz="0 0 0" />
      <geometry>
        <mesh filename="../meshes/hands/collision/right/right_index_distal_link.STL" />
      </geometry>
    </collision>
  </link>
  <joint name="right_index_distal_joint" type="revolute">
    <origin rpy="0 0 0" xyz="0 0 0.032" />
    <parent link="right_index_proximal_link" />
    <child link="right_index_distal_link" />
    <axis xyz="0 1 0" />
    <limit effort="2" lower="0" upper="1.63" velocity="2.2685" />
    <mimic joint="right_index_proximal_joint" multiplier="1.155" offset="0" />
  </joint>
  <link name="right_index_tip_link" />
  <joint name="right_index_tip_joint" type="fixed">
    <origin rpy="0 0.4756 0" xyz="0.011097 0 0.035739" />
    <parent link="right_index_distal_link" />
    <child link="right_index_tip_link" />
    <axis xyz="0 0 0" />
  </joint>
  <link name="right_index_touch_link">
    <inertial>
      <origin rpy="0 0 0" xyz="-0.0030756425122115622 0.0025978485335546638 -0.00037591028031885978" />
      <mass value="0.002" />
      <inertia ixx="3.6524673994293294e-08" ixy="8.5175534114718623e-09" ixz="0" iyy="1.7473827933116035e-08" iyz="0" izz="2.9538435400132262e-08" />
    </inertial>
    <visual>
      <origin rpy="0 0 0" xyz="0 0 0" />
      <geometry>
        <mesh filename="../meshes/hands/visual/right/right_index_touch_link.STL" />
      </geometry>
      <material name="">
        <color rgba="1 1 1 1" />
      </material>
    </visual>
    <collision>
      <origin rpy="0 0 0" xyz="0 0 0" />
      <geometry>
        <mesh filename="../meshes/hands/collision/right/right_index_touch_link.STL" />
      </geometry>
    </collision>
  </link>
  <joint name="right_index_touch_joint" type="fixed">
    <origin rpy="1.7145 0.4756 0" xyz="0.014497 0 0.023303" />
    <parent link="right_index_distal_link" />
    <child link="right_index_touch_link" />
    <axis xyz="0 0 0" />
  </joint>
  <link name="right_middle_proximal_link">
    <inertial>
      <origin rpy="0 0 0" xyz="-0.0021465008816623902 7.0198977972219691e-07 0.020085720078992036" />
      <mass value="0.0089999999999999993" />
      <inertia ixx="9.9491303633046107e-07" ixy="0" ixz="-2.4754791568584298e-08" iyy="9.6311492131951794e-07" iyz="0" izz="2.7511378046084461e-07" />
    </inertial>
    <visual>
      <origin rpy="0 0 0" xyz="0 0 0" />
      <geometry>
        <mesh filename="../meshes/hands/visual/right/right_middle_proximal_link.STL" />
      </geometry>
      <material name="">
        <color rgba="1 1 1 1" />
      </material>
    </visual>
    <collision>
      <origin rpy="0 0 0" xyz="0 0 0" />
      <geometry>
        <mesh filename="../meshes/hands/collision/right/right_middle_proximal_link.STL" />
      </geometry>
    </collision>
  </link>
  <joint name="right_middle_proximal_joint" type="revolute">
    <origin rpy="-0.039468 0.1483 -0.057975" xyz="-0.0045767 0.010051 0.084993" />
    <parent link="right_hand_base_link" />
    <child link="right_middle_proximal_link" />
    <axis xyz="0 1 0" />
    <limit effort="2" lower="0" upper="1.41" velocity="2.2685" />
  </joint>
  <link name="right_middle_distal_link">
    <inertial>
      <origin rpy="0 0 0" xyz="0.0041837929560845618 -2.4434499929700306e-07 0.016319389628929492" />
      <mass value="0.0089999999999999993" />
      <inertia ixx="1.1798753837899665e-06" ixy="0" ixz="-3.6506311352307707e-07" iyy="1.3027657805093205e-06" iyz="0" izz="2.74608919409821e-07" />
    </inertial>
    <visual>
      <origin rpy="0 0 0" xyz="0 0 0" />
      <geometry>
        <mesh filename="../meshes/hands/visual/right/right_middle_distal_link.STL" />
      </geometry>
      <material name="">
        <color rgba="1 1 1 1" />
      </material>
    </visual>
    <collision>
      <origin rpy="0 0 0" xyz="0 0 0" />
      <geometry>
        <mesh filename="../meshes/hands/collision/right/right_middle_distal_link.STL" />
      </geometry>
    </collision>
  </link>
  <joint name="right_middle_distal_joint" type="revolute">
    <origin rpy="0 0 0" xyz="0 0 0.037" />
    <parent link="right_middle_proximal_link" />
    <child link="right_middle_distal_link" />
    <axis xyz="0 1 0" />
    <limit effort="2" lower="0" upper="1.63" velocity="2.2685" />
    <mimic joint="right_middle_proximal_joint" multiplier="1.155" offset="0" />
  </joint>
  <link name="right_middle_tip_link" />
  <joint name="right_middle_tip_joint" type="fixed">
    <origin rpy="0 0.4756 0" xyz="0.012558 0 0.040442" />
    <parent link="right_middle_distal_link" />
    <child link="right_middle_tip_link" />
    <axis xyz="0 0 0" />
  </joint>
  <link name="right_middle_touch_link">
    <inertial>
      <origin rpy="0 0 0" xyz="-0.00322648744586361 -1.6462838133423407e-08 0.003019915690530168" />
      <mass value="0.002" />
      <inertia ixx="4.3751562145816199e-08" ixy="0" ixz="1.0061853585855406e-08" iyy="3.6155257979078231e-08" iyz="0" izz="1.9203682382619578e-08" />
    </inertial>
    <visual>
      <origin rpy="0 0 0" xyz="0 0 0" />
      <geometry>
        <mesh filename="../meshes/hands/visual/right/right_middle_touch_link.STL" />
      </geometry>
      <material name="">
        <color rgba="1 1 1 1" />
      </material>
    </visual>
    <collision>
      <origin rpy="0 0 0" xyz="0 0 0" />
      <geometry>
        <mesh filename="../meshes/hands/collision/right/right_middle_touch_link.STL" />
      </geometry>
    </collision>
  </link>
  <joint name="right_middle_touch_joint" type="fixed">
    <origin rpy="0 0.475602221168456 0" xyz="0.015975871997898 0 0.0265894268903603" />
    <parent link="right_middle_distal_link" />
    <child link="right_middle_touch_link" />
    <axis xyz="0 0 0" />
  </joint>
  <link name="right_ring_proximal_link">
    <inertial>
      <origin rpy="0 0 0" xyz="-0.0022400419451280916 -3.1642021509100015e-07 0.018974768492582277" />
      <mass value="0.0089999999999999993" />
      <inertia ixx="9.2192274611012312e-07" ixy="0" ixz="-2.1434689277025735e-08" iyy="8.7978062842405091e-07" iyz="0" izz="2.6982721614770708e-07" />
    </inertial>
    <visual>
      <origin rpy="0 0 0" xyz="0 0 0" />
      <geometry>
        <mesh filename="../meshes/hands/visual/right/right_ring_proximal_link.STL" />
      </geometry>
      <material name="">
        <color rgba="1 1 1 1" />
      </material>
    </visual>
    <collision>
      <origin rpy="0 0 0" xyz="0 0 0" />
      <geometry>
        <mesh filename="../meshes/hands/collision/right/right_ring_proximal_link.STL" />
      </geometry>
    </collision>
  </link>
  <joint name="right_ring_proximal_joint" type="revolute">
    <origin rpy="0.039462 0.14721 0.057932" xyz="-0.0046709 -0.010037 0.083982" />
    <parent link="right_hand_base_link" />
    <child link="right_ring_proximal_link" />
    <axis xyz="0 1 0" />
    <limit effort="2" lower="0" upper="1.41" velocity="2.2685" />
  </joint>
  <link name="right_ring_distal_link">
    <inertial>
      <origin rpy="0 0 0" xyz="0.0040015207242677124 -8.8623994317685101e-09 0.015850785477788721" />
      <mass value="0.0089999999999999993" />
      <inertia ixx="1.1288595625756626e-06" ixy="0" ixz="-3.5169780079057451e-07" iyy="1.2460980805338906e-06" iyz="0" izz="2.6695244589650716e-07" />
    </inertial>
    <visual>
      <origin rpy="0 0 0" xyz="0 0 0" />
      <geometry>
        <mesh filename="../meshes/hands/visual/right/right_ring_distal_link.STL" />
      </geometry>
      <material name="">
        <color rgba="1 1 1 1" />
      </material>
    </visual>
    <collision>
      <origin rpy="0 0 0" xyz="0 0 0" />
      <geometry>
        <mesh filename="../meshes/hands/collision/right/right_ring_distal_link.STL" />
      </geometry>
    </collision>
  </link>
  <joint name="right_ring_distal_joint" type="revolute">
    <origin rpy="0 0 0" xyz="0 0 0.035" />
    <parent link="right_ring_proximal_link" />
    <child link="right_ring_distal_link" />
    <axis xyz="0 1 0" />
    <limit effort="2" lower="0" upper="1.63" velocity="2.2685" />
    <mimic joint="right_ring_proximal_joint" multiplier="1.155" offset="0" />
  </joint>
  <link name="right_ring_tip_link" />
  <joint name="right_ring_tip_joint" type="fixed">
    <origin rpy="0 0.4756 0" xyz="0.012266 0 0.039501" />
    <parent link="right_ring_distal_link" />
    <child link="right_ring_tip_link" />
    <axis xyz="0 0 0" />
  </joint>
  <link name="right_ring_touch_link">
    <inertial>
      <origin rpy="0 0 0" xyz="-0.0030536856753133582 -2.2426892399133907e-08 0.0030774156138667829" />
      <mass value="0.002" />
      <inertia ixx="4.0792303960880825e-08" ixy="0" ixz="9.3093997541088973e-09" iyy="3.3284943664080675e-08" iyz="0" izz="1.799009099498985e-08" />
    </inertial>
    <visual>
      <origin rpy="0 0 0" xyz="0 0 0" />
      <geometry>
        <mesh filename="../meshes/hands/visual/right/right_ring_touch_link.STL" />
      </geometry>
      <material name="">
        <color rgba="1 1 1 1" />
      </material>
    </visual>
    <collision>
      <origin rpy="0 0 0" xyz="0 0 0" />
      <geometry>
        <mesh filename="../meshes/hands/collision/right/right_ring_touch_link.STL" />
      </geometry>
    </collision>
  </link>
  <joint name="right_ring_touch_joint" type="fixed">
    <origin rpy="0 0.475602221168648 0" xyz="0.0154392324697935 0 0.0260561041381566" />
    <parent link="right_ring_distal_link" />
    <child link="right_ring_touch_link" />
    <axis xyz="0 0 0" />
  </joint>
  <link name="right_pinky_proximal_link">
    <inertial>
      <origin rpy="0 0 0" xyz="-0.001975334662528235 -2.9023458616399922e-07 0.015823987731302468" />
      <mass value="0.0089999999999999993" />
      <inertia ixx="7.0777766209880607e-07" ixy="0" ixz="-1.3707570348896025e-08" iyy="6.6113592506802425e-07" iyz="0" izz="2.7014080371543559e-07" />
    </inertial>
    <visual>
      <origin rpy="0 0 0" xyz="0 0 0" />
      <geometry>
        <mesh filename="../meshes/hands/visual/right/right_pinky_proximal_link.STL" />
      </geometry>
      <material name="">
        <color rgba="1 1 1 1" />
      </material>
    </visual>
    <collision>
      <origin rpy="0 0 0" xyz="0 0 0" />
      <geometry>
        <mesh filename="../meshes/hands/collision/right/right_pinky_proximal_link.STL" />
      </geometry>
    </collision>
  </link>
  <joint name="right_pinky_proximal_joint" type="revolute">
    <origin rpy="0.11815 0.14491 0.17392" xyz="-0.0023566 -0.029366 0.078694" />
    <parent link="right_hand_base_link" />
    <child link="right_pinky_proximal_link" />
    <axis xyz="0 1 0" />
    <limit effort="2" lower="0" upper="1.41" velocity="2.2685" />
  </joint>
  <link name="right_pinky_distal_link">
    <inertial>
      <origin rpy="0 0 0" xyz="0.0032566529441424874 -3.0043695826476274e-07 0.012848383340721354" />
      <mass value="0.0089999999999999993" />
      <inertia ixx="8.4398585277410544e-07" ixy="0" ixz="-2.5703935799039044e-07" iyy="9.2771658916401349e-07" iyz="0" izz="2.2973189795614046e-07" />
    </inertial>
    <visual>
      <origin rpy="0 0 0" xyz="0 0 0" />
      <geometry>
        <mesh filename="../meshes/hands/visual/right/right_pinky_distal_link.STL" />
      </geometry>
      <material name="">
        <color rgba="1 1 1 1" />
      </material>
    </visual>
    <collision>
      <origin rpy="0 0 0" xyz="0 0 0" />
      <geometry>
        <mesh filename="../meshes/hands/collision/right/right_pinky_distal_link.STL" />
      </geometry>
    </collision>
  </link>
  <joint name="right_pinky_distal_joint" type="revolute">
    <origin rpy="0 0 0" xyz="0 0 0.029" />
    <parent link="right_pinky_proximal_link" />
    <child link="right_pinky_distal_link" />
    <axis xyz="0 1 0" />
    <limit effort="2" lower="0" upper="1.63" velocity="2.2685" />
    <mimic joint="right_pinky_proximal_joint" multiplier="1.155" offset="0" />
  </joint>
  <link name="right_pinky_tip_link" />
  <joint name="right_pinky_tip_joint" type="fixed">
    <origin rpy="0 0.4756 0" xyz="0.010221 0 0.032918" />
    <parent link="right_pinky_distal_link" />
    <child link="right_pinky_tip_link" />
    <axis xyz="0 0 0" />
  </joint>
  <link name="right_pinky_touch_link">
    <inertial>
      <origin rpy="0 0 0" xyz="-0.0028960060613945678 1.3392487741221686e-08 0.0016531329144734779" />
      <mass value="0.002" />
      <inertia ixx="3.6971683917529048e-08" ixy="0" ixz="7.6565029947266085e-09" iyy="2.859011067413845e-08" iyz="0" izz="1.7539244747520166e-08" />
    </inertial>
    <visual>
      <origin rpy="0 0 0" xyz="0 0 0" />
      <geometry>
        <mesh filename="../meshes/hands/visual/right/right_pinky_touch_link.STL" />
      </geometry>
      <material name="">
        <color rgba="1 1 1 1" />
      </material>
    </visual>
    <collision>
      <origin rpy="0 0 0" xyz="0 0 0" />
      <geometry>
        <mesh filename="../meshes/hands/collision/right/right_pinky_touch_link.STL" />
      </geometry>
    </collision>
  </link>
  <joint name="right_pinky_touch_joint" type="fixed">
    <origin rpy="0 0.4756 0" xyz="0.01401 0 0.021124" />
    <parent link="right_pinky_distal_link" />
    <child link="right_pinky_touch_link" />
    <axis xyz="0 0 0" />
  </joint>
</robot>