<?xml version='1.0' encoding='utf-8'?>
<robot name="revoarm_single">
  <link name="base_link">
    <inertial>
      <origin rpy="0 0 0" xyz="-0.00044332747291356403 -0.00018960038049865597 0.041658123214062585" />
      <mass value="2.05031149778" />
      <inertia ixx="0.00574143134257215" ixy="-5.947609211488795e-06" ixz="-2.2526485067060592e-05" iyy="0.0039000929392483917" iyz="9.640527208518365e-06" izz="0.004903557716784477" />
    </inertial>
    <visual>
      <origin rpy="0 0 0" xyz="0 0 0" />
      <geometry>
        <mesh filename="../meshes/body/visual/single/base_link.STL" />
      </geometry>
      <material name="">
        <color rgba="0.556863 0.556863 0.556863 1" />
      </material>
    </visual>
    <collision>
      <origin rpy="0 0 0" xyz="0 0 0" />
      <geometry>
        <mesh filename="../meshes/body/collision/single/base_link.STL" />
      </geometry>
    </collision>
  </link>
  <joint name="left_base_joint" type="fixed">
    <parent link="base_link" />
    <child link="left_base_link" />
    <origin rpy="1.5708 0 0" xyz="0 0 0.0997" />
  </joint>
  <link name="left_base_link" />
  <link name="left_arm_link1">
    <inertial>
      <origin rpy="0 0 0" xyz="0.0014558952417556832 0.052716571861716806 -0.0012746925369990579" />
      <mass value="0.99862" />
      <inertia ixx="0.0013455582136954168" ixy="-7.831531833443126e-06" ixz="-1.1584640844290234e-06" iyy="0.0008358775975363909" iyz="-5.1116974592436684e-05" izz="0.0010339431564673298" />
    </inertial>
    <visual>
      <origin rpy="0 0 0" xyz="0 0 0" />
      <geometry>
        <mesh filename="../meshes/arm/visual/left_arm_link1.STL" />
      </geometry>
      <material name="">
        <color rgba="1 1 1 1" />
      </material>
    </visual>
    <collision>
      <origin rpy="0 0 0" xyz="0 0 0" />
      <geometry>
        <mesh filename="../meshes/arm/collision/left_arm_link1.STL" />
      </geometry>
    </collision>
  </link>
  <joint name="revoarm_left_joint1" type="revolute">
    <origin rpy="0 1.5708 0" xyz="0 0 0" />
    <parent link="left_base_link" />
    <child link="left_arm_link1" />
    <axis xyz="0 1 0" />
    <limit effort="40" lower="-4.1015" upper="0.7854" velocity="2.792" />
  </joint>
  <link name="left_arm_link2">
    <inertial>
      <origin rpy="0 0 0" xyz="0.0003522335464279825 0.00038005451984361304 -0.027671836967634263" />
      <mass value="0.1942" />
      <inertia ixx="0.00037984612194445115" ixy="-1.4630943049862306e-06" ixz="1.603119961015182e-06" iyy="0.00036786946654754907" iyz="1.582395907574811e-06" izz="0.0002084532432667245" />
    </inertial>
    <visual>
      <origin rpy="0 0 0" xyz="0 0 0" />
      <geometry>
        <mesh filename="../meshes/arm/visual/left_arm_link2.STL" />
      </geometry>
      <material name="">
        <color rgba="1 1 1 1" />
      </material>
    </visual>
    <collision>
      <origin rpy="0 0 0" xyz="0 0 0" />
      <geometry>
        <mesh filename="../meshes/arm/collision/left_arm_link2.STL" />
      </geometry>
    </collision>
  </link>
  <joint name="revoarm_left_joint2" type="revolute">
    <origin rpy="1.5708 0 0" xyz="0 0.06 0" />
    <parent link="left_arm_link1" />
    <child link="left_arm_link2" />
    <axis xyz="1 0 0" />
    <limit effort="40" lower="-1.7453" upper="1.7453" velocity="2.792" />
  </joint>
  <link name="left_arm_link3">
    <inertial>
      <origin rpy="0 0 0" xyz="-0.00038856719925421814 -1.856841337962366e-05 -0.0669511733195832" />
      <mass value="0.56897" />
      <inertia ixx="0.001347024509553418" ixy="3.824029645136789e-07" ixz="-1.080913497188802e-05" iyy="0.0013183781004236497" iyz="4.508896464373414e-07" izz="0.0004885001058002036" />
    </inertial>
    <visual>
      <origin rpy="0 0 0" xyz="0 0 0" />
      <geometry>
        <mesh filename="../meshes/arm/visual/left_arm_link3.STL" />
      </geometry>
      <material name="">
        <color rgba="1 1 1 1" />
      </material>
    </visual>
    <collision>
      <origin rpy="0 0 0" xyz="0 0 0" />
      <geometry>
        <mesh filename="../meshes/arm/collision/left_arm_link3.STL" />
      </geometry>
    </collision>
  </link>
  <joint name="revoarm_left_joint3" type="revolute">
    <origin rpy="0 0 1.5708" xyz="0 0 -0.099" />
    <parent link="left_arm_link2" />
    <child link="left_arm_link3" />
    <axis xyz="0 0 -1" />
    <limit effort="27" lower="-3.6652" upper="0.5236" velocity="1.745" />
  </joint>
  <link name="left_arm_link4">
    <inertial>
      <origin rpy="0 0 0" xyz="-9.928907268251463e-05 -0.00035402152400401 -0.025368403210649232" />
      <mass value="0.43039" />
      <inertia ixx="0.0004717793537881475" ixy="-1.2442902049896903e-07" ixz="-7.688576107641954e-07" iyy="0.00047406778201506214" iyz="2.5261136738388584e-06" izz="0.00027664775194187767" />
    </inertial>
    <visual>
      <origin rpy="0 0 0" xyz="0 0 0" />
      <geometry>
        <mesh filename="../meshes/arm/visual/left_arm_link4.STL" />
      </geometry>
      <material name="">
        <color rgba="1 1 1 1" />
      </material>
    </visual>
    <collision>
      <origin rpy="0 0 0" xyz="0 0 0" />
      <geometry>
        <mesh filename="../meshes/arm/collision/left_arm_link4.STL" />
      </geometry>
    </collision>
  </link>
  <joint name="revoarm_left_joint4" type="revolute">
    <origin rpy="0 0.0 0" xyz="0 0 -0.121" />
    <parent link="left_arm_link3" />
    <child link="left_arm_link4" />
    <axis xyz="0 -1 0" />
    <limit effort="27" lower="-0.34907" upper="2.2166" velocity="1.745" />
  </joint>
  <link name="left_arm_link5">
    <inertial>
      <origin rpy="0 0 0" xyz="0.0009273109394114897 -0.00014084089093363534 -0.07442692427006262" />
      <mass value="0.80969" />
      <inertia ixx="0.0018262186167409072" ixy="1.4279441393496652e-08" ixz="2.781229306841082e-05" iyy="0.0018338945560489519" iyz="-2.8548278354889502e-06" izz="0.0005616240442547082" />
    </inertial>
    <visual>
      <origin rpy="0 0 0" xyz="0 0 0" />
      <geometry>
        <mesh filename="../meshes/arm/visual/left_arm_link5.STL" />
      </geometry>
      <material name="">
        <color rgba="1 1 1 1" />
      </material>
    </visual>
    <collision>
      <origin rpy="0 0 0" xyz="0 0 0" />
      <geometry>
        <mesh filename="../meshes/arm/collision/left_arm_link5.STL" />
      </geometry>
    </collision>
  </link>
  <joint name="revoarm_left_joint5" type="revolute">
    <origin rpy="0 0 0.0" xyz="0 0 -0.0635" />
    <parent link="left_arm_link4" />
    <child link="left_arm_link5" />
    <axis xyz="0 0 -1" />
    <limit effort="7" lower="-3.1444" upper="0.9044" velocity="6.98" />
  </joint>
  <link name="left_arm_link6">
    <inertial>
      <origin rpy="0 0 0" xyz="0.0001405267991875142 -0.001049427241263535 -2.2489628719575287e-05" />
      <mass value="0.31466" />
      <inertia ixx="0.00012100842021227848" ixy="-2.1489023911950789e-07" ixz="-6.95891723798596e-08" iyy="0.00013672911934102953" iyz="-2.010668451920477e-07" izz="0.00013781623418694094" />
    </inertial>
    <visual>
      <origin rpy="0 0 0" xyz="0 0 0" />
      <geometry>
        <mesh filename="../meshes/arm/visual/left_arm_link6.STL" />
      </geometry>
      <material name="">
        <color rgba="1 1 1 1" />
      </material>
    </visual>
    <collision>
      <origin rpy="0 0 0" xyz="0 0 0" />
      <geometry>
        <mesh filename="../meshes/arm/collision/left_arm_link6.STL" />
      </geometry>
    </collision>
  </link>
  <joint name="revoarm_left_joint6" type="revolute">
    <origin rpy="0.0 0 0" xyz="0 0 -0.1525" />
    <parent link="left_arm_link5" />
    <child link="left_arm_link6" />
    <axis xyz="-1 0 0" />
    <limit effort="7" lower="-0.64577" upper="0.64577" velocity="6.98" />
  </joint>
  
  <link name="left_arm_link7">
    <inertial>
      <origin rpy="0 0 0" xyz="0 0 0" />
      <mass value="0.0" />
      <inertia ixx="1e-09" ixy="0" ixz="0" iyy="1e-09" iyz="0" izz="1e-09" />
    </inertial>
  </link>
  <joint name="revoarm_left_joint7" type="revolute">
    <origin rpy="-0.0019404 0.0 0" xyz="0 0 0" />
    <parent link="left_arm_link6" />
    <child link="left_arm_link7" />
    <axis xyz="0 -1 0" />
    <limit effort="7" lower="-1.5708" upper="1.5708" velocity="6.98" />
  </joint>
  
  <link name="left_connector_link">
    <inertial>
      <origin rpy="0 0 0" xyz="0.005118745362621232 0.0006367060365849771 -0.02674019826311511" />
      <mass value="0.49311" />
      <inertia ixx="0.00022442378409980932" ixy="4.1874361256991135e-06" ixz="6.488777698062572e-06" iyy="0.00029604403831446697" iyz="1.527999228564945e-05" izz="0.00020292508000928854" />
    </inertial>
    <visual>
      <origin rpy="0 0 0" xyz="0 0 0" />
      <geometry>
        <mesh filename="../meshes/connector/visual/left_revo2_connector.STL" />
      </geometry>
      <material name="">
        <color rgba="0.79216 0.81961 0.93333 1.0" />
      </material>
    </visual>
    <collision>
      <origin rpy="0 0 0" xyz="0 0 0" />
      <geometry>
        <mesh filename="../meshes/connector/collision/left_revo2_connector.STL" />
      </geometry>
    </collision>
  </link>
  
  <joint name="left_connector_mount" type="fixed">
    <parent link="left_arm_link7" />
    <child link="left_connector_link" />
    <origin rpy="0 0 1.57" xyz="0 0 0" />
  </joint>
  
  <link name="left_connector_tip" />
  <joint name="left_connector_tip_joint" type="fixed">
    <parent link="left_connector_link" />
    <child link="left_connector_tip" />
    <origin rpy="0 3.14 0" xyz="0.0000760 0.0001518 -0.0583" />
  </joint>
  
  <joint name="left_hand_base_joint" type="fixed">
    <parent link="left_connector_tip" />
    <child link="left_hand_base_link" />
    <origin rpy="0 0 0" xyz="0 0 -0.0118" />
  </joint>
  <link name="left_hand_base_link">
    <inertial>
      <origin rpy="0 0 0" xyz="-0.0050069196557942898 0.0031951498725952578 0.044048985017541092" />
      <mass value="0.23799999999999999" />
      <inertia ixx="0.00021243703191569629" ixy="-2.160578998863694e-06" ixz="3.6168810917662211e-06" iyy="0.00016014308936489096" iyz="1.2241686067591412e-05" izz="7.7420062865293511e-05" />
    </inertial>
    <visual>
      <origin rpy="0 0 0" xyz="0 0 0" />
      <geometry>
        <mesh filename="../meshes/hands/visual/left/left_base_link.STL" />
      </geometry>
      <material name="">
        <color rgba="1 1 1 1" />
      </material>
    </visual>
    <visual>
      <origin rpy="0 0 0" xyz="0 0 0" />
      <geometry>
        <mesh filename="../meshes/hands/visual/left/left_base_visual_link.STL" />
      </geometry>
      <material name="">
        <color rgba="1 1 1 1" />
      </material>
    </visual>
    <collision>
      <origin rpy="0 0 0" xyz="0 0 0" />
      <geometry>
        <mesh filename="../meshes/hands/collision/left/left_base_link.STL" />
      </geometry>
    </collision>
  </link>
  <link name="left_thumb_metacarpal_link">
    <inertial>
      <origin rpy="0 0 0" xyz="5.2448120648044896e-05 -0.0064127113564924525 -0.0038999285548428604" />
      <mass value="0.01" />
      <inertia ixx="1.0391374023389509e-06" ixy="2.6878105173942598e-08" ixz="3.1994739840723345e-09" iyy="9.9133648861034965e-07" iyz="8.0715388563913015e-08" izz="3.2287162991569446e-07" />
    </inertial>
    <visual>
      <origin rpy="0 0 0" xyz="0 0 0" />
      <geometry>
        <mesh filename="../meshes/hands/visual/left/left_thumb_metacarpal_link.STL" />
      </geometry>
      <material name="">
        <color rgba="1 1 1 1" />
      </material>
    </visual>
    <collision>
      <origin rpy="0 0 0" xyz="0 0 0" />
      <geometry>
        <mesh filename="../meshes/hands/collision/left/left_thumb_metacarpal_link.STL" />
      </geometry>
    </collision>
  </link>
  <joint name="left_thumb_metacarpal_joint" type="revolute">
    <origin rpy="0 0 0.16787" xyz="0.0045 -0.019 0.027825" />
    <parent link="left_hand_base_link" />
    <child link="left_thumb_metacarpal_link" />
    <axis xyz="0 0 1" />
    <limit effort="0.5" lower="0" upper="1.57" velocity="2.6175" />
  </joint>
  <link name="left_thumb_proximal_link">
    <inertial>
      <origin rpy="0 0 0" xyz="-5.3592746671882903e-07 -0.027910209963501159 -0.0021690604228547681" />
      <mass value="0.050000000000000003" />
      <inertia ixx="1.1041485159004667e-05" ixy="0" ixz="0" iyy="1.7787677179094888e-06" iyz="-2.7574629630040948e-08" izz="1.1565614290883625e-05" />
    </inertial>
    <visual>
      <origin rpy="0 0 0" xyz="0 0 0" />
      <geometry>
        <mesh filename="../meshes/hands/visual/left/left_thumb_proximal_link.STL" />
      </geometry>
      <material name="">
        <color rgba="1 1 1 1" />
      </material>
    </visual>
    <visual>
      <origin rpy="0 0 0" xyz="0 0 0" />
      <geometry>
        <mesh filename="../meshes/hands/visual/left/left_thumb_proximal_visual_link.STL" />
      </geometry>
      <material name="">
        <color rgba="1 1 1 1" />
      </material>
    </visual>
    <collision>
      <origin rpy="0 0 0" xyz="0 0 0" />
      <geometry>
        <mesh filename="../meshes/hands/collision/left/left_thumb_proximal_link.STL" />
      </geometry>
    </collision>
  </link>
  <joint name="left_thumb_proximal_joint" type="revolute">
    <origin rpy="-0.17488 0.23736 -0.16787" xyz="0 -0.014227 0" />
    <parent link="left_thumb_metacarpal_link" />
    <child link="left_thumb_proximal_link" />
    <axis xyz="-1 0 0" />
    <limit effort="1.1" lower="0" upper="1.03" velocity="2.5303" />
  </joint>
  <link name="left_thumb_distal_link">
    <inertial>
      <origin rpy="0 0 0" xyz="-9.3250353421736472e-07 -0.0092216958166139763 -0.0022464414712281789" />
      <mass value="0.01" />
      <inertia ixx="4.53439708081094e-07" ixy="0" ixz="0" iyy="2.6101216224350947e-07" iyz="-1.20090505524035e-08" izz="5.2010076079456636e-07" />
    </inertial>
    <visual>
      <origin rpy="0 0 0" xyz="0 0 0" />
      <geometry>
        <mesh filename="../meshes/hands/visual/left/left_thumb_distal_link.STL" />
      </geometry>
      <material name="">
        <color rgba="1 1 1 1" />
      </material>
    </visual>
    <collision>
      <origin rpy="0 0 0" xyz="0 0 0" />
      <geometry>
        <mesh filename="../meshes/hands/collision/left/left_thumb_distal_link.STL" />
      </geometry>
    </collision>
  </link>
  <joint name="left_thumb_distal_joint" type="revolute">
    <origin rpy="0 0 0" xyz="0 -0.052 0" />
    <parent link="left_thumb_proximal_link" />
    <child link="left_thumb_distal_link" />
    <axis xyz="-1 0 0" />
    <limit effort="1.1" lower="0" upper="1.03" velocity="2.5303" />
    <mimic joint="left_thumb_proximal_joint" multiplier="1" offset="0" />
  </joint>
  <link name="left_thumb_tip_link">
    </link>
  <joint name="left_thumb_tip_joint" type="fixed">
    <origin rpy="0.06675 0 0" xyz="0 -0.026529 -0.0017734" />
    <parent link="left_thumb_distal_link" />
    <child link="left_thumb_tip_link" />
    <axis xyz="0 0 0" />
  </joint>
  <link name="left_thumb_touch_link">
    <inertial>
      <origin rpy="0 0 0" xyz="-5.5105603595396999e-07 -0.0015679769969614223 -0.0056888113918425586" />
      <mass value="0.002" />
      <inertia ixx="6.9337608696321383e-08" ixy="0" ixz="0" iyy="5.6838789495101113e-08" iyz="-3.5148755380579443e-09" izz="1.0288222773007187e-07" />
    </inertial>
    <visual>
      <origin rpy="0 0 0" xyz="0 0 0" />
      <geometry>
        <mesh filename="../meshes/hands/visual/left/left_thumb_touch_link.STL" />
      </geometry>
      <material name="">
        <color rgba="1 1 1 1" />
      </material>
    </visual>
    <collision>
      <origin rpy="0 0 0" xyz="0 0 0" />
      <geometry>
        <mesh filename="../meshes/hands/collision/left/left_thumb_touch_link.STL" />
      </geometry>
    </collision>
  </link>
  <joint name="left_thumb_touch_joint" type="fixed">
    <origin rpy="0.17488 0 0" xyz="0 -0.013836 0.0076686" />
    <parent link="left_thumb_distal_link" />
    <child link="left_thumb_touch_link" />
    <axis xyz="0 0 0" />
  </joint>
  <link name="left_index_proximal_link">
    <inertial>
      <origin rpy="0 0 0" xyz="-0.0021095762185109556 -1.0018489057074859e-06 0.017433891986291937" />
      <mass value="0.0089999999999999993" />
      <inertia ixx="8.0725407014471423e-07" ixy="0" ixz="-1.8489857513645255e-08" iyy="7.6517802541226111e-07" iyz="0" izz="2.7130906026168039e-07" />
    </inertial>
    <visual>
      <origin rpy="0 0 0" xyz="0 0 0" />
      <geometry>
        <mesh filename="../meshes/hands/visual/left/left_index_proximal_link.STL" />
      </geometry>
      <material name="">
        <color rgba="1 1 1 1" />
      </material>
    </visual>
    <collision>
      <origin rpy="0 0 0" xyz="0 0 0" />
      <geometry>
        <mesh filename="../meshes/hands/collision/left/left_index_proximal_link.STL" />
      </geometry>
    </collision>
  </link>
  <joint name="left_index_proximal_joint" type="revolute">
    <origin rpy="0.11819 0.14743 0.17422" xyz="-0.0021349 -0.029578 0.080876" />
    <parent link="left_hand_base_link" />
    <child link="left_index_proximal_link" />
    <axis xyz="0 1 0" />
    <limit effort="2" lower="0" upper="1.41" velocity="2.2685" />
  </joint>
  <link name="left_index_distal_link">
    <inertial>
      <origin rpy="0 0 0" xyz="0.0034973861673681678 -8.6913011917289015e-08 0.014024367479174444" />
      <mass value="0.0089999999999999993" />
      <inertia ixx="9.573382382798683e-07" ixy="0" ixz="-2.9240822964098857e-07" iyy="1.0538009354304963e-06" iyz="0" izz="2.4208109624630676e-07" />
    </inertial>
    <visual>
      <origin rpy="0 0 0" xyz="0 0 0" />
      <geometry>
        <mesh filename="../meshes/hands/visual/left/left_index_distal_link.STL" />
      </geometry>
      <material name="">
        <color rgba="1 1 1 1" />
      </material>
    </visual>
    <collision>
      <origin rpy="0 0 0" xyz="0 0 0" />
      <geometry>
        <mesh filename="../meshes/hands/collision/left/left_index_distal_link.STL" />
      </geometry>
    </collision>
  </link>
  <joint name="left_index_distal_joint" type="revolute">
    <origin rpy="0 0 0" xyz="0 0 0.032" />
    <parent link="left_index_proximal_link" />
    <child link="left_index_distal_link" />
    <axis xyz="0 1 0" />
    <limit effort="2" lower="0" upper="1.63" velocity="2.2685" />
    <mimic joint="left_index_proximal_joint" multiplier="1.155" offset="0" />
  </joint>
  <link name="left_index_tip_link">
    </link>
  <joint name="left_index_tip_joint" type="fixed">
    <origin rpy="0 0.48723 0" xyz="0.011097 0 0.035739" />
    <parent link="left_index_distal_link" />
    <child link="left_index_tip_link" />
    <axis xyz="0 0 0" />
  </joint>
  <link name="left_index_touch_link">
    <inertial>
      <origin rpy="0 0 0" xyz="-0.0030756425070118062 -3.9046886263805012e-08 0.0026249048738638684" />
      <mass value="0.002" />
      <inertia ixx="3.6524673961438282e-08" ixy="0" ixz="8.6063395532046128e-09" iyy="2.9796812970068342e-08" iyz="0" izz="1.721545025385639e-08" />
    </inertial>
    <visual>
      <origin rpy="0 0 0" xyz="0 0 0" />
      <geometry>
        <mesh filename="../meshes/hands/visual/left/left_index_touch_link.STL" />
      </geometry>
      <material name="">
        <color rgba="1 1 1 1" />
      </material>
    </visual>
    <collision>
      <origin rpy="0 0 0" xyz="0 0 0" />
      <geometry>
        <mesh filename="../meshes/hands/collision/left/left_index_touch_link.STL" />
      </geometry>
    </collision>
  </link>
  <joint name="left_index_touch_joint" type="fixed">
    <origin rpy="0 0.4756 0" xyz="0.014497 0 0.023303" />
    <parent link="left_index_distal_link" />
    <child link="left_index_touch_link" />
    <axis xyz="0 0 0" />
  </joint>
  <link name="left_middle_proximal_link">
    <inertial>
      <origin rpy="0 0 0" xyz="-0.0021463337350766396 -1.4625211059774783e-06 0.020086308617024221" />
      <mass value="0.0089999999999999993" />
      <inertia ixx="9.948385373762115e-07" ixy="0" ixz="-2.4771872948759328e-08" iyy="9.6305285606291445e-07" iyz="0" izz="2.7511820938354049e-07" />
    </inertial>
    <visual>
      <origin rpy="0 0 0" xyz="0 0 0" />
      <geometry>
        <mesh filename="../meshes/hands/visual/left/left_middle_proximal_link.STL" />
      </geometry>
      <material name="">
        <color rgba="1 1 1 1" />
      </material>
    </visual>
    <collision>
      <origin rpy="0 0 0" xyz="0 0 0" />
      <geometry>
        <mesh filename="../meshes/hands/collision/left/left_middle_proximal_link.STL" />
      </geometry>
    </collision>
  </link>
  <joint name="left_middle_proximal_joint" type="revolute">
    <origin rpy="0.039468 0.1483 0.057975" xyz="-0.0045935 -0.010061 0.084993" />
    <parent link="left_hand_base_link" />
    <child link="left_middle_proximal_link" />
    <axis xyz="0 1 0" />
    <limit effort="2" lower="0" upper="1.41" velocity="2.2685" />
  </joint>
  <link name="left_middle_distal_link">
    <inertial>
      <origin rpy="0 0 0" xyz="0.0020908529801784512 -4.5736890814486051e-07 0.01671650106616987" />
      <mass value="0.0089999999999999993" />
      <inertia ixx="1.2569103327928516e-06" ixy="0" ixz="-2.401473206856006e-07" iyy="1.3028330363650818e-06" iyz="0" izz="1.9763470195018145e-07" />
    </inertial>
    <visual>
      <origin rpy="0 0 0" xyz="0 0 0" />
      <geometry>
        <mesh filename="../meshes/hands/visual/left/left_middle_distal_link.STL" />
      </geometry>
      <material name="">
        <color rgba="1 1 1 1" />
      </material>
    </visual>
    <collision>
      <origin rpy="0 0 0" xyz="0 0 0" />
      <geometry>
        <mesh filename="../meshes/hands/collision/left/left_middle_distal_link.STL" />
      </geometry>
    </collision>
  </link>
  <joint name="left_middle_distal_joint" type="revolute">
    <origin rpy="0 0.12654 0" xyz="0 0 0.037" />
    <parent link="left_middle_proximal_link" />
    <child link="left_middle_distal_link" />
    <axis xyz="0 1 0" />
    <limit effort="2" lower="0" upper="1.63" velocity="2.2685" />
    <mimic joint="left_middle_proximal_joint" multiplier="1.155" offset="0" />
  </joint>
  <link name="left_middle_tip_link">
    </link>
  <joint name="left_middle_tip_joint" type="fixed">
    <origin rpy="0 0.34907 0" xyz="0.0073534 0 0.041703" />
    <parent link="left_middle_distal_link" />
    <child link="left_middle_tip_link" />
    <axis xyz="0 0 0" />
  </joint>
  <link name="left_middle_touch_link">
    <inertial>
      <origin rpy="0 0 0" xyz="-0.0032264874449576693 -1.6464806441374979e-08 0.0030199156890812172" />
      <mass value="0.002" />
      <inertia ixx="4.3751562105730887e-08" ixy="0" ixz="1.0061853574977109e-08" iyy="3.6155257950531593e-08" iyz="0" izz="1.9203682361461601e-08" />
    </inertial>
    <visual>
      <origin rpy="0 0 0" xyz="0 0 0" />
      <geometry>
        <mesh filename="../meshes/hands/visual/left/left_middle_touch_link.STL" />
      </geometry>
      <material name="">
        <color rgba="1 1 1 1" />
      </material>
    </visual>
    <collision>
      <origin rpy="0 0 0" xyz="0 0 0" />
      <geometry>
        <mesh filename="../meshes/hands/collision/left/left_middle_touch_link.STL" />
      </geometry>
    </collision>
  </link>
  <joint name="left_middle_touch_joint" type="fixed">
    <origin rpy="0 0.34907 0" xyz="0.012493 0 0.028393" />
    <parent link="left_middle_distal_link" />
    <child link="left_middle_touch_link" />
    <axis xyz="0 0 0" />
  </joint>
  <link name="left_ring_proximal_link">
    <inertial>
      <origin rpy="0 0 0" xyz="-0.002241163016263785 -8.4923846884662759e-07 0.018974576063196438" />
      <mass value="0.0089999999999999993" />
      <inertia ixx="9.21960830860337e-07" ixy="0" ixz="-2.1402177757323032e-08" iyy="8.7978518100134324e-07" iyz="0" izz="2.6981238700334672e-07" />
    </inertial>
    <visual>
      <origin rpy="0 0 0" xyz="0 0 0" />
      <geometry>
        <mesh filename="../meshes/hands/visual/left/left_ring_proximal_link.STL" />
      </geometry>
      <material name="">
        <color rgba="1 1 1 1" />
      </material>
    </visual>
    <collision>
      <origin rpy="0 0 0" xyz="0 0 0" />
      <geometry>
        <mesh filename="../meshes/hands/collision/left/left_ring_proximal_link.STL" />
      </geometry>
    </collision>
  </link>
  <joint name="left_ring_proximal_joint" type="revolute">
    <origin rpy="-0.039462 0.14721 -0.057932" xyz="-0.0046877 0.010026 0.083982" />
    <parent link="left_hand_base_link" />
    <child link="left_ring_proximal_link" />
    <axis xyz="0 1 0" />
    <limit effort="2" lower="0" upper="1.41" velocity="2.2685" />
  </joint>
  <link name="left_ring_distal_link">
    <inertial>
      <origin rpy="0 0 0" xyz="0.0019691538124462942 -3.4712054827091547e-07 0.016229097338575658" />
      <mass value="0.0089999999999999993" />
      <inertia ixx="1.2032005239980334e-06" ixy="0" ixz="-2.3259339845713864e-07" iyy="1.2461108965833513e-06" iyz="0" izz="1.9261810732426007e-07" />
    </inertial>
    <visual>
      <origin rpy="0 0 0" xyz="0 0 0" />
      <geometry>
        <mesh filename="../meshes/hands/visual/left/left_ring_distal_link.STL" />
      </geometry>
      <material name="">
        <color rgba="1 1 1 1" />
      </material>
    </visual>
    <collision>
      <origin rpy="0 0 0" xyz="0 0 0" />
      <geometry>
        <mesh filename="../meshes/hands/collision/left/left_ring_distal_link.STL" />
      </geometry>
    </collision>
  </link>
  <joint name="left_ring_distal_joint" type="revolute">
    <origin rpy="0 0.12654 0" xyz="0 0 0.035" />
    <parent link="left_ring_proximal_link" />
    <child link="left_ring_distal_link" />
    <axis xyz="0 1 0" />
    <limit effort="2" lower="0" upper="1.63" velocity="2.2685" />
    <mimic joint="left_ring_proximal_joint" multiplier="1.155" offset="0" />
  </joint>
  <link name="left_ring_tip_link">
    </link>
  <joint name="left_ring_tip_joint" type="fixed">
    <origin rpy="0 0.34907 0" xyz="0.0071824 0 0.040734" />
    <parent link="left_ring_distal_link" />
    <child link="left_ring_tip_link" />
    <axis xyz="0 0 0" />
  </joint>
  <link name="left_ring_touch_link">
    <inertial>
      <origin rpy="0 0 0" xyz="-0.0030536856758857163 -2.2421376448217619e-08 0.0030774156162143426" />
      <mass value="0.002" />
      <inertia ixx="4.0792303970112657e-08" ixy="0" ixz="9.3093997531703186e-09" iyy="3.3284943655501508e-08" iyz="0" izz="1.7990091011534739e-08" />
    </inertial>
    <visual>
      <origin rpy="0 0 0" xyz="0 0 0" />
      <geometry>
        <mesh filename="../meshes/hands/visual/left/left_ring_touch_link.STL" />
      </geometry>
      <material name="">
        <color rgba="1 1 1 1" />
      </material>
    </visual>
    <collision>
      <origin rpy="0 0 0" xyz="0 0 0" />
      <geometry>
        <mesh filename="../meshes/hands/collision/left/left_ring_touch_link.STL" />
      </geometry>
    </collision>
  </link>
  <joint name="left_ring_touch_joint" type="fixed">
    <origin rpy="0 0.34907 0" xyz="0.012028 0 0.027796" />
    <parent link="left_ring_distal_link" />
    <child link="left_ring_touch_link" />
    <axis xyz="0 0 0" />
  </joint>
  <link name="left_pinky_proximal_link">
    <inertial>
      <origin rpy="0 0 0" xyz="-0.0019751463194913974 6.4981026612137112e-08 0.015824327842517756" />
      <mass value="0.0089999999999999993" />
      <inertia ixx="7.0779884784116139e-07" ixy="0" ixz="-1.3722323933888289e-08" iyy="6.6116859611754332e-07" iyz="0" izz="2.7015041652352649e-07" />
    </inertial>
    <visual>
      <origin rpy="0 0 0" xyz="0 0 0" />
      <geometry>
        <mesh filename="../meshes/hands/visual/left/left_pinky_proximal_link.STL" />
      </geometry>
      <material name="">
        <color rgba="1 1 1 1" />
      </material>
    </visual>
    <collision>
      <origin rpy="0 0 0" xyz="0 0 0" />
      <geometry>
        <mesh filename="../meshes/hands/collision/left/left_pinky_proximal_link.STL" />
      </geometry>
    </collision>
  </link>
  <joint name="left_pinky_proximal_joint" type="revolute">
    <origin rpy="-0.11815 0.14491 -0.17392" xyz="-0.0023733 0.029356 0.078694" />
    <parent link="left_hand_base_link" />
    <child link="left_pinky_proximal_link" />
    <axis xyz="0 1 0" />
    <limit effort="2" lower="0" upper="1.41" velocity="2.2685" />
  </joint>
  <link name="left_pinky_distal_link">
    <inertial>
      <origin rpy="0 0 0" xyz="0.0032566663967065887 6.0349934992072735e-08 0.012848446629738369" />
      <mass value="0.0089999999999999993" />
      <inertia ixx="8.4398368399810062e-07" ixy="0" ixz="-2.5703579314090776e-07" iyy="9.2770964490637625e-07" iyz="0" izz="2.2973324087645152e-07" />
    </inertial>
    <visual>
      <origin rpy="0 0 0" xyz="0 0 0" />
      <geometry>
        <mesh filename="../meshes/hands/visual/left/left_pinky_distal_link.STL" />
      </geometry>
      <material name="">
        <color rgba="1 1 1 1" />
      </material>
    </visual>
    <collision>
      <origin rpy="0 0 0" xyz="0 0 0" />
      <geometry>
        <mesh filename="../meshes/hands/collision/left/left_pinky_distal_link.STL" />
      </geometry>
    </collision>
  </link>
  <joint name="left_pinky_distal_joint" type="revolute">
    <origin rpy="0 0 0" xyz="0 0 0.029" />
    <parent link="left_pinky_proximal_link" />
    <child link="left_pinky_distal_link" />
    <axis xyz="0 1 0" />
    <limit effort="2" lower="0" upper="1.63" velocity="2.2685" />
    <mimic joint="left_pinky_proximal_joint" multiplier="1.155" offset="0" />
  </joint>
  <link name="left_pinky_tip_link">
    </link>
  <joint name="left_pinky_tip_joint" type="fixed">
    <origin rpy="0 0.4756 0" xyz="0.010221 0 0.032918" />
    <parent link="left_pinky_distal_link" />
    <child link="left_pinky_tip_link" />
    <axis xyz="0 0 0" />
  </joint>
  <link name="left_pinky_touch_link">
    <inertial>
      <origin rpy="0 0 0" xyz="-0.0028960060506516769 1.3502056552567891e-08 0.0016531329149271808" />
      <mass value="0.002" />
      <inertia ixx="3.6971683787748592e-08" ixy="0" ixz="7.6565030051316787e-09" iyy="2.8590110714915212e-08" iyz="0" izz="1.7539244571260405e-08" />
    </inertial>
    <visual>
      <origin rpy="0 0 0" xyz="0 0 0" />
      <geometry>
        <mesh filename="../meshes/hands/visual/left/left_pinky_touch_link.STL" />
      </geometry>
      <material name="">
        <color rgba="1 1 1 1" />
      </material>
    </visual>
    <collision>
      <origin rpy="0 0 0" xyz="0 0 0" />
      <geometry>
        <mesh filename="../meshes/hands/collision/left/left_pinky_touch_link.STL" />
      </geometry>
    </collision>
  </link>
  <joint name="left_pinky_touch_joint" type="fixed">
    <origin rpy="0 0.4756 0" xyz="0.01401 0 0.021124" />
    <parent link="left_pinky_distal_link" />
    <child link="left_pinky_touch_link" />
    <axis xyz="0 0 0" />
  </joint>
</robot>