<?xml version='1.0' encoding='utf-8'?>
<robot name="revoarm_single">
  <link name="base_link">
    <inertial>
      <origin rpy="0 0 0" xyz="-0.00044332747291356403 -0.00018960038049865597 0.041658123214062585" />
      <mass value="2.05031149778" />
      <inertia ixx="0.00574143134257215" ixy="-5.947609211488795e-06" ixz="-2.2526485067060592e-05" iyy="0.0039000929392483917" iyz="9.640527208518365e-06" izz="0.004903557716784477" />
    </inertial>
    <visual>
      <origin rpy="0 0 0" xyz="0 0 0" />
      <geometry>
        <mesh filename="../meshes/body/visual/single/base_link.STL" />
      </geometry>
      <material name="">
        <color rgba="0.556863 0.556863 0.556863 1" />
      </material>
    </visual>
    <collision>
      <origin rpy="0 0 0" xyz="0 0 0" />
      <geometry>
        <mesh filename="../meshes/body/collision/single/base_link.STL" />
      </geometry>
    </collision>
  </link>
  <joint name="right_base_joint" type="fixed">
    <parent link="base_link" />
    <child link="right_base_link" />
    <origin rpy="-1.5708 0 0" xyz="0 0 0.0997" />
  </joint>
  <link name="right_base_link" />
  <link name="right_arm_link1">
    <inertial>
      <origin rpy="0 0 0" xyz="0.001382612465367731 -0.052712342946782335 -0.0012165214801131664" />
      <mass value="0.99862" />
      <inertia ixx="0.0013454491322157436" ixy="9.357367309461081e-06" ixz="3.478204709148893e-07" iyy="0.0008341355869281277" iyz="4.903673631863885e-05" izz="0.0010334387005480317" />
    </inertial>
    <visual>
      <origin rpy="0 0 0" xyz="0 0 0" />
      <geometry>
        <mesh filename="../meshes/arm/visual/right_arm_link1.STL" />
      </geometry>
      <material name="">
        <color rgba="0.89804 0.91765 0.92941 1" />
      </material>
    </visual>
    <collision>
      <origin rpy="0 0 0" xyz="0 0 0" />
      <geometry>
        <mesh filename="../meshes/arm/collision/right_arm_link1.STL" />
      </geometry>
    </collision>
  </link>
  <joint name="revoarm_right_joint1" type="revolute">
    <origin rpy="0 1.5708 0" xyz="0 0 0" />
    <parent link="right_base_link" />
    <child link="right_arm_link1" />
    <axis xyz="0 1 0" />
    <limit effort="40" lower="-4.1015" upper="0.7854" velocity="2.792" />
  </joint>
  <link name="right_arm_link2">
    <inertial>
      <origin rpy="0 0 0" xyz="5.452832766175412e-06 -0.00028243118094375947 -0.026891342134806036" />
      <mass value="0.1942" />
      <inertia ixx="0.0003826255144247354" ixy="9.486795520508637e-07" ixz="-2.1848535528029543e-06" iyy="0.0003692337436614689" iyz="2.313823793144637e-06" izz="0.00020728050191330547" />
    </inertial>
    <visual>
      <origin rpy="0 0 0" xyz="0 0 0" />
      <geometry>
        <mesh filename="../meshes/arm/visual/right_arm_link2.STL" />
      </geometry>
      <material name="">
        <color rgba="0.556863 0.556863 0.556863 1" />
      </material>
    </visual>
    <collision>
      <origin rpy="0 0 0" xyz="0 0 0" />
      <geometry>
        <mesh filename="../meshes/arm/collision/right_arm_link2.STL" />
      </geometry>
    </collision>
  </link>
  <joint name="revoarm_right_joint2" type="revolute">
    <origin rpy="-1.5708 0 0" xyz="0 -0.06 0" />
    <parent link="right_arm_link1" />
    <child link="right_arm_link2" />
    <axis xyz="-1 0 0" />
    <limit effort="40" lower="-1.7453" upper="1.7453" velocity="2.792" />
  </joint>
  <link name="right_arm_link3">
    <inertial>
      <origin rpy="0 0 0" xyz="-0.0004545696147919951 3.124497872877622e-05 -0.06669396716612074" />
      <mass value="0.56897" />
      <inertia ixx="0.001342436554031375" ixy="-1.1015969569091774e-06" ixz="-8.986727133401938e-06" iyy="0.0013131089829151352" iyz="1.8766376444528735e-06" izz="0.0004921543202930038" />
    </inertial>
    <visual>
      <origin rpy="0 0 0" xyz="0 0 0" />
      <geometry>
        <mesh filename="../meshes/arm/visual/right_arm_link3.STL" />
      </geometry>
      <material name="">
        <color rgba="0.054902 0.054902 0.054902 1" />
      </material>
    </visual>
    <collision>
      <origin rpy="0 0 0" xyz="0 0 0" />
      <geometry>
        <mesh filename="../meshes/arm/collision/right_arm_link3.STL" />
      </geometry>
    </collision>
  </link>
  <joint name="revoarm_right_joint3" type="revolute">
    <origin rpy="0 0 1.5708" xyz="0 0 -0.099" />
    <parent link="right_arm_link2" />
    <child link="right_arm_link3" />
    <axis xyz="0 0 1" />
    <limit effort="27" lower="-3.6652" upper="0.5236" velocity="1.745" />
  </joint>
  <link name="right_arm_link4">
    <inertial>
      <origin rpy="0 0 0" xyz="-7.585570779113467e-06 0.0003510704511493275 -0.02538448707879066" />
      <mass value="0.43039" />
      <inertia ixx="0.00047306084260980287" ixy="1.3323690129685178e-07" ixz="-1.0905992016120662e-06" iyy="0.00047377939083966165" iyz="-2.6711329620963666e-06" izz="0.0002759998800131494" />
    </inertial>
    <visual>
      <origin rpy="0 0 0" xyz="0 0 0" />
      <geometry>
        <mesh filename="../meshes/arm/visual/right_arm_link4.STL" />
      </geometry>
      <material name="">
        <color rgba="0.556863 0.556863 0.556863 1" />
      </material>
    </visual>
    <collision>
      <origin rpy="0 0 0" xyz="0 0 0" />
      <geometry>
        <mesh filename="../meshes/arm/collision/right_arm_link4.STL" />
      </geometry>
    </collision>
  </link>
  <joint name="revoarm_right_joint4" type="revolute">
    <origin rpy="0 0.0 0" xyz="0 0 -0.121" />
    <parent link="right_arm_link3" />
    <child link="right_arm_link4" />
    <axis xyz="0 -1 0" />
    <limit effort="27" lower="-0.34907" upper="2.2166" velocity="1.745" />
  </joint>
  <link name="right_arm_link5">
    <inertial>
      <origin rpy="0 0 0" xyz="0.0009150768289936717 1.834968667242696e-05 -0.07514702828445248" />
      <mass value="0.80969" />
      <inertia ixx="0.001829311510089025" ixy="9.374941322173225e-07" ixz="3.673713321385765e-05" iyy="0.0018345098956241942" iyz="-1.6270176108032502e-06" izz="0.000560869910640031" />
    </inertial>
    <visual>
      <origin rpy="0 0 0" xyz="0 0 0" />
      <geometry>
        <mesh filename="../meshes/arm/visual/right_arm_link5.STL" />
      </geometry>
      <material name="">
        <color rgba="0.054902 0.054902 0.054902 1" />
      </material>
    </visual>
    <collision>
      <origin rpy="0 0 0" xyz="0 0 0" />
      <geometry>
        <mesh filename="../meshes/arm/collision/right_arm_link5.STL" />
      </geometry>
    </collision>
  </link>
  <joint name="revoarm_right_joint5" type="revolute">
    <origin rpy="0 0 0.0" xyz="0 0 -0.0635" />
    <parent link="right_arm_link4" />
    <child link="right_arm_link5" />
    <axis xyz="0 0 1" />
    <limit effort="7" lower="-3.1444" upper="0.9044" velocity="6.98" />
  </joint>
  <link name="right_arm_link6">
    <inertial>
      <origin rpy="0 0 0" xyz="0.00017945944403328923 0.0010005698320528372 -2.47524159457321e-05" />
      <mass value="0.31466" />
      <inertia ixx="0.00012089545378700789" ixy="2.385592039940795e-07" ixz="-7.17472862339045e-08" iyy="0.00013671438156731276" iyz="2.583665322590944e-07" izz="0.00013749574401418263" />
    </inertial>
    <visual>
      <origin rpy="0 0 0" xyz="0 0 0" />
      <geometry>
        <mesh filename="../meshes/arm/visual/right_arm_link6.STL" />
      </geometry>
      <material name="">
        <color rgba="0.556863 0.556863 0.556863 1" />
      </material>
    </visual>
    <collision>
      <origin rpy="0 0 0" xyz="0 0 0" />
      <geometry>
        <mesh filename="../meshes/arm/collision/right_arm_link6.STL" />
      </geometry>
    </collision>
  </link>
  <joint name="revoarm_right_joint6" type="revolute">
    <origin rpy="0.0 0 0" xyz="0 0 -0.1525" />
    <parent link="right_arm_link5" />
    <child link="right_arm_link6" />
    <axis xyz="1 0 0" />
    <limit effort="7" lower="-0.64577" upper="0.64577" velocity="6.98" />
  </joint>
  
  <link name="right_arm_link7">
    <inertial>
      <origin rpy="0 0 0" xyz="0 0 0" />
      <mass value="0.0" />
      <inertia ixx="1e-09" ixy="0" ixz="0" iyy="1e-09" iyz="0" izz="1e-09" />
    </inertial>
  </link>
  <joint name="revoarm_right_joint7" type="revolute">
    <origin rpy="0.0019404 0.0 0" xyz="0 0 0" />
    <parent link="right_arm_link6" />
    <child link="right_arm_link7" />
    <axis xyz="0 -1 0" />
    <limit effort="7" lower="-1.5708" upper="1.5708" velocity="6.98" />
  </joint>
  
  <link name="right_connector_link">
    <inertial>
      <origin rpy="0 0 0" xyz="-0.0001127897191147954 3.154095953719937e-05 0.033255098703552484" />
      <mass value="0.49311" />
      <inertia ixx="0.00036354132395392217" ixy="-1.8696439735909203e-06" ixz="-1.2524578426564315e-06" iyy="0.0002280032694205684" iyz="-5.077766344224587e-06" izz="0.00026796699787763335" />
    </inertial>
    <visual>
      <origin rpy="0 0 0" xyz="0 0 0" />
      <geometry>
        <mesh filename="../meshes/connector/visual/right_revo3_connector.STL" />
      </geometry>
      <material name="">
        <color rgba="0.79216 0.81961 0.93333 1.0" />
      </material>
    </visual>
    <collision>
      <origin rpy="0 0 0" xyz="0 0 0" />
      <geometry>
        <mesh filename="../meshes/connector/collision/right_revo3_connector.STL" />
      </geometry>
    </collision>
  </link>
  
  <joint name="right_connector_mount" type="fixed">
    <parent link="right_arm_link7" />
    <child link="right_connector_link" />
    <origin rpy="0 0 0" xyz="0 0 -0.06054" />
  </joint>
  
  <link name="right_connector_tip" />
  <joint name="right_connector_tip_joint" type="fixed">
    <parent link="right_connector_link" />
    <child link="right_connector_tip" />
    <origin rpy="0 3.14 0" xyz="0.0 0.0 0.0" />
  </joint>
  
  <joint name="right_hand_base_joint" type="fixed">
    <parent link="right_connector_tip" />
    <child link="right_hand_base_link" />
    <origin rpy="0 0 0" xyz="0 0 -0.0118" />
  </joint>
  <link name="right_palm">
    <inertial>
      <origin rpy="0 0 0" xyz="0 0 0" />
      <mass value="0.000" />
      <inertia ixx="0.000001" ixy="0" ixz="0" iyy="0.000001" iyz="0" izz="0.000001" />
    </inertial>
  </link>
  <joint name="right_palm_center" type="fixed">
    <parent link="right_hand_base_link" />
    <child link="right_palm" />
    <origin rpy="0 0 0" xyz="0.0155 0 0.055" />
  </joint>
  <link name="right_hand_base_link">
    <inertial>
      <origin rpy="0 0 0" xyz="-0.00345736 0.00054338 0.03983468" />
      <mass value="0.462" />
      <inertia ixx="0.00080601" ixy="0.00001197" ixz="0.00005633" iyy="0.00061040" iyz="-0.00001657" izz="0.00041275" />
    </inertial>
    <visual>
      <origin rpy="0 0 0" xyz="0 0 0" />
      <geometry>
        <mesh filename="../meshes/hands/visual/right/base_link.STL" />
      </geometry>
      <material name="">
        <color rgba="0.792156862745098 0.819607843137255 0.933333333333333 1" />
      </material>
    </visual>
    <collision>
      <origin rpy="0 0 0" xyz="0 0 0" />
      <geometry>
        <mesh filename="../meshes/hands/collision/right/part_000.obj" />
      </geometry>
    </collision>
    <collision>
      <origin rpy="0 0 0" xyz="0 0 0" />
      <geometry>
        <mesh filename="../meshes/hands/collision/right/part_001.obj" />
      </geometry>
    </collision>
    <collision>
      <origin rpy="0 0 0" xyz="0 0 0" />
      <geometry>
        <mesh filename="../meshes/hands/collision/right/part_002.obj" />
      </geometry>
    </collision>
    <collision>
      <origin rpy="0 0 0" xyz="0 0 0" />
      <geometry>
        <mesh filename="../meshes/hands/collision/right/part_003.obj" />
      </geometry>
    </collision>
    <collision>
      <origin rpy="0 0 0" xyz="0 0 0" />
      <geometry>
        <mesh filename="../meshes/hands/collision/right/part_004.obj" />
      </geometry>
    </collision>
    <collision>
      <origin rpy="0 0 0" xyz="0 0 0" />
      <geometry>
        <mesh filename="../meshes/hands/collision/right/part_005.obj" />
      </geometry>
    </collision>
    <collision>
      <origin rpy="0 0 0" xyz="0 0 0" />
      <geometry>
        <mesh filename="../meshes/hands/collision/right/part_006.obj" />
      </geometry>
    </collision>
    <collision>
      <origin rpy="0 0 0" xyz="0 0 0" />
      <geometry>
        <mesh filename="../meshes/hands/collision/right/part_007.obj" />
      </geometry>
    </collision>
    <collision>
      <origin rpy="0 0 0" xyz="0 0 0" />
      <geometry>
        <mesh filename="../meshes/hands/collision/right/part_008.obj" />
      </geometry>
    </collision>
    <collision>
      <origin rpy="0 0 0" xyz="0 0 0" />
      <geometry>
        <mesh filename="../meshes/hands/collision/right/part_009.obj" />
      </geometry>
    </collision>
    <collision>
      <origin rpy="0 0 0" xyz="0 0 0" />
      <geometry>
        <mesh filename="../meshes/hands/collision/right/part_010.obj" />
      </geometry>
    </collision>
    <collision>
      <origin rpy="0 0 0" xyz="0 0 0" />
      <geometry>
        <mesh filename="../meshes/hands/collision/right/part_011.obj" />
      </geometry>
    </collision>
    <collision>
      <origin rpy="0 0 0" xyz="0 0 0" />
      <geometry>
        <mesh filename="../meshes/hands/collision/right/part_012.obj" />
      </geometry>
    </collision>
    <collision>
      <origin rpy="0 0 0" xyz="0 0 0" />
      <geometry>
        <mesh filename="../meshes/hands/collision/right/part_013.obj" />
      </geometry>
    </collision>
    <collision>
      <origin rpy="0 0 0" xyz="0 0 0" />
      <geometry>
        <mesh filename="../meshes/hands/collision/right/part_014.obj" />
      </geometry>
    </collision>
    <collision>
      <origin rpy="0 0 0" xyz="0 0 0" />
      <geometry>
        <mesh filename="../meshes/hands/collision/right/part_015.obj" />
      </geometry>
    </collision>
    <collision>
      <origin rpy="0 0 0" xyz="0 0 0" />
      <geometry>
        <mesh filename="../meshes/hands/collision/right/part_016.obj" />
      </geometry>
    </collision>
    <collision>
      <origin rpy="0 0 0" xyz="0 0 0" />
      <geometry>
        <mesh filename="../meshes/hands/collision/right/part_017.obj" />
      </geometry>
    </collision>
    <collision>
      <origin rpy="0 0 0" xyz="0 0 0" />
      <geometry>
        <mesh filename="../meshes/hands/collision/right/part_018.obj" />
      </geometry>
    </collision>
    <collision>
      <origin rpy="0 0 0" xyz="0 0 0" />
      <geometry>
        <mesh filename="../meshes/hands/collision/right/part_019.obj" />
      </geometry>
    </collision>
    <collision>
      <origin rpy="0 0 0" xyz="0 0 0" />
      <geometry>
        <mesh filename="../meshes/hands/collision/right/part_020.obj" />
      </geometry>
    </collision>
    <collision>
      <origin rpy="0 0 0" xyz="0 0 0" />
      <geometry>
        <mesh filename="../meshes/hands/collision/right/part_021.obj" />
      </geometry>
    </collision>
    <collision>
      <origin rpy="0 0 0" xyz="0 0 0" />
      <geometry>
        <mesh filename="../meshes/hands/collision/right/part_022.obj" />
      </geometry>
    </collision>
    <collision>
      <origin rpy="0 0 0" xyz="0 0 0" />
      <geometry>
        <mesh filename="../meshes/hands/collision/right/part_023.obj" />
      </geometry>
    </collision>
    <collision>
      <origin rpy="0 0 0" xyz="0 0 0" />
      <geometry>
        <mesh filename="../meshes/hands/collision/right/part_024.obj" />
      </geometry>
    </collision>
    <collision>
      <origin rpy="0 0 0" xyz="0 0 0" />
      <geometry>
        <mesh filename="../meshes/hands/collision/right/part_025.obj" />
      </geometry>
    </collision>
    <collision>
      <origin rpy="0 0 0" xyz="0 0 0" />
      <geometry>
        <mesh filename="../meshes/hands/collision/right/part_026.obj" />
      </geometry>
    </collision>
    <collision>
      <origin rpy="0 0 0" xyz="0 0 0" />
      <geometry>
        <mesh filename="../meshes/hands/collision/right/part_027.obj" />
      </geometry>
    </collision>
  </link>
  <link name="right_thumb_CMP_Link">
    <inertial>
      <origin rpy="0 0 0" xyz="0 0 0" />
      <mass value="0.026" />
      <inertia ixx="0.00000203" ixy="0.00000000" ixz="0.00000000" iyy="0.00000229" iyz="0.00000000" izz="0.00000222" />
    </inertial>
    <visual>
      <origin rpy="0 0 0" xyz="0 0 0" />
      <geometry>
        <mesh filename="../meshes/hands/visual/right/right_thumb_CMP_Link.STL" />
      </geometry>
      <material name="">
        <color rgba="0.792156862745098 0.819607843137255 0.933333333333333 1" />
      </material>
    </visual>
    <collision>
      <origin rpy="0 0 0" xyz="0 0 0" />
      <geometry>
        <mesh filename="../meshes/hands/collision/right/right_thumb_CMP_Link.STL" />
      </geometry>
    </collision>
  </link>
  <joint name="right_thumb_CMP_joint" type="revolute">
    <origin rpy="0 0 0" xyz="0.002 0.0195 0.051993" />
    <parent link="right_hand_base_link" />
    <child link="right_thumb_CMP_Link" />
    <axis xyz="0 0 -1" />
    <limit effort="0.35" lower="0" upper="1.9199" velocity="6.28" />
  </joint>
  <link name="right_thumb_CMR_Link">
    <inertial>
      <origin rpy="0 0 0" xyz="0.00000000 0.00601571 -0.00128638" />
      <mass value="0.012" />
      <inertia ixx="0.00000057" ixy="0.00000000" ixz="0.00000000" iyy="0.00000095" iyz="0.00000002" izz="0.00000093" />
    </inertial>
    <visual>
      <origin rpy="0 0 0" xyz="0 0 0" />
      <geometry>
        <mesh filename="../meshes/hands/visual/right/right_thumb_CMR_Link.STL" />
      </geometry>
      <material name="">
        <color rgba="0.792156862745098 0.819607843137255 0.933333333333333 1" />
      </material>
    </visual>
    <collision>
      <origin rpy="0 0 0" xyz="0 0 0" />
      <geometry>
        <mesh filename="../meshes/hands/collision/right/right_thumb_CMR_Link.STL" />
      </geometry>
    </collision>
  </link>
  <joint name="right_thumb_CMR_joint" type="revolute">
    <origin rpy="0 1.57 0" xyz="0 0.0095 0" />
    <parent link="right_thumb_CMP_Link" />
    <child link="right_thumb_CMR_Link" />
    <axis xyz="0 -1 0" />
    <limit effort="0.35" lower="0" upper="2.0071" velocity="6.28" />
  </joint>
  <link name="right_thumb_MCP_Link">
    <inertial>
      <origin rpy="0 0 0" xyz="0.00001270 0.02200879 -0.00233775" />
      <mass value="0.067" />
      <inertia ixx="0.00001460" ixy="-0.00000002" ixz="0.00000000" iyy="0.00000660" iyz="0.00000080" izz="0.00001422" />
    </inertial>
    <visual>
      <origin rpy="0 0 0" xyz="0 0 0" />
      <geometry>
        <mesh filename="../meshes/hands/visual/right/right_thumb_MCP_Link.STL" />
      </geometry>
      <material name="">
        <color rgba="0.792156862745098 0.819607843137255 0.933333333333333 1" />
      </material>
    </visual>
    <collision>
      <origin rpy="0 0 0" xyz="0 0 0" />
      <geometry>
        <mesh filename="../meshes/hands/collision/right/right_thumb_MCP_Link.STL" />
      </geometry>
    </collision>
  </link>
  <joint name="right_thumb_MCP_joint" type="revolute">
    <origin rpy="0 0 0" xyz="0 0.0125 0" />
    <parent link="right_thumb_CMR_Link" />
    <child link="right_thumb_MCP_Link" />
    <axis xyz="1 0 0" />
    <limit effort="0.35" lower="0" upper="0.8727" velocity="6.28" />
  </joint>
  <link name="right_thumb_PIP_Link">
    <inertial>
      <origin rpy="0 0 0" xyz="2.72468422550815E-05 0.0196639755384296 -0.000959024619272792" />
      <mass value="0.035" />
      <inertia ixx="0.00000331" ixy="-0.00000003" ixz="0.00000000" iyy="0.00000269" iyz="-0.00000003" izz="0.00000407" />
    </inertial>
    <visual>
      <origin rpy="0 0 0" xyz="0 0 0" />
      <geometry>
        <mesh filename="../meshes/hands/visual/right/right_thumb_PIP_Link.STL" />
      </geometry>
      <material name="">
        <color rgba="0.792156862745098 0.819607843137255 0.933333333333333 1" />
      </material>
    </visual>
    <collision>
      <origin rpy="0 0 0" xyz="0 0 0" />
      <geometry>
        <mesh filename="../meshes/hands/collision/right/right_thumb_PIP_Link.STL" />
      </geometry>
    </collision>
  </link>
  <joint name="right_thumb_PIP_joint" type="revolute">
    <origin rpy="0 0 0" xyz="0.0001 0.042087 -0.0013667" />
    <parent link="right_thumb_MCP_Link" />
    <child link="right_thumb_PIP_Link" />
    <axis xyz="1 0 0" />
    <limit effort="0.35" lower="0" upper="1.4835" velocity="6.28" />
  </joint>
  <link name="right_thumb_DIP_Link">
    <inertial>
      <origin rpy="0 0 0" xyz="-0.00006365 0.01533800 -0.00158245" />
      <mass value="0.010" />
      <inertia ixx="0.00000149" ixy="0.00000002" ixz="0.00000000" iyy="0.00000096" iyz="-0.00000024" izz="0.00000155" />
    </inertial>
    <visual>
      <origin rpy="0 0 0" xyz="0 0 0" />
      <geometry>
        <mesh filename="../meshes/hands/visual/right/right_thumb_DIP_Link.STL" />
      </geometry>
      <material name="">
        <color rgba="0.792156862745098 0.819607843137255 0.933333333333333 1" />
      </material>
    </visual>
    <collision>
      <origin rpy="0 0 0" xyz="0 0 0" />
      <geometry>
        <mesh filename="../meshes/hands/collision/right/right_thumb_DIP_Link.STL" />
      </geometry>
    </collision>
  </link>
  <joint name="right_thumb_DIP_joint" type="revolute">
    <origin rpy="0 0 0" xyz="0.000125 0.032 -0.00052077" />
    <parent link="right_thumb_PIP_Link" />
    <child link="right_thumb_DIP_Link" />
    <axis xyz="1 0 0" />
    <limit effort="0.35" lower="0" upper="1.4835" velocity="6.28" />
  </joint>
  <link name="right_thumb_tip_Link">
    <inertial>
      <origin rpy="0 0 0" xyz="0 0 0" />
      <mass value="0.001" />
      <inertia ixx="0.0000000001" ixy="0" ixz="0" iyy="0.0000000001" iyz="0" izz="0.000000001" />
    </inertial>
  </link>
  <joint name="right_thumb_tip_joint" type="fixed">
    <origin rpy="0 0 0" xyz="0 0.01 0.0098" />
    <parent link="right_thumb_DIP_Link" />
    <child link="right_thumb_tip_Link" />
    <axis xyz="0 0 0" />
  </joint>
  <link name="right_index_MPR_Link">
    <inertial>
      <origin rpy="0 0 0" xyz="-0.00223218743935583 0.000719586142970907 0.00541673485893115" />
      <mass value="0.013" />
      <inertia ixx="0.00000042" ixy="0" ixz="0" iyy="0.00000042" iyz="0" izz="0.00000042" />
    </inertial>
    <visual>
      <origin rpy="0 0 0" xyz="0 0 0" />
      <geometry>
        <mesh filename="../meshes/hands/visual/right/right_index_MPR_Link.STL" />
      </geometry>
      <material name="">
        <color rgba="0.792156862745098 0.819607843137255 0.933333333333333 1" />
      </material>
    </visual>
    <collision>
      <origin rpy="0 0 0" xyz="0 0 0" />
      <geometry>
        <mesh filename="../meshes/hands/collision/right/right_index_MPR_Link.STL" />
      </geometry>
    </collision>
  </link>
  <joint name="right_index_MPR_joint" type="revolute">
    <origin rpy="0 0 0" xyz="-0.005442 0.036871 0.097822" />
    <parent link="right_hand_base_link" />
    <child link="right_index_MPR_Link" />
    <axis xyz="0.99836 -0.057297 0" />
    <limit effort="0.35" lower="-0.2618" upper="0.2618" velocity="6.28" />
  </joint>
  <link name="right_index_MCP_Link">
    <inertial>
      <origin rpy="0 0 0" xyz="-2.40856439470052E-05 0.00140938308494733 0.0229088413322571" />
      <mass value="0.0658" />
      <inertia ixx="0.00001192" ixy="-0.00000001" ixz="0" iyy="0.00001164" iyz="-0.00000049" izz="0.00000376" />
    </inertial>
    <visual>
      <origin rpy="0 0 0" xyz="0 0 0" />
      <geometry>
        <mesh filename="../meshes/hands/visual/right/right_index_MCP_Link.STL" />
      </geometry>
      <material name="">
        <color rgba="0.792156862745098 0.819607843137255 0.933333333333333 1" />
      </material>
    </visual>
    <collision>
      <origin rpy="0 0 0" xyz="0 0 0" />
      <geometry>
        <mesh filename="../meshes/hands/collision/right/right_index_MCP_Link.STL" />
      </geometry>
    </collision>
  </link>
  <joint name="right_index_MCP_joint" type="revolute">
    <origin rpy="0 0 0" xyz="5.6148E-05 0.00097833 0.01597" />
    <parent link="right_index_MPR_Link" />
    <child link="right_index_MCP_Link" />
    <axis xyz="0.05719 0.99648 -0.061246" />
    <limit effort="0.35" lower="0" upper="1.4835" velocity="6.28" />
  </joint>
  <link name="right_index_PIP_Link">
    <inertial>
      <origin rpy="0 0 0" xyz="0.000370302095446862 0.00104638125778082 0.018249278978223" />
      <mass value="0.0332" />
      <inertia ixx="0.00000252" ixy="-0.00000001" ixz="-0.00000003" iyy="0.00000233" iyz="-0.00000003" izz="0.00000184" />
    </inertial>
    <visual>
      <origin rpy="0 0 0" xyz="0 0 0" />
      <geometry>
        <mesh filename="../meshes/hands/visual/right/right_index_PIP_Link.STL" />
      </geometry>
      <material name="">
        <color rgba="0.792156862745098 0.819607843137255 0.933333333333333 1" />
      </material>
    </visual>
    <collision>
      <origin rpy="0 0 0" xyz="0 0 0" />
      <geometry>
        <mesh filename="../meshes/hands/collision/right/right_index_PIP_Link.STL" />
      </geometry>
    </collision>
  </link>
  <joint name="right_index_PIP_joint" type="revolute">
    <origin rpy="0 0 0" xyz="0.00074566 0.0028407 0.046916" />
    <parent link="right_index_MCP_Link" />
    <child link="right_index_PIP_Link" />
    <axis xyz="0.05719 0.99648 -0.061245" />
    <limit effort="0.35" lower="0" upper="1.4835" velocity="6.28" />
  </joint>
  <link name="right_index_DIP_Link">
    <inertial>
      <origin rpy="0 0 0" xyz="-0.000421264678793044 0.000956967726905893 0.0155551999344334" />
      <mass value="0.010" />
      <inertia ixx="0.00000064" ixy="0" ixz="0.00000003" iyy="0.00000057" iyz="0" izz="0.00000048" />
    </inertial>
    <visual>
      <origin rpy="0 0 0" xyz="0 0 0" />
      <geometry>
        <mesh filename="../meshes/hands/visual/right/right_index_DIP_Link.STL" />
      </geometry>
      <material name="">
        <color rgba="0.898039215686275 0.917647058823529 0.929411764705882 1" />
      </material>
    </visual>
    <collision>
      <origin rpy="0 0 0" xyz="0 0 0" />
      <geometry>
        <mesh filename="../meshes/hands/collision/right/right_index_DIP_Link.STL" />
      </geometry>
    </collision>
  </link>
  <joint name="right_index_DIP_joint" type="revolute">
    <origin rpy="0 0 0" xyz="0.0013627 0.0017313 0.029441" />
    <parent link="right_index_PIP_Link" />
    <child link="right_index_DIP_Link" />
    <axis xyz="0.05719 0.99648 -0.061255" />
    <limit effort="0.35" lower="0" upper="1.4835" velocity="6.28" />
  </joint>
  <link name="right_index_tip_Link">
    <inertial>
      <origin rpy="0 0 0" xyz="0 0 0" />
      <mass value="0.001" />
      <inertia ixx="0.0000000001" ixy="0" ixz="0" iyy="0.0000000001" iyz="0" izz="0.000000001" />
    </inertial>
  </link>
  <joint name="right_index_tip_joint" type="fixed">
    <origin rpy="0 0 0" xyz="0.0084 0.0005 0.01" />
    <parent link="right_index_DIP_Link" />
    <child link="right_index_tip_Link" />
    <axis xyz="0 0 0" />
  </joint>
  <link name="right_middle_MPR_Link">
    <inertial>
      <origin rpy="0 0 0" xyz="-0.00226228401898452 0.000412100759088652 0.00543632642356778" />
      <mass value="0.013" />
      <inertia ixx="0.00000042" ixy="0" ixz="0" iyy="0.00000042" iyz="0" izz="0.00000042" />
    </inertial>
    <visual>
      <origin rpy="0 0 0" xyz="0 0 0" />
      <geometry>
        <mesh filename="../meshes/hands/visual/right/right_middle_MPR_Link.STL" />
      </geometry>
      <material name="">
        <color rgba="0.792156862745098 0.819607843137255 0.933333333333333 1" />
      </material>
    </visual>
    <collision>
      <origin rpy="0 0 0" xyz="0 0 0" />
      <geometry>
        <mesh filename="../meshes/hands/collision/right/right_middle_MPR_Link.STL" />
      </geometry>
    </collision>
  </link>
  <joint name="right_middle_MPR_joint" type="revolute">
    <origin rpy="0 0 0" xyz="-0.0060223 0.012496 0.10793" />
    <parent link="right_hand_base_link" />
    <child link="right_middle_MPR_Link" />
    <axis xyz="0.99982 -0.019105 0" />
    <limit effort="0.35" lower="-0.2618" upper="0.2618" velocity="6.28" />
  </joint>
  <link name="right_middle_MCP_Link">
    <inertial>
      <origin rpy="0 0 0" xyz="-9.58184291929209E-05 0.000470872880033474 0.0229471333965294" />
      <mass value="0.0658" />
      <inertia ixx="0.00001192" ixy="0.00000003" ixz="0.00000003" iyy="0.00001167" iyz="-0.00000014" izz="0.00000374" />
    </inertial>
    <visual>
      <origin rpy="0 0 0" xyz="0 0 0" />
      <geometry>
        <mesh filename="../meshes/hands/visual/right/right_middle_MCP_Link.STL" />
      </geometry>
      <material name="">
        <color rgba="0.792156862745098 0.819607843137255 0.933333333333333 1" />
      </material>
    </visual>
    <collision>
      <origin rpy="0 0 0" xyz="0 0 0" />
      <geometry>
        <mesh filename="../meshes/hands/collision/right/right_middle_MCP_Link.STL" />
      </geometry>
    </collision>
  </link>
  <joint name="right_middle_MCP_joint" type="revolute">
    <origin rpy="0 0 0" xyz="0 0.00032687 0.015997" />
    <parent link="right_middle_MPR_Link" />
    <child link="right_middle_MCP_Link" />
    <axis xyz="0.019101 0.99961 -0.020433" />
    <limit effort="0.35" lower="0" upper="1.4835" velocity="6.28" />
  </joint>
  <link name="right_middle_PIP_Link">
    <inertial>
      <origin rpy="0 0 0" xyz="0.000315792331514126 0.000313740806259835 0.0182775844652326" />
      <mass value="0.0332" />
      <inertia ixx="0.00000252" ixy="0" ixz="-0.00000003" iyy="0.00000233" iyz="0" izz="0.00000183" />
    </inertial>
    <visual>
      <origin rpy="0 0 0" xyz="0 0 0" />
      <geometry>
        <mesh filename="../meshes/hands/visual/right/right_middle_PIP_Link.STL" />
      </geometry>
      <material name="">
        <color rgba="0.792156862745098 0.819607843137255 0.933333333333333 1" />
      </material>
    </visual>
    <collision>
      <origin rpy="0 0 0" xyz="0 0 0" />
      <geometry>
        <mesh filename="../meshes/hands/collision/right/right_middle_PIP_Link.STL" />
      </geometry>
    </collision>
  </link>
  <joint name="right_middle_PIP_joint" type="revolute">
    <origin rpy="0 0 0" xyz="0.00059991 0.00094912 0.046994" />
    <parent link="right_middle_MCP_Link" />
    <child link="right_middle_PIP_Link" />
    <axis xyz="0.019101 0.99961 -0.020432" />
    <limit effort="0.35" lower="0" upper="1.4835" velocity="6.28" />
  </joint>
  <link name="right_middle_DIP_Link">
    <inertial>
      <origin rpy="0 0 0" xyz="-0.000469437908234031 0.000304801770127686 0.0155807548985219" />
      <mass value="0.010" />
      <inertia ixx="0.00000064" ixy="0" ixz="0.00000003" iyy="0.00000057" iyz="0" izz="0.00000048" />
    </inertial>
    <visual>
      <origin rpy="0 0 0" xyz="0 0 0" />
      <geometry>
        <mesh filename="../meshes/hands/visual/right/right_middle_DIP_Link.STL" />
      </geometry>
      <material name="">
        <color rgba="0.898039215686275 0.917647058823529 0.929411764705882 1" />
      </material>
    </visual>
    <collision>
      <origin rpy="0 0 0" xyz="0 0 0" />
      <geometry>
        <mesh filename="../meshes/hands/collision/right/right_middle_DIP_Link.STL" />
      </geometry>
    </collision>
  </link>
  <joint name="right_middle_DIP_joint" type="revolute">
    <origin rpy="0 0 0" xyz="0.0012725 0.00057847 0.02949" />
    <parent link="right_middle_PIP_Link" />
    <child link="right_middle_DIP_Link" />
    <axis xyz="0.019101 0.99961 -0.020443" />
    <limit effort="0.35" lower="0" upper="1.4835" velocity="6.28" />
  </joint>
  <link name="right_middle_tip_Link">
    <inertial>
      <origin rpy="0 0 0" xyz="0 0 0" />
      <mass value="0.001" />
      <inertia ixx="0.0000000001" ixy="0" ixz="0" iyy="0.0000000001" iyz="0" izz="0.000000001" />
    </inertial>
  </link>
  <joint name="right_middle_tip_joint" type="fixed">
    <origin rpy="0 0 0" xyz="0.0084 -0.0 0.01" />
    <parent link="right_middle_DIP_Link" />
    <child link="right_middle_tip_Link" />
    <axis xyz="0 0 0" />
  </joint>
  <link name="right_ring_MPR_Link">
    <inertial>
      <origin rpy="0 0 0" xyz="-0.00222213402037077 0.000103943894861984 0.00544684832540869" />
      <mass value="0.013" />
      <inertia ixx="0.00000042" ixy="0" ixz="0" iyy="0.00000042" iyz="0" izz="0.00000042" />
    </inertial>
    <visual>
      <origin rpy="0 0 0" xyz="0 0 0" />
      <geometry>
        <mesh filename="../meshes/hands/visual/right/right_ring_MPR_Link.STL" />
      </geometry>
      <material name="">
        <color rgba="0.792156862745098 0.819607843137255 0.933333333333333 1" />
      </material>
    </visual>
    <collision>
      <origin rpy="0 0 0" xyz="0 0 0" />
      <geometry>
        <mesh filename="../meshes/hands/collision/right/right_ring_MPR_Link.STL" />
      </geometry>
    </collision>
  </link>
  <joint name="right_ring_MPR_joint" type="revolute">
    <origin rpy="0 0 0" xyz="-0.0062466 -0.012415 0.10384" />
    <parent link="right_hand_base_link" />
    <child link="right_ring_MPR_Link" />
    <axis xyz="0.99982 0.019105 0" />
    <limit effort="0.35" lower="-0.2618" upper="0.2618" velocity="6.28" />
  </joint>
  <link name="right_ring_MCP_Link">
    <inertial>
      <origin rpy="0 0 0" xyz="-4.58227668414394E-05 -0.000469969862117097 0.0229471407955383" />
      <mass value="0.0658" />
      <inertia ixx="0.00001192" ixy="0" ixz="0.00000003" iyy="0.00001166" iyz="0.00000016" izz="0.00000374" />
    </inertial>
    <visual>
      <origin rpy="0 0 0" xyz="0 0 0" />
      <geometry>
        <mesh filename="../meshes/hands/visual/right/right_ring_MCP_Link.STL" />
      </geometry>
      <material name="">
        <color rgba="0.792156862745098 0.819607843137255 0.933333333333333 1" />
      </material>
    </visual>
    <collision>
      <origin rpy="0 0 0" xyz="0 0 0" />
      <geometry>
        <mesh filename="../meshes/hands/collision/right/right_ring_MCP_Link.STL" />
      </geometry>
    </collision>
  </link>
  <joint name="right_ring_MCP_joint" type="revolute">
    <origin rpy="0 0 0" xyz="0 -0.00032687 0.015997" />
    <parent link="right_ring_MPR_Link" />
    <child link="right_ring_MCP_Link" />
    <axis xyz="-0.019101 0.99961 0.020433" />
    <limit effort="0.35" lower="0" upper="1.4835" velocity="6.28" />
  </joint>
  <link name="right_ring_PIP_Link">
    <inertial>
      <origin rpy="0 0 0" xyz="0.000317847616005967 -0.000421387078381153 0.0182753825948413" />
      <mass value="0.0332" />
      <inertia ixx="0.00000252" ixy="0" ixz="-0.00000003" iyy="0.00000233" iyz="0" izz="0.00000183" />
    </inertial>
    <visual>
      <origin rpy="0 0 0" xyz="0 0 0" />
      <geometry>
        <mesh filename="../meshes/hands/visual/right/right_ring_PIP_Link.STL" />
      </geometry>
      <material name="">
        <color rgba="0.792156862745098 0.819607843137255 0.933333333333333 1" />
      </material>
    </visual>
    <collision>
      <origin rpy="0 0 0" xyz="0 0 0" />
      <geometry>
        <mesh filename="../meshes/hands/collision/right/right_ring_PIP_Link.STL" />
      </geometry>
    </collision>
  </link>
  <joint name="right_ring_PIP_joint" type="revolute">
    <origin rpy="0 0 0" xyz="0.0006499 -0.00094821 0.046994" />
    <parent link="right_ring_MCP_Link" />
    <child link="right_ring_PIP_Link" />
    <axis xyz="-0.019101 0.99961 0.020434" />
    <limit effort="0.35" lower="0" upper="1.4835" velocity="6.28" />
  </joint>
  <link name="right_ring_DIP_Link">
    <inertial>
      <origin rpy="0 0 0" xyz="-0.000468578428744866 -0.000349896977335539 0.0155798440443939" />
      <mass value="0.010" />
      <inertia ixx="0.00000064" ixy="0" ixz="0.00000003" iyy="0.00000057" iyz="0" izz="0.00000048" />
    </inertial>
    <visual>
      <origin rpy="0 0 0" xyz="0 0 0" />
      <geometry>
        <mesh filename="../meshes/hands/visual/right/right_ring_DIP_Link.STL" />
      </geometry>
      <material name="">
        <color rgba="0.898039215686275 0.917647058823529 0.929411764705882 1" />
      </material>
    </visual>
    <collision>
      <origin rpy="0 0 0" xyz="0 0 0" />
      <geometry>
        <mesh filename="../meshes/hands/collision/right/right_ring_DIP_Link.STL" />
      </geometry>
    </collision>
  </link>
  <joint name="right_ring_DIP_joint" type="revolute">
    <origin rpy="0 0 0" xyz="0.0012725 -0.00057823 0.02949" />
    <parent link="right_ring_PIP_Link" />
    <child link="right_ring_DIP_Link" />
    <axis xyz="-0.019101 0.99961 0.020424" />
    <limit effort="0.35" lower="0" upper="1.4835" velocity="6.28" />
  </joint>
  <link name="right_ring_tip_Link">
    <inertial>
      <origin rpy="0 0 0" xyz="0 0 0" />
      <mass value="0.001" />
      <inertia ixx="0.0000000001" ixy="0" ixz="0" iyy="0.0000000001" iyz="0" izz="0.000000001" />
    </inertial>
  </link>
  <joint name="right_ring_tip_joint" type="fixed">
    <origin rpy="0 0 0" xyz="0.0084 -0.000185 0.01" />
    <parent link="right_ring_DIP_Link" />
    <child link="right_ring_tip_Link" />
    <axis xyz="0 0 0" />
  </joint>
  <link name="right_little_MPR_Link">
    <inertial>
      <origin rpy="0 0 0" xyz="-0.00221173949200121 -0.000203240251325634 0.00544829709322221" />
      <mass value="0.013" />
      <inertia ixx="0.00000042" ixy="0" ixz="0" iyy="0.00000042" iyz="0" izz="0.00000042" />
    </inertial>
    <visual>
      <origin rpy="0 0 0" xyz="0 0 0" />
      <geometry>
        <mesh filename="../meshes/hands/visual/right/right_little_MPR_Link.STL" />
      </geometry>
      <material name="">
        <color rgba="0.792156862745098 0.819607843137255 0.933333333333333 1" />
      </material>
    </visual>
    <collision>
      <origin rpy="0 0 0" xyz="0 0 0" />
      <geometry>
        <mesh filename="../meshes/hands/collision/right/right_little_MPR_Link.STL" />
      </geometry>
    </collision>
  </link>
  <joint name="right_little_MPR_joint" type="revolute">
    <origin rpy="0 0 0" xyz="-0.0052697 -0.036412 0.090532" />
    <parent link="right_hand_base_link" />
    <child link="right_little_MPR_Link" />
    <axis xyz="0.99836 0.057297 0" />
    <limit effort="0.35" lower="-0.2618" upper="0.2618" velocity="6.28" />
  </joint>
  <link name="right_little_MCP_Link">
    <inertial>
      <origin rpy="0 0 0" xyz="2.58235094345444E-05 -0.00140652628093031 0.0229088448633661" />
      <mass value="0.0658" />
      <inertia ixx="0.00001192" ixy="0.00000001" ixz="0" iyy="0.00001164" iyz="0.00000049" izz="0.00000376" />
    </inertial>
    <visual>
      <origin rpy="0 0 0" xyz="0 0 0" />
      <geometry>
        <mesh filename="../meshes/hands/visual/right/right_little_MCP_Link.STL" />
      </geometry>
      <material name="">
        <color rgba="0.792156862745098 0.819607843137255 0.933333333333333 1" />
      </material>
    </visual>
    <collision>
      <origin rpy="0 0 0" xyz="0 0 0" />
      <geometry>
        <mesh filename="../meshes/hands/collision/right/right_little_MCP_Link.STL" />
      </geometry>
    </collision>
  </link>
  <joint name="right_little_MCP_joint" type="revolute">
    <origin rpy="0 0 0" xyz="5.6148E-05 -0.00097833 0.01597" />
    <parent link="right_little_MPR_Link" />
    <child link="right_little_MCP_Link" />
    <axis xyz="-0.05719 0.99648 0.061246" />
    <limit effort="0.35" lower="0" upper="1.4835" velocity="6.28" />
  </joint>
  <link name="right_little_PIP_Link">
    <inertial>
      <origin rpy="0 0 0" xyz="0.000376458559587514 -0.00115364512766754 0.0182426815291117" />
      <mass value="0.0332" />
      <inertia ixx="0.00000252" ixy="0.00000001" ixz="-0.00000003" iyy="0.00000233" iyz="0.00000003" izz="0.00000184" />
    </inertial>
    <visual>
      <origin rpy="0 0 0" xyz="0 0 0" />
      <geometry>
        <mesh filename="../meshes/hands/visual/right/right_little_PIP_Link.STL" />
      </geometry>
      <material name="">
        <color rgba="0.792156862745098 0.819607843137255 0.933333333333333 1" />
      </material>
    </visual>
    <collision>
      <origin rpy="0 0 0" xyz="0 0 0" />
      <geometry>
        <mesh filename="../meshes/hands/collision/right/right_little_PIP_Link.STL" />
      </geometry>
    </collision>
  </link>
  <joint name="right_little_PIP_joint" type="revolute">
    <origin rpy="0 0 0" xyz="0.00079558 -0.0028379 0.046916" />
    <parent link="right_little_MCP_Link" />
    <child link="right_little_PIP_Link" />
    <axis xyz="-0.05719 0.99648 0.061247" />
    <limit effort="0.35" lower="0" upper="1.4835" velocity="6.28" />
  </joint>
  <link name="right_little_DIP_Link">
    <inertial>
      <origin rpy="0 0 0" xyz="-0.000418722273889093 -0.00100158140010181 0.0155525044850821" />
      <mass value="0.010" />
      <inertia ixx="0.00000064" ixy="0" ixz="0.00000003" iyy="0.00000057" iyz="0" izz="0.00000048" />
    </inertial>
    <visual>
      <origin rpy="0 0 0" xyz="0 0 0" />
      <geometry>
        <mesh filename="../meshes/hands/visual/right/right_little_DIP_Link.STL" />
      </geometry>
      <material name="">
        <color rgba="0.898039215686275 0.917647058823529 0.929411764705882 1" />
      </material>
    </visual>
    <collision>
      <origin rpy="0 0 0" xyz="0 0 0" />
      <geometry>
        <mesh filename="../meshes/hands/collision/right/right_little_DIP_Link.STL" />
      </geometry>
    </collision>
  </link>
  <joint name="right_little_DIP_joint" type="revolute">
    <origin rpy="0 0 0" xyz="0.0013627 -0.0017313 0.029441" />
    <parent link="right_little_PIP_Link" />
    <child link="right_little_DIP_Link" />
    <axis xyz="-0.057189 0.99648 0.061237" />
    <limit effort="0.35" lower="0" upper="1.4835" velocity="6.28" />
  </joint>
  <link name="right_little_tip_Link">
    <inertial>
      <origin rpy="0 0 0" xyz="0 0 0" />
      <mass value="0.001" />
      <inertia ixx="0.0000000001" ixy="0" ixz="0" iyy="0.0000000001" iyz="0" izz="0.000000001" />
    </inertial>
  </link>
  <joint name="right_little_tip_joint" type="fixed">
    <origin rpy="0 0 0" xyz="0.0084 -0.0012185 0.01" />
    <parent link="right_little_DIP_Link" />
    <child link="right_little_tip_Link" />
    <axis xyz="0 0 0" />
  </joint>
</robot>