<?xml version='1.0' encoding='utf-8'?>
<mujoco model="revoarm_bimanual">
  <compiler angle="radian" autolimits="true" balanceinertia="true" />
  <option cone="elliptic" impratio="10" />
  <default>
    <default class="visual">
      <geom type="mesh" contype="0" conaffinity="0" group="2" />
    </default>
    <default class="collision">
      <geom type="mesh" group="3" />
    </default>
  </default>
  <asset>
    <mesh name="base_link_visual_0_base_link" file="../meshes/body/visual/bimanual/base_link.STL" />
    <mesh name="base_link_collision_0_base_link" file="../meshes/body/collision/bimanual/base_link.STL" />
    <mesh name="left_arm_link1_visual_0_left_arm_link1" file="../meshes/arm/visual/left_arm_link1.STL" />
    <mesh name="left_arm_link1_collision_0_left_arm_link1" file="../meshes/arm/collision/left_arm_link1.STL" />
    <mesh name="left_arm_link2_visual_0_left_arm_link2" file="../meshes/arm/visual/left_arm_link2.STL" />
    <mesh name="left_arm_link2_collision_0_left_arm_link2" file="../meshes/arm/collision/left_arm_link2.STL" />
    <mesh name="left_arm_link3_visual_0_left_arm_link3" file="../meshes/arm/visual/left_arm_link3.STL" />
    <mesh name="left_arm_link3_collision_0_left_arm_link3" file="../meshes/arm/collision/left_arm_link3.STL" />
    <mesh name="left_arm_link4_visual_0_left_arm_link4" file="../meshes/arm/visual/left_arm_link4.STL" />
    <mesh name="left_arm_link4_collision_0_left_arm_link4" file="../meshes/arm/collision/left_arm_link4.STL" />
    <mesh name="left_arm_link5_visual_0_left_arm_link5" file="../meshes/arm/visual/left_arm_link5.STL" />
    <mesh name="left_arm_link5_collision_0_left_arm_link5" file="../meshes/arm/collision/left_arm_link5.STL" />
    <mesh name="left_arm_link6_visual_0_left_arm_link6" file="../meshes/arm/visual/left_arm_link6.STL" />
    <mesh name="left_arm_link6_collision_0_left_arm_link6" file="../meshes/arm/collision/left_arm_link6.STL" />
    <mesh name="left_connector_link_visual_0_left_revo2_connector" file="../meshes/connector/visual/left_revo2_connector.STL" />
    <mesh name="left_connector_link_collision_0_left_revo2_connector" file="../meshes/connector/collision/left_revo2_connector.STL" />
    <mesh name="left_hand_base_link_visual_0_left_base_link" file="../meshes/hands/visual/left/left_base_link.STL" />
    <mesh name="left_hand_base_link_visual_1_left_base_visual_link" file="../meshes/hands/visual/left/left_base_visual_link.STL" />
    <mesh name="left_hand_base_link_collision_0_left_base_link" file="../meshes/hands/collision/left/left_base_link.STL" />
    <mesh name="left_thumb_metacarpal_link_visual_0_left_thumb_metacarpal_link" file="../meshes/hands/visual/left/left_thumb_metacarpal_link.STL" />
    <mesh name="left_thumb_metacarpal_link_collision_0_left_thumb_metacarpal_link" file="../meshes/hands/collision/left/left_thumb_metacarpal_link.STL" />
    <mesh name="left_thumb_proximal_link_visual_0_left_thumb_proximal_link" file="../meshes/hands/visual/left/left_thumb_proximal_link.STL" />
    <mesh name="left_thumb_proximal_link_visual_1_left_thumb_proximal_visual_link" file="../meshes/hands/visual/left/left_thumb_proximal_visual_link.STL" />
    <mesh name="left_thumb_proximal_link_collision_0_left_thumb_proximal_link" file="../meshes/hands/collision/left/left_thumb_proximal_link.STL" />
    <mesh name="left_thumb_distal_link_visual_0_left_thumb_distal_link" file="../meshes/hands/visual/left/left_thumb_distal_link.STL" />
    <mesh name="left_thumb_distal_link_collision_0_left_thumb_distal_link" file="../meshes/hands/collision/left/left_thumb_distal_link.STL" />
    <mesh name="left_thumb_touch_link_visual_0_left_thumb_touch_link" file="../meshes/hands/visual/left/left_thumb_touch_link.STL" />
    <mesh name="left_thumb_touch_link_collision_0_left_thumb_touch_link" file="../meshes/hands/collision/left/left_thumb_touch_link.STL" />
    <mesh name="left_index_proximal_link_visual_0_left_index_proximal_link" file="../meshes/hands/visual/left/left_index_proximal_link.STL" />
    <mesh name="left_index_proximal_link_collision_0_left_index_proximal_link" file="../meshes/hands/collision/left/left_index_proximal_link.STL" />
    <mesh name="left_index_distal_link_visual_0_left_index_distal_link" file="../meshes/hands/visual/left/left_index_distal_link.STL" />
    <mesh name="left_index_distal_link_collision_0_left_index_distal_link" file="../meshes/hands/collision/left/left_index_distal_link.STL" />
    <mesh name="left_index_touch_link_visual_0_left_index_touch_link" file="../meshes/hands/visual/left/left_index_touch_link.STL" />
    <mesh name="left_index_touch_link_collision_0_left_index_touch_link" file="../meshes/hands/collision/left/left_index_touch_link.STL" />
    <mesh name="left_middle_proximal_link_visual_0_left_middle_proximal_link" file="../meshes/hands/visual/left/left_middle_proximal_link.STL" />
    <mesh name="left_middle_proximal_link_collision_0_left_middle_proximal_link" file="../meshes/hands/collision/left/left_middle_proximal_link.STL" />
    <mesh name="left_middle_distal_link_visual_0_left_middle_distal_link" file="../meshes/hands/visual/left/left_middle_distal_link.STL" />
    <mesh name="left_middle_distal_link_collision_0_left_middle_distal_link" file="../meshes/hands/collision/left/left_middle_distal_link.STL" />
    <mesh name="left_middle_touch_link_visual_0_left_middle_touch_link" file="../meshes/hands/visual/left/left_middle_touch_link.STL" />
    <mesh name="left_middle_touch_link_collision_0_left_middle_touch_link" file="../meshes/hands/collision/left/left_middle_touch_link.STL" />
    <mesh name="left_ring_proximal_link_visual_0_left_ring_proximal_link" file="../meshes/hands/visual/left/left_ring_proximal_link.STL" />
    <mesh name="left_ring_proximal_link_collision_0_left_ring_proximal_link" file="../meshes/hands/collision/left/left_ring_proximal_link.STL" />
    <mesh name="left_ring_distal_link_visual_0_left_ring_distal_link" file="../meshes/hands/visual/left/left_ring_distal_link.STL" />
    <mesh name="left_ring_distal_link_collision_0_left_ring_distal_link" file="../meshes/hands/collision/left/left_ring_distal_link.STL" />
    <mesh name="left_ring_touch_link_visual_0_left_ring_touch_link" file="../meshes/hands/visual/left/left_ring_touch_link.STL" />
    <mesh name="left_ring_touch_link_collision_0_left_ring_touch_link" file="../meshes/hands/collision/left/left_ring_touch_link.STL" />
    <mesh name="left_pinky_proximal_link_visual_0_left_pinky_proximal_link" file="../meshes/hands/visual/left/left_pinky_proximal_link.STL" />
    <mesh name="left_pinky_proximal_link_collision_0_left_pinky_proximal_link" file="../meshes/hands/collision/left/left_pinky_proximal_link.STL" />
    <mesh name="left_pinky_distal_link_visual_0_left_pinky_distal_link" file="../meshes/hands/visual/left/left_pinky_distal_link.STL" />
    <mesh name="left_pinky_distal_link_collision_0_left_pinky_distal_link" file="../meshes/hands/collision/left/left_pinky_distal_link.STL" />
    <mesh name="left_pinky_touch_link_visual_0_left_pinky_touch_link" file="../meshes/hands/visual/left/left_pinky_touch_link.STL" />
    <mesh name="left_pinky_touch_link_collision_0_left_pinky_touch_link" file="../meshes/hands/collision/left/left_pinky_touch_link.STL" />
    <mesh name="right_arm_link1_visual_0_right_arm_link1" file="../meshes/arm/visual/right_arm_link1.STL" />
    <mesh name="right_arm_link1_collision_0_right_arm_link1" file="../meshes/arm/collision/right_arm_link1.STL" />
    <mesh name="right_arm_link2_visual_0_right_arm_link2" file="../meshes/arm/visual/right_arm_link2.STL" />
    <mesh name="right_arm_link2_collision_0_right_arm_link2" file="../meshes/arm/collision/right_arm_link2.STL" />
    <mesh name="right_arm_link3_visual_0_right_arm_link3" file="../meshes/arm/visual/right_arm_link3.STL" />
    <mesh name="right_arm_link3_collision_0_right_arm_link3" file="../meshes/arm/collision/right_arm_link3.STL" />
    <mesh name="right_arm_link4_visual_0_right_arm_link4" file="../meshes/arm/visual/right_arm_link4.STL" />
    <mesh name="right_arm_link4_collision_0_right_arm_link4" file="../meshes/arm/collision/right_arm_link4.STL" />
    <mesh name="right_arm_link5_visual_0_right_arm_link5" file="../meshes/arm/visual/right_arm_link5.STL" />
    <mesh name="right_arm_link5_collision_0_right_arm_link5" file="../meshes/arm/collision/right_arm_link5.STL" />
    <mesh name="right_arm_link6_visual_0_right_arm_link6" file="../meshes/arm/visual/right_arm_link6.STL" />
    <mesh name="right_arm_link6_collision_0_right_arm_link6" file="../meshes/arm/collision/right_arm_link6.STL" />
    <mesh name="right_connector_link_visual_0_right_revo2_connector" file="../meshes/connector/visual/right_revo2_connector.STL" />
    <mesh name="right_connector_link_collision_0_right_revo2_connector" file="../meshes/connector/collision/right_revo2_connector.STL" />
    <mesh name="right_hand_base_link_visual_0_right_base_link" file="../meshes/hands/visual/right/right_base_link.STL" />
    <mesh name="right_hand_base_link_visual_1_right_base_visual_link" file="../meshes/hands/visual/right/right_base_visual_link.STL" />
    <mesh name="right_hand_base_link_collision_0_right_base_link" file="../meshes/hands/collision/right/right_base_link.STL" />
    <mesh name="right_thumb_metacarpal_link_visual_0_right_thumb_metacarpal_link" file="../meshes/hands/visual/right/right_thumb_metacarpal_link.STL" />
    <mesh name="right_thumb_metacarpal_link_collision_0_right_thumb_metacarpal_link" file="../meshes/hands/collision/right/right_thumb_metacarpal_link.STL" />
    <mesh name="right_thumb_proximal_link_visual_0_right_thumb_proximal_visual_link" file="../meshes/hands/visual/right/right_thumb_proximal_visual_link.STL" />
    <mesh name="right_thumb_proximal_link_collision_0_right_thumb_proximal_link" file="../meshes/hands/collision/right/right_thumb_proximal_link.STL" />
    <mesh name="right_thumb_distal_link_visual_0_right_thumb_distal_link" file="../meshes/hands/visual/right/right_thumb_distal_link.STL" />
    <mesh name="right_thumb_distal_link_collision_0_right_thumb_distal_link" file="../meshes/hands/collision/right/right_thumb_distal_link.STL" />
    <mesh name="right_thumb_touch_link_visual_0_right_thumb_touch_link" file="../meshes/hands/visual/right/right_thumb_touch_link.STL" />
    <mesh name="right_thumb_touch_link_collision_0_right_thumb_touch_link" file="../meshes/hands/collision/right/right_thumb_touch_link.STL" />
    <mesh name="right_index_proximal_link_visual_0_right_index_proximal_link" file="../meshes/hands/visual/right/right_index_proximal_link.STL" />
    <mesh name="right_index_proximal_link_collision_0_right_index_proximal_link" file="../meshes/hands/collision/right/right_index_proximal_link.STL" />
    <mesh name="right_index_distal_link_visual_0_right_index_distal_link" file="../meshes/hands/visual/right/right_index_distal_link.STL" />
    <mesh name="right_index_distal_link_collision_0_right_index_distal_link" file="../meshes/hands/collision/right/right_index_distal_link.STL" />
    <mesh name="right_index_touch_link_visual_0_right_index_touch_link" file="../meshes/hands/visual/right/right_index_touch_link.STL" />
    <mesh name="right_index_touch_link_collision_0_right_index_touch_link" file="../meshes/hands/collision/right/right_index_touch_link.STL" />
    <mesh name="right_middle_proximal_link_visual_0_right_middle_proximal_link" file="../meshes/hands/visual/right/right_middle_proximal_link.STL" />
    <mesh name="right_middle_proximal_link_collision_0_right_middle_proximal_link" file="../meshes/hands/collision/right/right_middle_proximal_link.STL" />
    <mesh name="right_middle_distal_link_visual_0_right_middle_distal_link" file="../meshes/hands/visual/right/right_middle_distal_link.STL" />
    <mesh name="right_middle_distal_link_collision_0_right_middle_distal_link" file="../meshes/hands/collision/right/right_middle_distal_link.STL" />
    <mesh name="right_middle_touch_link_visual_0_right_middle_touch_link" file="../meshes/hands/visual/right/right_middle_touch_link.STL" />
    <mesh name="right_middle_touch_link_collision_0_right_middle_touch_link" file="../meshes/hands/collision/right/right_middle_touch_link.STL" />
    <mesh name="right_ring_proximal_link_visual_0_right_ring_proximal_link" file="../meshes/hands/visual/right/right_ring_proximal_link.STL" />
    <mesh name="right_ring_proximal_link_collision_0_right_ring_proximal_link" file="../meshes/hands/collision/right/right_ring_proximal_link.STL" />
    <mesh name="right_ring_distal_link_visual_0_right_ring_distal_link" file="../meshes/hands/visual/right/right_ring_distal_link.STL" />
    <mesh name="right_ring_distal_link_collision_0_right_ring_distal_link" file="../meshes/hands/collision/right/right_ring_distal_link.STL" />
    <mesh name="right_ring_touch_link_visual_0_right_ring_touch_link" file="../meshes/hands/visual/right/right_ring_touch_link.STL" />
    <mesh name="right_ring_touch_link_collision_0_right_ring_touch_link" file="../meshes/hands/collision/right/right_ring_touch_link.STL" />
    <mesh name="right_pinky_proximal_link_visual_0_right_pinky_proximal_link" file="../meshes/hands/visual/right/right_pinky_proximal_link.STL" />
    <mesh name="right_pinky_proximal_link_collision_0_right_pinky_proximal_link" file="../meshes/hands/collision/right/right_pinky_proximal_link.STL" />
    <mesh name="right_pinky_distal_link_visual_0_right_pinky_distal_link" file="../meshes/hands/visual/right/right_pinky_distal_link.STL" />
    <mesh name="right_pinky_distal_link_collision_0_right_pinky_distal_link" file="../meshes/hands/collision/right/right_pinky_distal_link.STL" />
    <mesh name="right_pinky_touch_link_visual_0_right_pinky_touch_link" file="../meshes/hands/visual/right/right_pinky_touch_link.STL" />
    <mesh name="right_pinky_touch_link_collision_0_right_pinky_touch_link" file="../meshes/hands/collision/right/right_pinky_touch_link.STL" />
  </asset>
  <worldbody>
    <body name="base_link">
      <inertial mass="20.9229828634" pos="0.00366369659918 -2.56673169996e-05 -0.6401483469" fullinertia="3.13550082094 3.13363525493 0.352520792674 -2.20161422074e-05 -0.0122674408678 8.21094464182e-05" />
      <geom name="base_link_visual_0" class="visual" mesh="base_link_visual_0_base_link" rgba="0.054902 0.054902 0.054902 1" />
      <geom name="base_link_collision_0" class="collision" mesh="base_link_collision_0_base_link" />
      <body name="left_base_link" pos="0.0055 0.10424 -0.038037" quat="0.996194825565 0.0871542857135 0 0">
        <body name="left_arm_link1">
          <inertial mass="0.99862" pos="0.00145589524176 0.0527165718617 -0.001274692537" fullinertia="0.0013455582137 0.000835877597536 0.00103394315647 -7.83153183344e-06 -1.15846408443e-06 -5.11169745924e-05" />
          <joint name="revoarm_left_joint1" type="hinge" axis="0 1 0" range="-4.1015 0.7854" actuatorfrcrange="-40 40" />
          <geom name="left_arm_link1_visual_0" class="visual" mesh="left_arm_link1_visual_0_left_arm_link1" rgba="1 1 1 1" />
          <geom name="left_arm_link1_collision_0" class="collision" mesh="left_arm_link1_collision_0_left_arm_link1" />
          <body name="left_arm_link2" pos="0 0.06 0" quat="0.996194825565 -0.0871542857135 0 0">
            <inertial mass="0.1942" pos="0.000352233546428 0.000380054519844 -0.0276718369676" fullinertia="0.000379846121944 0.000367869466548 0.000208453243267 -1.46309430499e-06 1.60311996102e-06 1.58239590757e-06" />
            <joint name="revoarm_left_joint2" type="hinge" axis="1 0 0" range="-0.1745 3.3161" actuatorfrcrange="-40 40" />
            <geom name="left_arm_link2_visual_0" class="visual" mesh="left_arm_link2_visual_0_left_arm_link2" rgba="1 1 1 1" />
            <geom name="left_arm_link2_collision_0" class="collision" mesh="left_arm_link2_collision_0_left_arm_link2" />
            <body name="left_arm_link3" pos="0 0 -0.099">
              <inertial mass="0.56897" pos="-0.000388567199254 -1.85684133796e-05 -0.0669511733196" fullinertia="0.00134702450955 0.00131837810042 0.0004885001058 3.82402964514e-07 -1.08091349719e-05 4.50889646437e-07" />
              <joint name="revoarm_left_joint3" type="hinge" axis="0 0 -1" range="-3.6652 0.5236" actuatorfrcrange="-27 27" />
              <geom name="left_arm_link3_visual_0" class="visual" mesh="left_arm_link3_visual_0_left_arm_link3" rgba="1 1 1 1" />
              <geom name="left_arm_link3_collision_0" class="collision" mesh="left_arm_link3_collision_0_left_arm_link3" />
              <body name="left_arm_link4" pos="0 0 -0.121">
                <inertial mass="0.43039" pos="-9.92890726825e-05 -0.000354021524004 -0.0253684032106" fullinertia="0.000471779353788 0.000474067782015 0.000276647751942 -1.24429020499e-07 -7.68857610764e-07 2.52611367384e-06" />
                <joint name="revoarm_left_joint4" type="hinge" axis="0 -1 0" range="-0.34907 2.2166" actuatorfrcrange="-27 27" />
                <geom name="left_arm_link4_visual_0" class="visual" mesh="left_arm_link4_visual_0_left_arm_link4" rgba="1 1 1 1" />
                <geom name="left_arm_link4_collision_0" class="collision" mesh="left_arm_link4_collision_0_left_arm_link4" />
                <body name="left_arm_link5" pos="0 0 -0.0635">
                  <inertial mass="0.80969" pos="0.000927310939411 -0.000140840890934 -0.0744269242701" fullinertia="0.00182621861674 0.00183389455605 0.000561624044255 1.42794413935e-08 2.78122930684e-05 -2.85482783549e-06" />
                  <joint name="revoarm_left_joint5" type="hinge" axis="0 0 -1" range="-3.1444 0.9044" actuatorfrcrange="-7 7" />
                  <geom name="left_arm_link5_visual_0" class="visual" mesh="left_arm_link5_visual_0_left_arm_link5" rgba="1 1 1 1" />
                  <geom name="left_arm_link5_collision_0" class="collision" mesh="left_arm_link5_collision_0_left_arm_link5" />
                  <body name="left_arm_link6" pos="0 0 -0.1525">
                    <inertial mass="0.31466" pos="0.000140526799188 -0.00104942724126 -2.24896287196e-05" fullinertia="0.000121008420212 0.000136729119341 0.000137816234187 -2.1489023912e-07 -6.95891723799e-08 -2.01066845192e-07" />
                    <joint name="revoarm_left_joint6" type="hinge" axis="-1 0 0" range="-0.64577 0.64577" actuatorfrcrange="-7 7" />
                    <geom name="left_arm_link6_visual_0" class="visual" mesh="left_arm_link6_visual_0_left_arm_link6" rgba="1 1 1 1" />
                    <geom name="left_arm_link6_collision_0" class="collision" mesh="left_arm_link6_collision_0_left_arm_link6" />
                    <body name="left_arm_link7" quat="0.999999529356 -0.000970199847794 0 0">
                      <joint name="revoarm_left_joint7" type="hinge" axis="0 -1 0" range="-1.5708 1.5708" actuatorfrcrange="-7 7" />
                      <body name="left_connector_link" quat="0.707388269167 0 0 0.706825181105">
                        <inertial mass="0.49311" pos="0.00511874536262 0.000636706036585 -0.0267401982631" fullinertia="0.0002244237841 0.000296044038314 0.000202925080009 4.1874361257e-06 6.48877769806e-06 1.52799922856e-05" />
                        <geom name="left_connector_link_visual_0" class="visual" mesh="left_connector_link_visual_0_left_revo2_connector" rgba="1.0 1.0 1.0 1.0" />
                        <geom name="left_connector_link_collision_0" class="collision" mesh="left_connector_link_collision_0_left_revo2_connector" />
                        <body name="left_connector_tip" pos="7.6e-05 0.0001518 -0.0583" quat="0.000563312173597 0.706824956994 0.707388044877 -0.000562863771533">
                          <body name="left_hand_base_link" pos="0 0 -0.0118">
                            <inertial mass="0.238" pos="-0.00500691965579 0.0031951498726 0.0440489850175" fullinertia="0.000212437031916 0.000160143089365 7.74200628653e-05 -2.16057899886e-06 3.61688109177e-06 1.22416860676e-05" />
                            <geom name="left_hand_base_link_visual_0" class="visual" mesh="left_hand_base_link_visual_0_left_base_link" rgba="1 1 1 1" />
                            <geom name="left_hand_base_link_visual_1" class="visual" mesh="left_hand_base_link_visual_1_left_base_visual_link" rgba="1 1 1 1" />
                            <geom name="left_hand_base_link_collision_0" class="collision" mesh="left_hand_base_link_collision_0_left_base_link" />
                            <body name="left_thumb_metacarpal_link" pos="0.0045 -0.019 0.027825" quat="0.996479525452 0 0 0.0838364798531">
                              <inertial mass="0.01" pos="5.2448120648e-05 -0.00641271135649 -0.00389992855484" fullinertia="1.03913740234e-06 9.9133648861e-07 3.22871629916e-07 2.68781051739e-08 3.19947398407e-09 8.07153885639e-08" />
                              <joint name="left_thumb_metacarpal_joint" type="hinge" axis="0 0 1" range="0 1.57" actuatorfrcrange="-0.5 0.5" />
                              <geom name="left_thumb_metacarpal_link_visual_0" class="visual" mesh="left_thumb_metacarpal_link_visual_0_left_thumb_metacarpal_link" rgba="1 1 1 1" />
                              <geom name="left_thumb_metacarpal_link_collision_0" class="collision" mesh="left_thumb_metacarpal_link_collision_0_left_thumb_metacarpal_link" />
                              <body name="left_thumb_proximal_link" pos="0 -0.014227 0" quat="0.98655672389 -0.0765206052367 0.124803836493 -0.0726252705212">
                                <inertial mass="0.05" pos="-5.35927466719e-07 -0.0279102099635 -0.00216906042285" fullinertia="1.1041485159e-05 1.77876771791e-06 1.15656142909e-05 0 0 -2.757462963e-08" />
                                <joint name="left_thumb_proximal_joint" type="hinge" axis="-1 0 0" range="0 1.03" actuatorfrcrange="-1.1 1.1" />
                                <geom name="left_thumb_proximal_link_visual_0" class="visual" mesh="left_thumb_proximal_link_visual_0_left_thumb_proximal_link" rgba="1 1 1 1" />
                                <geom name="left_thumb_proximal_link_visual_1" class="visual" mesh="left_thumb_proximal_link_visual_1_left_thumb_proximal_visual_link" rgba="1 1 1 1" />
                                <geom name="left_thumb_proximal_link_collision_0" class="collision" mesh="left_thumb_proximal_link_collision_0_left_thumb_proximal_link" />
                                <body name="left_thumb_distal_link" pos="0 -0.052 0">
                                  <inertial mass="0.01" pos="-9.32503534217e-07 -0.00922169581661 -0.00224644147123" fullinertia="4.53439708081e-07 2.61012162244e-07 5.20100760795e-07 0 0 -1.20090505524e-08" />
                                  <joint name="left_thumb_distal_joint" type="hinge" axis="-1 0 0" range="0 1.03" actuatorfrcrange="-1.1 1.1" />
                                  <geom name="left_thumb_distal_link_visual_0" class="visual" mesh="left_thumb_distal_link_visual_0_left_thumb_distal_link" rgba="1 1 1 1" />
                                  <geom name="left_thumb_distal_link_collision_0" class="collision" mesh="left_thumb_distal_link_collision_0_left_thumb_distal_link" />
                                  <body name="left_thumb_tip_link" pos="0 -0.026529 -0.0017734" quat="0.999443106384 0.0333688043285 0 0" />
                                  <body name="left_thumb_touch_link" pos="0 -0.013836 0.0076686" quat="0.99617955831 0.0873286184725 0 0">
                                    <inertial mass="0.002" pos="-5.51056035954e-07 -0.00156797699696 -0.00568881139184" fullinertia="6.93376086963e-08 5.68387894951e-08 1.0288222773e-07 0 0 -3.51487553806e-09" />
                                    <geom name="left_thumb_touch_link_visual_0" class="visual" mesh="left_thumb_touch_link_visual_0_left_thumb_touch_link" rgba="1 1 1 1" />
                                    <geom name="left_thumb_touch_link_collision_0" class="collision" mesh="left_thumb_touch_link_collision_0_left_thumb_touch_link" />
                                  </body>
                                </body>
                              </body>
                            </body>
                            <body name="left_index_proximal_link" pos="-0.0021349 -0.029578 0.080876" quat="0.992147063362 0.0522806833485 0.0783652462556 0.0822789340577">
                              <inertial mass="0.009" pos="-0.00210957621851 -1.00184890571e-06 0.0174338919863" fullinertia="8.07254070145e-07 7.65178025412e-07 2.71309060262e-07 0 -1.84898575136e-08 0" />
                              <joint name="left_index_proximal_joint" type="hinge" axis="0 1 0" range="0 1.41" actuatorfrcrange="-2 2" />
                              <geom name="left_index_proximal_link_visual_0" class="visual" mesh="left_index_proximal_link_visual_0_left_index_proximal_link" rgba="1 1 1 1" />
                              <geom name="left_index_proximal_link_collision_0" class="collision" mesh="left_index_proximal_link_collision_0_left_index_proximal_link" />
                              <body name="left_index_distal_link" pos="0 0 0.032">
                                <inertial mass="0.009" pos="0.00349738616737 -8.69130119173e-08 0.0140243674792" fullinertia="9.5733823828e-07 1.05380093543e-06 2.42081096246e-07 0 -2.92408229641e-07 0" />
                                <joint name="left_index_distal_joint" type="hinge" axis="0 1 0" range="0 1.63" actuatorfrcrange="-2 2" />
                                <geom name="left_index_distal_link_visual_0" class="visual" mesh="left_index_distal_link_visual_0_left_index_distal_link" rgba="1 1 1 1" />
                                <geom name="left_index_distal_link_collision_0" class="collision" mesh="left_index_distal_link_collision_0_left_index_distal_link" />
                                <body name="left_index_tip_link" pos="0.011097 0 0.035739" quat="0.970472334904 0 0.241212452384 0" />
                                <body name="left_index_touch_link" pos="0.014497 0 0.023303" quat="0.971858569571 0 0.235565109366 0">
                                  <inertial mass="0.002" pos="-0.00307564250701 -3.90468862638e-08 0.00262490487386" fullinertia="3.65246739614e-08 2.97968129701e-08 1.72154502539e-08 0 8.6063395532e-09 0" />
                                  <geom name="left_index_touch_link_visual_0" class="visual" mesh="left_index_touch_link_visual_0_left_index_touch_link" rgba="1 1 1 1" />
                                  <geom name="left_index_touch_link_collision_0" class="collision" mesh="left_index_touch_link_collision_0_left_index_touch_link" />
                                </body>
                              </body>
                            </body>
                            <body name="left_middle_proximal_link" pos="-0.0045935 -0.010061 0.084993" quat="0.996681471076 0.0175234943017 0.0746068794758 0.0274369440089">
                              <inertial mass="0.009" pos="-0.00214633373508 -1.46252110598e-06 0.020086308617" fullinertia="9.94838537376e-07 9.63052856063e-07 2.75118209384e-07 0 -2.47718729488e-08 0" />
                              <joint name="left_middle_proximal_joint" type="hinge" axis="0 1 0" range="0 1.41" actuatorfrcrange="-2 2" />
                              <geom name="left_middle_proximal_link_visual_0" class="visual" mesh="left_middle_proximal_link_visual_0_left_middle_proximal_link" rgba="1 1 1 1" />
                              <geom name="left_middle_proximal_link_collision_0" class="collision" mesh="left_middle_proximal_link_collision_0_left_middle_proximal_link" />
                              <body name="left_middle_distal_link" pos="0 0 0.037" quat="0.997999121159 0 0.0632277958336 0">
                                <inertial mass="0.009" pos="0.00209085298018 -4.57368908145e-07 0.0167165010662" fullinertia="1.25691033279e-06 1.30283303637e-06 1.9763470195e-07 0 -2.40147320686e-07 0" />
                                <joint name="left_middle_distal_joint" type="hinge" axis="0 1 0" range="0 1.63" actuatorfrcrange="-2 2" />
                                <geom name="left_middle_distal_link_visual_0" class="visual" mesh="left_middle_distal_link_visual_0_left_middle_distal_link" rgba="1 1 1 1" />
                                <geom name="left_middle_distal_link_collision_0" class="collision" mesh="left_middle_distal_link_collision_0_left_middle_distal_link" />
                                <body name="left_middle_tip_link" pos="0.0073534 0 0.041703" quat="0.984807392725 0 0.173650220946 0" />
                                <body name="left_middle_touch_link" pos="0.012493 0 0.028393" quat="0.984807392725 0 0.173650220946 0">
                                  <inertial mass="0.002" pos="-0.00322648744496 -1.64648064414e-08 0.00301991568908" fullinertia="4.37515621057e-08 3.61552579505e-08 1.92036823615e-08 0 1.0061853575e-08 0" />
                                  <geom name="left_middle_touch_link_visual_0" class="visual" mesh="left_middle_touch_link_visual_0_left_middle_touch_link" rgba="1 1 1 1" />
                                  <geom name="left_middle_touch_link_collision_0" class="collision" mesh="left_middle_touch_link_collision_0_left_middle_touch_link" />
                                </body>
                              </body>
                            </body>
                            <body name="left_ring_proximal_link" pos="-0.0046877 0.010026 0.083982" quat="0.996722004661 -0.0175386397699 0.0740632637929 -0.0274276228537">
                              <inertial mass="0.009" pos="-0.00224116301626 -8.49238468847e-07 0.0189745760632" fullinertia="9.2196083086e-07 8.79785181001e-07 2.69812387003e-07 0 -2.14021777573e-08 0" />
                              <joint name="left_ring_proximal_joint" type="hinge" axis="0 1 0" range="0 1.41" actuatorfrcrange="-2 2" />
                              <geom name="left_ring_proximal_link_visual_0" class="visual" mesh="left_ring_proximal_link_visual_0_left_ring_proximal_link" rgba="1 1 1 1" />
                              <geom name="left_ring_proximal_link_collision_0" class="collision" mesh="left_ring_proximal_link_collision_0_left_ring_proximal_link" />
                              <body name="left_ring_distal_link" pos="0 0 0.035" quat="0.997999121159 0 0.0632277958336 0">
                                <inertial mass="0.009" pos="0.00196915381245 -3.47120548271e-07 0.0162290973386" fullinertia="1.203200524e-06 1.24611089658e-06 1.92618107324e-07 0 -2.32593398457e-07 0" />
                                <joint name="left_ring_distal_joint" type="hinge" axis="0 1 0" range="0 1.63" actuatorfrcrange="-2 2" />
                                <geom name="left_ring_distal_link_visual_0" class="visual" mesh="left_ring_distal_link_visual_0_left_ring_distal_link" rgba="1 1 1 1" />
                                <geom name="left_ring_distal_link_collision_0" class="collision" mesh="left_ring_distal_link_collision_0_left_ring_distal_link" />
                                <body name="left_ring_tip_link" pos="0.0071824 0 0.040734" quat="0.984807392725 0 0.173650220946 0" />
                                <body name="left_ring_touch_link" pos="0.012028 0 0.027796" quat="0.984807392725 0 0.173650220946 0">
                                  <inertial mass="0.002" pos="-0.00305368567589 -2.24213764482e-08 0.00307741561621" fullinertia="4.07923039701e-08 3.32849436555e-08 1.79900910115e-08 0 9.30939975317e-09 0" />
                                  <geom name="left_ring_touch_link_visual_0" class="visual" mesh="left_ring_touch_link_visual_0_left_ring_touch_link" rgba="1 1 1 1" />
                                  <geom name="left_ring_touch_link_collision_0" class="collision" mesh="left_ring_touch_link_collision_0_left_ring_touch_link" />
                                </body>
                              </body>
                            </body>
                            <body name="left_pinky_proximal_link" pos="-0.0023733 0.029356 0.078694" quat="0.992245493622 -0.0523869549011 0.0771065283009 -0.0822135672249">
                              <inertial mass="0.009" pos="-0.00197514631949 6.49810266121e-08 0.0158243278425" fullinertia="7.07798847841e-07 6.61168596118e-07 2.70150416524e-07 0 -1.37223239339e-08 0" />
                              <joint name="left_pinky_proximal_joint" type="hinge" axis="0 1 0" range="0 1.41" actuatorfrcrange="-2 2" />
                              <geom name="left_pinky_proximal_link_visual_0" class="visual" mesh="left_pinky_proximal_link_visual_0_left_pinky_proximal_link" rgba="1 1 1 1" />
                              <geom name="left_pinky_proximal_link_collision_0" class="collision" mesh="left_pinky_proximal_link_collision_0_left_pinky_proximal_link" />
                              <body name="left_pinky_distal_link" pos="0 0 0.029">
                                <inertial mass="0.009" pos="0.00325666639671 6.03499349921e-08 0.0128484466297" fullinertia="8.43983683998e-07 9.27709644906e-07 2.29733240876e-07 0 -2.57035793141e-07 0" />
                                <joint name="left_pinky_distal_joint" type="hinge" axis="0 1 0" range="0 1.63" actuatorfrcrange="-2 2" />
                                <geom name="left_pinky_distal_link_visual_0" class="visual" mesh="left_pinky_distal_link_visual_0_left_pinky_distal_link" rgba="1 1 1 1" />
                                <geom name="left_pinky_distal_link_collision_0" class="collision" mesh="left_pinky_distal_link_collision_0_left_pinky_distal_link" />
                                <body name="left_pinky_tip_link" pos="0.010221 0 0.032918" quat="0.971858569571 0 0.235565109366 0" />
                                <body name="left_pinky_touch_link" pos="0.01401 0 0.021124" quat="0.971858569571 0 0.235565109366 0">
                                  <inertial mass="0.002" pos="-0.00289600605065 1.35020565526e-08 0.00165313291493" fullinertia="3.69716837877e-08 2.85901107149e-08 1.75392445713e-08 0 7.65650300513e-09 0" />
                                  <geom name="left_pinky_touch_link_visual_0" class="visual" mesh="left_pinky_touch_link_visual_0_left_pinky_touch_link" rgba="1 1 1 1" />
                                  <geom name="left_pinky_touch_link_collision_0" class="collision" mesh="left_pinky_touch_link_collision_0_left_pinky_touch_link" />
                                </body>
                              </body>
                            </body>
                          </body>
                        </body>
                      </body>
                    </body>
                  </body>
                </body>
              </body>
            </body>
          </body>
        </body>
      </body>
      <body name="right_base_link" pos="0.0055 -0.10424 -0.038037" quat="0.996194825565 -0.0871542857135 0 0">
        <body name="right_arm_link1">
          <inertial mass="0.99862" pos="0.00138261246537 -0.0527123429468 -0.00121652148011" fullinertia="0.00134544913222 0.000834135586928 0.00103343870055 9.35736730946e-06 3.47820470915e-07 4.90367363186e-05" />
          <joint name="revoarm_right_joint1" type="hinge" axis="0 1 0" range="-4.1015 0.7854" actuatorfrcrange="-40 40" />
          <geom name="right_arm_link1_visual_0" class="visual" mesh="right_arm_link1_visual_0_right_arm_link1" rgba="1 1 1 1" />
          <geom name="right_arm_link1_collision_0" class="collision" mesh="right_arm_link1_collision_0_right_arm_link1" />
          <body name="right_arm_link2" pos="0 -0.06 0" quat="0.996194825565 0.0871542857135 0 0">
            <inertial mass="0.1942" pos="5.45283276618e-06 -0.000282431180944 -0.0268913421348" fullinertia="0.000382625514425 0.000369233743661 0.000207280501913 9.48679552051e-07 -2.1848535528e-06 2.31382379314e-06" />
            <joint name="revoarm_right_joint2" type="hinge" axis="-1 0 0" range="-0.1745 3.3161" actuatorfrcrange="-40 40" />
            <geom name="right_arm_link2_visual_0" class="visual" mesh="right_arm_link2_visual_0_right_arm_link2" rgba="1 1 1 1" />
            <geom name="right_arm_link2_collision_0" class="collision" mesh="right_arm_link2_collision_0_right_arm_link2" />
            <body name="right_arm_link3" pos="0 0 -0.099">
              <inertial mass="0.56897" pos="-0.000454569614792 3.12449787288e-05 -0.0666939671661" fullinertia="0.00134243655403 0.00131310898292 0.000492154320293 -1.10159695691e-06 -8.9867271334e-06 1.87663764445e-06" />
              <joint name="revoarm_right_joint3" type="hinge" axis="0 0 1" range="-3.6652 0.5236" actuatorfrcrange="-27 27" />
              <geom name="right_arm_link3_visual_0" class="visual" mesh="right_arm_link3_visual_0_right_arm_link3" rgba="1 1 1 1" />
              <geom name="right_arm_link3_collision_0" class="collision" mesh="right_arm_link3_collision_0_right_arm_link3" />
              <body name="right_arm_link4" pos="0 0 -0.121">
                <inertial mass="0.43039" pos="-7.58557077911e-06 0.000351070451149 -0.0253844870788" fullinertia="0.00047306084261 0.00047377939084 0.000275999880013 1.33236901297e-07 -1.09059920161e-06 -2.6711329621e-06" />
                <joint name="revoarm_right_joint4" type="hinge" axis="0 -1 0" range="-0.34907 2.2166" actuatorfrcrange="-27 27" />
                <geom name="right_arm_link4_visual_0" class="visual" mesh="right_arm_link4_visual_0_right_arm_link4" rgba="1 1 1 1" />
                <geom name="right_arm_link4_collision_0" class="collision" mesh="right_arm_link4_collision_0_right_arm_link4" />
                <body name="right_arm_link5" pos="0 0 -0.0635">
                  <inertial mass="0.80969" pos="0.000915076828994 1.83496866724e-05 -0.0751470282845" fullinertia="0.00182931151009 0.00183450989562 0.00056086991064 9.37494132217e-07 3.67371332139e-05 -1.6270176108e-06" />
                  <joint name="revoarm_right_joint5" type="hinge" axis="0 0 1" range="-3.1444 0.9044" actuatorfrcrange="-7 7" />
                  <geom name="right_arm_link5_visual_0" class="visual" mesh="right_arm_link5_visual_0_right_arm_link5" rgba="1 1 1 1" />
                  <geom name="right_arm_link5_collision_0" class="collision" mesh="right_arm_link5_collision_0_right_arm_link5" />
                  <body name="right_arm_link6" pos="0 0 -0.1525">
                    <inertial mass="0.31466" pos="0.000179459444033 0.00100056983205 -2.47524159457e-05" fullinertia="0.000120895453787 0.000136714381567 0.000137495744014 2.38559203994e-07 -7.17472862339e-08 2.58366532259e-07" />
                    <joint name="revoarm_right_joint6" type="hinge" axis="1 0 0" range="-0.64577 0.64577" actuatorfrcrange="-7 7" />
                    <geom name="right_arm_link6_visual_0" class="visual" mesh="right_arm_link6_visual_0_right_arm_link6" rgba="1 1 1 1" />
                    <geom name="right_arm_link6_collision_0" class="collision" mesh="right_arm_link6_collision_0_right_arm_link6" />
                    <body name="right_arm_link7" quat="0.999999529356 0.000970199847794 0 0">
                      <joint name="revoarm_right_joint7" type="hinge" axis="0 -1 0" range="-1.5708 1.5708" actuatorfrcrange="-7 7" />
                      <body name="right_connector_link" quat="0.707388269167 0 0 -0.706825181105">
                        <inertial mass="0.49311" pos="0.00630257811604 -0.00345240316034 -0.0228922389732" fullinertia="0.000258191430957 0.000307759197121 0.000162681515831 -2.80239939166e-05 -1.00555941171e-05 -1.27801645289e-05" />
                        <geom name="right_connector_link_visual_0" class="visual" mesh="right_connector_link_visual_0_right_revo2_connector" rgba="1.0 1.0 1.0 1.0" />
                        <geom name="right_connector_link_collision_0" class="collision" mesh="right_connector_link_collision_0_right_revo2_connector" />
                        <body name="right_connector_tip" pos="7.6e-05 -0.0001518 -0.0583" quat="0.000563312173597 -0.706824956994 0.707388044877 0.000562863771533">
                          <body name="right_hand_base_link" pos="0 0 -0.0118">
                            <inertial mass="0.238" pos="-0.00499090399733 -0.0032037440312 0.0440507784562" fullinertia="0.000212430690833 0.000160132967062 7.74219628519e-05 2.16367569398e-06 3.61502824762e-06 -1.22355213676e-05" />
                            <geom name="right_hand_base_link_visual_0" class="visual" mesh="right_hand_base_link_visual_0_right_base_link" rgba="1 1 1 1" />
                            <geom name="right_hand_base_link_visual_1" class="visual" mesh="right_hand_base_link_visual_1_right_base_visual_link" rgba="1 1 1 1" />
                            <geom name="right_hand_base_link_collision_0" class="collision" mesh="right_hand_base_link_collision_0_right_base_link" />
                            <body name="right_thumb_metacarpal_link" pos="0.005619 0.019867 0.027825" quat="0.996479525452 0 0 -0.0838364798531">
                              <inertial mass="0.01" pos="5.24580204563e-05 0.00641288231813 -0.0038998195538" fullinertia="1.03912259807e-06 9.91339727453e-07 3.22854838473e-07 -2.68660869899e-08 3.1967028003e-09 -8.06829991718e-08" />
                              <joint name="right_thumb_metacarpal_joint" type="hinge" axis="0 0 -1" range="0 1.57" actuatorfrcrange="-0.5 0.5" />
                              <geom name="right_thumb_metacarpal_link_visual_0" class="visual" mesh="right_thumb_metacarpal_link_visual_0_right_thumb_metacarpal_link" rgba="1 1 1 1" />
                              <geom name="right_thumb_metacarpal_link_collision_0" class="collision" mesh="right_thumb_metacarpal_link_collision_0_right_thumb_metacarpal_link" />
                              <body name="right_thumb_proximal_link" pos="0 0.014227 0" quat="0.98655672389 0.0765206052367 0.124803836493 0.0726252705212">
                                <inertial mass="0.05" pos="-8.89762214511e-07 0.0279092873947 -0.00216940109303" fullinertia="1.10412368074e-05 1.77881179518e-06 1.15652864677e-05 0 0 2.75542392609e-08" />
                                <joint name="right_thumb_proximal_joint" type="hinge" axis="1 0 0" range="0 1.03" actuatorfrcrange="-1.1 1.1" />
                                <geom name="right_thumb_proximal_link_visual_0" class="visual" mesh="right_thumb_proximal_link_visual_0_right_thumb_proximal_visual_link" rgba="1 1 1 1" />
                                <geom name="right_thumb_proximal_link_collision_0" class="collision" mesh="right_thumb_proximal_link_collision_0_right_thumb_proximal_link" />
                                <body name="right_thumb_distal_link" pos="0 0.052 0">
                                  <inertial mass="0.01" pos="1.49655290334e-05 0.00922852132423 -0.00225603078695" fullinertia="4.53319679276e-07 2.60156541182e-07 5.19783541213e-07 0 0 1.1609788285e-08" />
                                  <joint name="right_thumb_distal_joint" type="hinge" axis="1 0 0" range="0 1.03" actuatorfrcrange="-1.1 1.1" />
                                  <geom name="right_thumb_distal_link_visual_0" class="visual" mesh="right_thumb_distal_link_visual_0_right_thumb_distal_link" rgba="1 1 1 1" />
                                  <geom name="right_thumb_distal_link_collision_0" class="collision" mesh="right_thumb_distal_link_collision_0_right_thumb_distal_link" />
                                  <body name="right_thumb_tip_link" pos="0 0.0265287811636 -0.00177344281308" quat="0.999443098864 -0.0333690295624 0 0" />
                                  <body name="right_thumb_touch_link" pos="0 0.0137927522749 0.00767659940412" quat="0.999443098864 -0.0333690295624 0 0">
                                    <inertial mass="0.002" pos="5.68135746383e-08 0.00098883010262 -0.0058303970076" fullinertia="6.93283042171e-08 5.81285535805e-08 1.0158078426e-07 0 0 8.37483596547e-09" />
                                    <geom name="right_thumb_touch_link_visual_0" class="visual" mesh="right_thumb_touch_link_visual_0_right_thumb_touch_link" rgba="1 1 1 1" />
                                    <geom name="right_thumb_touch_link_collision_0" class="collision" mesh="right_thumb_touch_link_collision_0_right_thumb_touch_link" />
                                  </body>
                                </body>
                              </body>
                            </body>
                            <body name="right_index_proximal_link" pos="-0.0021181 0.029568 0.080876" quat="0.992147063362 -0.0522806833485 0.0783652462556 -0.0822789340577">
                              <inertial mass="0.009" pos="-0.0021097272761 7.63064164078e-07 0.0174334820659" fullinertia="8.07303137168e-07 7.65224563984e-07 2.71306397962e-07 0 -1.8482997741e-08 0" />
                              <joint name="right_index_proximal_joint" type="hinge" axis="0 1 0" range="0 1.41" actuatorfrcrange="-2 2" />
                              <geom name="right_index_proximal_link_visual_0" class="visual" mesh="right_index_proximal_link_visual_0_right_index_proximal_link" rgba="1 1 1 1" />
                              <geom name="right_index_proximal_link_collision_0" class="collision" mesh="right_index_proximal_link_collision_0_right_index_proximal_link" />
                              <body name="right_index_distal_link" pos="0 0 0.032">
                                <inertial mass="0.009" pos="0.00349732370262 -2.43970736749e-08 0.0140241097206" fullinertia="9.57356237219e-07 1.05382469611e-06 2.4207960788e-07 0 -2.92415838167e-07 0" />
                                <joint name="right_index_distal_joint" type="hinge" axis="0 1 0" range="0 1.63" actuatorfrcrange="-2 2" />
                                <geom name="right_index_distal_link_visual_0" class="visual" mesh="right_index_distal_link_visual_0_right_index_distal_link" rgba="1 1 1 1" />
                                <geom name="right_index_distal_link_collision_0" class="collision" mesh="right_index_distal_link_collision_0_right_index_distal_link" />
                                <body name="right_index_tip_link" pos="0.011097 0 0.035739" quat="0.971858569571 0 0.235565109366 0" />
                                <body name="right_index_touch_link" pos="0.014497 0 0.023303" quat="0.63609996281 0.734769294787 0.15418185526 -0.178097940076">
                                  <inertial mass="0.002" pos="-0.00307564251221 0.00259784853355 -0.000375910280319" fullinertia="3.65246739943e-08 1.74738279331e-08 2.95384354001e-08 8.51755341147e-09 0 0" />
                                  <geom name="right_index_touch_link_visual_0" class="visual" mesh="right_index_touch_link_visual_0_right_index_touch_link" rgba="1 1 1 1" />
                                  <geom name="right_index_touch_link_collision_0" class="collision" mesh="right_index_touch_link_collision_0_right_index_touch_link" />
                                </body>
                              </body>
                            </body>
                            <body name="right_middle_proximal_link" pos="-0.0045767 0.010051 0.084993" quat="0.996681471076 -0.0175234943017 0.0746068794758 -0.0274369440089">
                              <inertial mass="0.009" pos="-0.00214650088166 7.01989779722e-07 0.020085720079" fullinertia="9.9491303633e-07 9.6311492132e-07 2.75113780461e-07 0 -2.47547915686e-08 0" />
                              <joint name="right_middle_proximal_joint" type="hinge" axis="0 1 0" range="0 1.41" actuatorfrcrange="-2 2" />
                              <geom name="right_middle_proximal_link_visual_0" class="visual" mesh="right_middle_proximal_link_visual_0_right_middle_proximal_link" rgba="1 1 1 1" />
                              <geom name="right_middle_proximal_link_collision_0" class="collision" mesh="right_middle_proximal_link_collision_0_right_middle_proximal_link" />
                              <body name="right_middle_distal_link" pos="0 0 0.037">
                                <inertial mass="0.009" pos="0.00418379295608 -2.44344999297e-07 0.0163193896289" fullinertia="1.17987538379e-06 1.30276578051e-06 2.7460891941e-07 0 -3.65063113523e-07 0" />
                                <joint name="right_middle_distal_joint" type="hinge" axis="0 1 0" range="0 1.63" actuatorfrcrange="-2 2" />
                                <geom name="right_middle_distal_link_visual_0" class="visual" mesh="right_middle_distal_link_visual_0_right_middle_distal_link" rgba="1 1 1 1" />
                                <geom name="right_middle_distal_link_collision_0" class="collision" mesh="right_middle_distal_link_collision_0_right_middle_distal_link" />
                                <body name="right_middle_tip_link" pos="0.012558 0 0.040442" quat="0.971858569571 0 0.235565109366 0" />
                                <body name="right_middle_touch_link" pos="0.0159758719979 0 0.0265894268904" quat="0.971858307956 0 0.235566188697 0">
                                  <inertial mass="0.002" pos="-0.00322648744586 -1.64628381334e-08 0.00301991569053" fullinertia="4.37515621458e-08 3.61552579791e-08 1.92036823826e-08 0 1.00618535859e-08 0" />
                                  <geom name="right_middle_touch_link_visual_0" class="visual" mesh="right_middle_touch_link_visual_0_right_middle_touch_link" rgba="1 1 1 1" />
                                  <geom name="right_middle_touch_link_collision_0" class="collision" mesh="right_middle_touch_link_collision_0_right_middle_touch_link" />
                                </body>
                              </body>
                            </body>
                            <body name="right_ring_proximal_link" pos="-0.0046709 -0.010037 0.083982" quat="0.996722004661 0.0175386397699 0.0740632637929 0.0274276228537">
                              <inertial mass="0.009" pos="-0.00224004194513 -3.16420215091e-07 0.0189747684926" fullinertia="9.2192274611e-07 8.79780628424e-07 2.69827216148e-07 0 -2.1434689277e-08 0" />
                              <joint name="right_ring_proximal_joint" type="hinge" axis="0 1 0" range="0 1.41" actuatorfrcrange="-2 2" />
                              <geom name="right_ring_proximal_link_visual_0" class="visual" mesh="right_ring_proximal_link_visual_0_right_ring_proximal_link" rgba="1 1 1 1" />
                              <geom name="right_ring_proximal_link_collision_0" class="collision" mesh="right_ring_proximal_link_collision_0_right_ring_proximal_link" />
                              <body name="right_ring_distal_link" pos="0 0 0.035">
                                <inertial mass="0.009" pos="0.00400152072427 -8.86239943177e-09 0.0158507854778" fullinertia="1.12885956258e-06 1.24609808053e-06 2.66952445897e-07 0 -3.51697800791e-07 0" />
                                <joint name="right_ring_distal_joint" type="hinge" axis="0 1 0" range="0 1.63" actuatorfrcrange="-2 2" />
                                <geom name="right_ring_distal_link_visual_0" class="visual" mesh="right_ring_distal_link_visual_0_right_ring_distal_link" rgba="1 1 1 1" />
                                <geom name="right_ring_distal_link_collision_0" class="collision" mesh="right_ring_distal_link_collision_0_right_ring_distal_link" />
                                <body name="right_ring_tip_link" pos="0.012266 0 0.039501" quat="0.971858569571 0 0.235565109366 0" />
                                <body name="right_ring_touch_link" pos="0.0154392324698 0 0.0260561041382" quat="0.971858307956 0 0.235566188697 0">
                                  <inertial mass="0.002" pos="-0.00305368567531 -2.24268923991e-08 0.00307741561387" fullinertia="4.07923039609e-08 3.32849436641e-08 1.7990090995e-08 0 9.30939975411e-09 0" />
                                  <geom name="right_ring_touch_link_visual_0" class="visual" mesh="right_ring_touch_link_visual_0_right_ring_touch_link" rgba="1 1 1 1" />
                                  <geom name="right_ring_touch_link_collision_0" class="collision" mesh="right_ring_touch_link_collision_0_right_ring_touch_link" />
                                </body>
                              </body>
                            </body>
                            <body name="right_pinky_proximal_link" pos="-0.0023566 -0.029366 0.078694" quat="0.992245493622 0.0523869549011 0.0771065283009 0.0822135672249">
                              <inertial mass="0.009" pos="-0.00197533466253 -2.90234586164e-07 0.0158239877313" fullinertia="7.07777662099e-07 6.61135925068e-07 2.70140803715e-07 0 -1.37075703489e-08 0" />
                              <joint name="right_pinky_proximal_joint" type="hinge" axis="0 1 0" range="0 1.41" actuatorfrcrange="-2 2" />
                              <geom name="right_pinky_proximal_link_visual_0" class="visual" mesh="right_pinky_proximal_link_visual_0_right_pinky_proximal_link" rgba="1 1 1 1" />
                              <geom name="right_pinky_proximal_link_collision_0" class="collision" mesh="right_pinky_proximal_link_collision_0_right_pinky_proximal_link" />
                              <body name="right_pinky_distal_link" pos="0 0 0.029">
                                <inertial mass="0.009" pos="0.00325665294414 -3.00436958265e-07 0.0128483833407" fullinertia="8.43985852774e-07 9.27716589164e-07 2.29731897956e-07 0 -2.5703935799e-07 0" />
                                <joint name="right_pinky_distal_joint" type="hinge" axis="0 1 0" range="0 1.63" actuatorfrcrange="-2 2" />
                                <geom name="right_pinky_distal_link_visual_0" class="visual" mesh="right_pinky_distal_link_visual_0_right_pinky_distal_link" rgba="1 1 1 1" />
                                <geom name="right_pinky_distal_link_collision_0" class="collision" mesh="right_pinky_distal_link_collision_0_right_pinky_distal_link" />
                                <body name="right_pinky_tip_link" pos="0.010221 0 0.032918" quat="0.971858569571 0 0.235565109366 0" />
                                <body name="right_pinky_touch_link" pos="0.01401 0 0.021124" quat="0.971858569571 0 0.235565109366 0">
                                  <inertial mass="0.002" pos="-0.00289600606139 1.33924877412e-08 0.00165313291447" fullinertia="3.69716839175e-08 2.85901106741e-08 1.75392447475e-08 0 7.65650299473e-09 0" />
                                  <geom name="right_pinky_touch_link_visual_0" class="visual" mesh="right_pinky_touch_link_visual_0_right_pinky_touch_link" rgba="1 1 1 1" />
                                  <geom name="right_pinky_touch_link_collision_0" class="collision" mesh="right_pinky_touch_link_collision_0_right_pinky_touch_link" />
                                </body>
                              </body>
                            </body>
                          </body>
                        </body>
                      </body>
                    </body>
                  </body>
                </body>
              </body>
            </body>
          </body>
        </body>
      </body>
    </body>
  </worldbody>
</mujoco>