<?xml version='1.0' encoding='utf-8'?>
<mujoco model="revoarm_bimanual">
  <compiler angle="radian" autolimits="true" balanceinertia="true" />
  <option cone="elliptic" impratio="10" />
  <default>
    <default class="visual">
      <geom type="mesh" contype="0" conaffinity="0" group="2" />
    </default>
    <default class="collision">
      <geom type="mesh" group="3" />
    </default>
  </default>
  <asset>
    <mesh name="base_link_visual_0_base_link" file="../meshes/body/visual/bimanual/base_link.STL" />
    <mesh name="base_link_collision_0_base_link" file="../meshes/body/collision/bimanual/base_link.STL" />
    <mesh name="left_arm_link1_visual_0_left_arm_link1" file="../meshes/arm/visual/left_arm_link1.STL" />
    <mesh name="left_arm_link1_collision_0_left_arm_link1" file="../meshes/arm/collision/left_arm_link1.STL" />
    <mesh name="left_arm_link2_visual_0_left_arm_link2" file="../meshes/arm/visual/left_arm_link2.STL" />
    <mesh name="left_arm_link2_collision_0_left_arm_link2" file="../meshes/arm/collision/left_arm_link2.STL" />
    <mesh name="left_arm_link3_visual_0_left_arm_link3" file="../meshes/arm/visual/left_arm_link3.STL" />
    <mesh name="left_arm_link3_collision_0_left_arm_link3" file="../meshes/arm/collision/left_arm_link3.STL" />
    <mesh name="left_arm_link4_visual_0_left_arm_link4" file="../meshes/arm/visual/left_arm_link4.STL" />
    <mesh name="left_arm_link4_collision_0_left_arm_link4" file="../meshes/arm/collision/left_arm_link4.STL" />
    <mesh name="left_arm_link5_visual_0_left_arm_link5" file="../meshes/arm/visual/left_arm_link5.STL" />
    <mesh name="left_arm_link5_collision_0_left_arm_link5" file="../meshes/arm/collision/left_arm_link5.STL" />
    <mesh name="left_arm_link6_visual_0_left_arm_link6" file="../meshes/arm/visual/left_arm_link6.STL" />
    <mesh name="left_arm_link6_collision_0_left_arm_link6" file="../meshes/arm/collision/left_arm_link6.STL" />
    <mesh name="left_connector_link_visual_0_left_revo3_connector" file="../meshes/connector/visual/left_revo3_connector.STL" />
    <mesh name="left_connector_link_collision_0_left_revo3_connector" file="../meshes/connector/collision/left_revo3_connector.STL" />
    <mesh name="left_hand_base_link_visual_0_base_link" file="../meshes/hands/visual/left/base_link.STL" />
    <mesh name="left_hand_base_link_collision_0_part_000" file="../meshes/hands/collision/left/part_000.obj" />
    <mesh name="left_hand_base_link_collision_1_part_001" file="../meshes/hands/collision/left/part_001.obj" />
    <mesh name="left_hand_base_link_collision_2_part_002" file="../meshes/hands/collision/left/part_002.obj" />
    <mesh name="left_hand_base_link_collision_3_part_003" file="../meshes/hands/collision/left/part_003.obj" />
    <mesh name="left_hand_base_link_collision_4_part_004" file="../meshes/hands/collision/left/part_004.obj" />
    <mesh name="left_hand_base_link_collision_5_part_005" file="../meshes/hands/collision/left/part_005.obj" />
    <mesh name="left_hand_base_link_collision_6_part_006" file="../meshes/hands/collision/left/part_006.obj" />
    <mesh name="left_hand_base_link_collision_7_part_007" file="../meshes/hands/collision/left/part_007.obj" />
    <mesh name="left_hand_base_link_collision_8_part_008" file="../meshes/hands/collision/left/part_008.obj" />
    <mesh name="left_hand_base_link_collision_9_part_009" file="../meshes/hands/collision/left/part_009.obj" />
    <mesh name="left_hand_base_link_collision_10_part_010" file="../meshes/hands/collision/left/part_010.obj" />
    <mesh name="left_hand_base_link_collision_11_part_011" file="../meshes/hands/collision/left/part_011.obj" />
    <mesh name="left_hand_base_link_collision_12_part_012" file="../meshes/hands/collision/left/part_012.obj" />
    <mesh name="left_hand_base_link_collision_13_part_013" file="../meshes/hands/collision/left/part_013.obj" />
    <mesh name="left_hand_base_link_collision_14_part_014" file="../meshes/hands/collision/left/part_014.obj" />
    <mesh name="left_hand_base_link_collision_15_part_015" file="../meshes/hands/collision/left/part_015.obj" />
    <mesh name="left_hand_base_link_collision_16_part_016" file="../meshes/hands/collision/left/part_016.obj" />
    <mesh name="left_hand_base_link_collision_17_part_017" file="../meshes/hands/collision/left/part_017.obj" />
    <mesh name="left_hand_base_link_collision_18_part_018" file="../meshes/hands/collision/left/part_018.obj" />
    <mesh name="left_hand_base_link_collision_19_part_019" file="../meshes/hands/collision/left/part_019.obj" />
    <mesh name="left_hand_base_link_collision_20_part_020" file="../meshes/hands/collision/left/part_020.obj" />
    <mesh name="left_hand_base_link_collision_21_part_021" file="../meshes/hands/collision/left/part_021.obj" />
    <mesh name="left_hand_base_link_collision_22_part_022" file="../meshes/hands/collision/left/part_022.obj" />
    <mesh name="left_hand_base_link_collision_23_part_023" file="../meshes/hands/collision/left/part_023.obj" />
    <mesh name="left_hand_base_link_collision_24_part_024" file="../meshes/hands/collision/left/part_024.obj" />
    <mesh name="left_thumb_CMP_Link_visual_0_left_thumb_CMP_Link" file="../meshes/hands/visual/left/left_thumb_CMP_Link.STL" />
    <mesh name="left_thumb_CMP_Link_collision_0_left_thumb_CMP_Link" file="../meshes/hands/collision/left/left_thumb_CMP_Link.STL" />
    <mesh name="left_thumb_CMR_Link_visual_0_left_thumb_CMR_Link" file="../meshes/hands/visual/left/left_thumb_CMR_Link.STL" />
    <mesh name="left_thumb_CMR_Link_collision_0_left_thumb_CMR_Link" file="../meshes/hands/collision/left/left_thumb_CMR_Link.STL" />
    <mesh name="left_thumb_MCP_Link_visual_0_left_thumb_MCP_Link" file="../meshes/hands/visual/left/left_thumb_MCP_Link.STL" />
    <mesh name="left_thumb_MCP_Link_collision_0_left_thumb_MCP_Link" file="../meshes/hands/collision/left/left_thumb_MCP_Link.STL" />
    <mesh name="left_thumb_PIP_Link_visual_0_left_thumb_PIP_Link" file="../meshes/hands/visual/left/left_thumb_PIP_Link.STL" />
    <mesh name="left_thumb_PIP_Link_collision_0_left_thumb_PIP_Link" file="../meshes/hands/collision/left/left_thumb_PIP_Link.STL" />
    <mesh name="left_thumb_DIP_Link_visual_0_left_thumb_DIP_Link" file="../meshes/hands/visual/left/left_thumb_DIP_Link.STL" />
    <mesh name="left_thumb_DIP_Link_collision_0_left_thumb_DIP_Link" file="../meshes/hands/collision/left/left_thumb_DIP_Link.STL" />
    <mesh name="left_index_MPR_Link_visual_0_left_index_MPR_Link" file="../meshes/hands/visual/left/left_index_MPR_Link.STL" />
    <mesh name="left_index_MPR_Link_collision_0_left_index_MPR_Link" file="../meshes/hands/collision/left/left_index_MPR_Link.STL" />
    <mesh name="left_index_MCP_Link_visual_0_left_index_MCP_Link" file="../meshes/hands/visual/left/left_index_MCP_Link.STL" />
    <mesh name="left_index_MCP_Link_collision_0_left_index_MCP_Link" file="../meshes/hands/collision/left/left_index_MCP_Link.STL" />
    <mesh name="left_index_PIP_Link_visual_0_left_index_PIP_Link" file="../meshes/hands/visual/left/left_index_PIP_Link.STL" />
    <mesh name="left_index_PIP_Link_collision_0_left_index_PIP_Link" file="../meshes/hands/collision/left/left_index_PIP_Link.STL" />
    <mesh name="left_index_DIP_Link_visual_0_left_index_DIP_Link" file="../meshes/hands/visual/left/left_index_DIP_Link.STL" />
    <mesh name="left_index_DIP_Link_collision_0_left_index_DIP_Link" file="../meshes/hands/collision/left/left_index_DIP_Link.STL" />
    <mesh name="left_middle_MPR_Link_visual_0_left_middle_MPR_Link" file="../meshes/hands/visual/left/left_middle_MPR_Link.STL" />
    <mesh name="left_middle_MPR_Link_collision_0_left_middle_MPR_Link" file="../meshes/hands/collision/left/left_middle_MPR_Link.STL" />
    <mesh name="left_middle_MCP_Link_visual_0_left_middle_MCP_Link" file="../meshes/hands/visual/left/left_middle_MCP_Link.STL" />
    <mesh name="left_middle_MCP_Link_collision_0_left_middle_MCP_Link" file="../meshes/hands/collision/left/left_middle_MCP_Link.STL" />
    <mesh name="left_middle_PIP_Link_visual_0_left_middle_PIP_Link" file="../meshes/hands/visual/left/left_middle_PIP_Link.STL" />
    <mesh name="left_middle_PIP_Link_collision_0_left_middle_PIP_Link" file="../meshes/hands/collision/left/left_middle_PIP_Link.STL" />
    <mesh name="left_middle_DIP_Link_visual_0_left_middle_DIP_Link" file="../meshes/hands/visual/left/left_middle_DIP_Link.STL" />
    <mesh name="left_middle_DIP_Link_collision_0_left_middle_DIP_Link" file="../meshes/hands/collision/left/left_middle_DIP_Link.STL" />
    <mesh name="left_ring_MPR_Link_visual_0_left_ring_MPR_Link" file="../meshes/hands/visual/left/left_ring_MPR_Link.STL" />
    <mesh name="left_ring_MPR_Link_collision_0_left_ring_MPR_Link" file="../meshes/hands/collision/left/left_ring_MPR_Link.STL" />
    <mesh name="left_ring_MCP_Link_visual_0_left_ring_MCP_Link" file="../meshes/hands/visual/left/left_ring_MCP_Link.STL" />
    <mesh name="left_ring_MCP_Link_collision_0_left_ring_MCP_Link" file="../meshes/hands/collision/left/left_ring_MCP_Link.STL" />
    <mesh name="left_ring_PIP_Link_visual_0_left_ring_PIP_Link" file="../meshes/hands/visual/left/left_ring_PIP_Link.STL" />
    <mesh name="left_ring_PIP_Link_collision_0_left_ring_PIP_Link" file="../meshes/hands/collision/left/left_ring_PIP_Link.STL" />
    <mesh name="left_ring_DIP_Link_visual_0_left_ring_DIP_Link" file="../meshes/hands/visual/left/left_ring_DIP_Link.STL" />
    <mesh name="left_ring_DIP_Link_collision_0_left_ring_DIP_Link" file="../meshes/hands/collision/left/left_ring_DIP_Link.STL" />
    <mesh name="left_little_MPR_Link_visual_0_left_little_MPR_Link" file="../meshes/hands/visual/left/left_little_MPR_Link.STL" />
    <mesh name="left_little_MPR_Link_collision_0_left_little_MPR_Link" file="../meshes/hands/collision/left/left_little_MPR_Link.STL" />
    <mesh name="left_little_MCP_Link_visual_0_left_little_MCP_Link" file="../meshes/hands/visual/left/left_little_MCP_Link.STL" />
    <mesh name="left_little_MCP_Link_collision_0_left_little_MCP_Link" file="../meshes/hands/collision/left/left_little_MCP_Link.STL" />
    <mesh name="left_little_PIP_Link_visual_0_left_little_PIP_Link" file="../meshes/hands/visual/left/left_little_PIP_Link.STL" />
    <mesh name="left_little_PIP_Link_collision_0_left_little_PIP_Link" file="../meshes/hands/collision/left/left_little_PIP_Link.STL" />
    <mesh name="left_little_DIP_Link_visual_0_left_little_DIP_Link" file="../meshes/hands/visual/left/left_little_DIP_Link.STL" />
    <mesh name="left_little_DIP_Link_collision_0_left_little_DIP_Link" file="../meshes/hands/collision/left/left_little_DIP_Link.STL" />
    <mesh name="right_arm_link1_visual_0_right_arm_link1" file="../meshes/arm/visual/right_arm_link1.STL" />
    <mesh name="right_arm_link1_collision_0_right_arm_link1" file="../meshes/arm/collision/right_arm_link1.STL" />
    <mesh name="right_arm_link2_visual_0_right_arm_link2" file="../meshes/arm/visual/right_arm_link2.STL" />
    <mesh name="right_arm_link2_collision_0_right_arm_link2" file="../meshes/arm/collision/right_arm_link2.STL" />
    <mesh name="right_arm_link3_visual_0_right_arm_link3" file="../meshes/arm/visual/right_arm_link3.STL" />
    <mesh name="right_arm_link3_collision_0_right_arm_link3" file="../meshes/arm/collision/right_arm_link3.STL" />
    <mesh name="right_arm_link4_visual_0_right_arm_link4" file="../meshes/arm/visual/right_arm_link4.STL" />
    <mesh name="right_arm_link4_collision_0_right_arm_link4" file="../meshes/arm/collision/right_arm_link4.STL" />
    <mesh name="right_arm_link5_visual_0_right_arm_link5" file="../meshes/arm/visual/right_arm_link5.STL" />
    <mesh name="right_arm_link5_collision_0_right_arm_link5" file="../meshes/arm/collision/right_arm_link5.STL" />
    <mesh name="right_arm_link6_visual_0_right_arm_link6" file="../meshes/arm/visual/right_arm_link6.STL" />
    <mesh name="right_arm_link6_collision_0_right_arm_link6" file="../meshes/arm/collision/right_arm_link6.STL" />
    <mesh name="right_connector_link_visual_0_right_revo3_connector" file="../meshes/connector/visual/right_revo3_connector.STL" />
    <mesh name="right_connector_link_collision_0_right_revo3_connector" file="../meshes/connector/collision/right_revo3_connector.STL" />
    <mesh name="right_hand_base_link_visual_0_base_link" file="../meshes/hands/visual/right/base_link.STL" />
    <mesh name="right_hand_base_link_collision_0_part_000" file="../meshes/hands/collision/right/part_000.obj" />
    <mesh name="right_hand_base_link_collision_1_part_001" file="../meshes/hands/collision/right/part_001.obj" />
    <mesh name="right_hand_base_link_collision_2_part_002" file="../meshes/hands/collision/right/part_002.obj" />
    <mesh name="right_hand_base_link_collision_3_part_003" file="../meshes/hands/collision/right/part_003.obj" />
    <mesh name="right_hand_base_link_collision_4_part_004" file="../meshes/hands/collision/right/part_004.obj" />
    <mesh name="right_hand_base_link_collision_5_part_005" file="../meshes/hands/collision/right/part_005.obj" />
    <mesh name="right_hand_base_link_collision_6_part_006" file="../meshes/hands/collision/right/part_006.obj" />
    <mesh name="right_hand_base_link_collision_7_part_007" file="../meshes/hands/collision/right/part_007.obj" />
    <mesh name="right_hand_base_link_collision_8_part_008" file="../meshes/hands/collision/right/part_008.obj" />
    <mesh name="right_hand_base_link_collision_9_part_009" file="../meshes/hands/collision/right/part_009.obj" />
    <mesh name="right_hand_base_link_collision_10_part_010" file="../meshes/hands/collision/right/part_010.obj" />
    <mesh name="right_hand_base_link_collision_11_part_011" file="../meshes/hands/collision/right/part_011.obj" />
    <mesh name="right_hand_base_link_collision_12_part_012" file="../meshes/hands/collision/right/part_012.obj" />
    <mesh name="right_hand_base_link_collision_13_part_013" file="../meshes/hands/collision/right/part_013.obj" />
    <mesh name="right_hand_base_link_collision_14_part_014" file="../meshes/hands/collision/right/part_014.obj" />
    <mesh name="right_hand_base_link_collision_15_part_015" file="../meshes/hands/collision/right/part_015.obj" />
    <mesh name="right_hand_base_link_collision_16_part_016" file="../meshes/hands/collision/right/part_016.obj" />
    <mesh name="right_hand_base_link_collision_17_part_017" file="../meshes/hands/collision/right/part_017.obj" />
    <mesh name="right_hand_base_link_collision_18_part_018" file="../meshes/hands/collision/right/part_018.obj" />
    <mesh name="right_hand_base_link_collision_19_part_019" file="../meshes/hands/collision/right/part_019.obj" />
    <mesh name="right_hand_base_link_collision_20_part_020" file="../meshes/hands/collision/right/part_020.obj" />
    <mesh name="right_hand_base_link_collision_21_part_021" file="../meshes/hands/collision/right/part_021.obj" />
    <mesh name="right_hand_base_link_collision_22_part_022" file="../meshes/hands/collision/right/part_022.obj" />
    <mesh name="right_hand_base_link_collision_23_part_023" file="../meshes/hands/collision/right/part_023.obj" />
    <mesh name="right_hand_base_link_collision_24_part_024" file="../meshes/hands/collision/right/part_024.obj" />
    <mesh name="right_hand_base_link_collision_25_part_025" file="../meshes/hands/collision/right/part_025.obj" />
    <mesh name="right_hand_base_link_collision_26_part_026" file="../meshes/hands/collision/right/part_026.obj" />
    <mesh name="right_hand_base_link_collision_27_part_027" file="../meshes/hands/collision/right/part_027.obj" />
    <mesh name="right_thumb_CMP_Link_visual_0_right_thumb_CMP_Link" file="../meshes/hands/visual/right/right_thumb_CMP_Link.STL" />
    <mesh name="right_thumb_CMP_Link_collision_0_right_thumb_CMP_Link" file="../meshes/hands/collision/right/right_thumb_CMP_Link.STL" />
    <mesh name="right_thumb_CMR_Link_visual_0_right_thumb_CMR_Link" file="../meshes/hands/visual/right/right_thumb_CMR_Link.STL" />
    <mesh name="right_thumb_CMR_Link_collision_0_right_thumb_CMR_Link" file="../meshes/hands/collision/right/right_thumb_CMR_Link.STL" />
    <mesh name="right_thumb_MCP_Link_visual_0_right_thumb_MCP_Link" file="../meshes/hands/visual/right/right_thumb_MCP_Link.STL" />
    <mesh name="right_thumb_MCP_Link_collision_0_right_thumb_MCP_Link" file="../meshes/hands/collision/right/right_thumb_MCP_Link.STL" />
    <mesh name="right_thumb_PIP_Link_visual_0_right_thumb_PIP_Link" file="../meshes/hands/visual/right/right_thumb_PIP_Link.STL" />
    <mesh name="right_thumb_PIP_Link_collision_0_right_thumb_PIP_Link" file="../meshes/hands/collision/right/right_thumb_PIP_Link.STL" />
    <mesh name="right_thumb_DIP_Link_visual_0_right_thumb_DIP_Link" file="../meshes/hands/visual/right/right_thumb_DIP_Link.STL" />
    <mesh name="right_thumb_DIP_Link_collision_0_right_thumb_DIP_Link" file="../meshes/hands/collision/right/right_thumb_DIP_Link.STL" />
    <mesh name="right_index_MPR_Link_visual_0_right_index_MPR_Link" file="../meshes/hands/visual/right/right_index_MPR_Link.STL" />
    <mesh name="right_index_MPR_Link_collision_0_right_index_MPR_Link" file="../meshes/hands/collision/right/right_index_MPR_Link.STL" />
    <mesh name="right_index_MCP_Link_visual_0_right_index_MCP_Link" file="../meshes/hands/visual/right/right_index_MCP_Link.STL" />
    <mesh name="right_index_MCP_Link_collision_0_right_index_MCP_Link" file="../meshes/hands/collision/right/right_index_MCP_Link.STL" />
    <mesh name="right_index_PIP_Link_visual_0_right_index_PIP_Link" file="../meshes/hands/visual/right/right_index_PIP_Link.STL" />
    <mesh name="right_index_PIP_Link_collision_0_right_index_PIP_Link" file="../meshes/hands/collision/right/right_index_PIP_Link.STL" />
    <mesh name="right_index_DIP_Link_visual_0_right_index_DIP_Link" file="../meshes/hands/visual/right/right_index_DIP_Link.STL" />
    <mesh name="right_index_DIP_Link_collision_0_right_index_DIP_Link" file="../meshes/hands/collision/right/right_index_DIP_Link.STL" />
    <mesh name="right_middle_MPR_Link_visual_0_right_middle_MPR_Link" file="../meshes/hands/visual/right/right_middle_MPR_Link.STL" />
    <mesh name="right_middle_MPR_Link_collision_0_right_middle_MPR_Link" file="../meshes/hands/collision/right/right_middle_MPR_Link.STL" />
    <mesh name="right_middle_MCP_Link_visual_0_right_middle_MCP_Link" file="../meshes/hands/visual/right/right_middle_MCP_Link.STL" />
    <mesh name="right_middle_MCP_Link_collision_0_right_middle_MCP_Link" file="../meshes/hands/collision/right/right_middle_MCP_Link.STL" />
    <mesh name="right_middle_PIP_Link_visual_0_right_middle_PIP_Link" file="../meshes/hands/visual/right/right_middle_PIP_Link.STL" />
    <mesh name="right_middle_PIP_Link_collision_0_right_middle_PIP_Link" file="../meshes/hands/collision/right/right_middle_PIP_Link.STL" />
    <mesh name="right_middle_DIP_Link_visual_0_right_middle_DIP_Link" file="../meshes/hands/visual/right/right_middle_DIP_Link.STL" />
    <mesh name="right_middle_DIP_Link_collision_0_right_middle_DIP_Link" file="../meshes/hands/collision/right/right_middle_DIP_Link.STL" />
    <mesh name="right_ring_MPR_Link_visual_0_right_ring_MPR_Link" file="../meshes/hands/visual/right/right_ring_MPR_Link.STL" />
    <mesh name="right_ring_MPR_Link_collision_0_right_ring_MPR_Link" file="../meshes/hands/collision/right/right_ring_MPR_Link.STL" />
    <mesh name="right_ring_MCP_Link_visual_0_right_ring_MCP_Link" file="../meshes/hands/visual/right/right_ring_MCP_Link.STL" />
    <mesh name="right_ring_MCP_Link_collision_0_right_ring_MCP_Link" file="../meshes/hands/collision/right/right_ring_MCP_Link.STL" />
    <mesh name="right_ring_PIP_Link_visual_0_right_ring_PIP_Link" file="../meshes/hands/visual/right/right_ring_PIP_Link.STL" />
    <mesh name="right_ring_PIP_Link_collision_0_right_ring_PIP_Link" file="../meshes/hands/collision/right/right_ring_PIP_Link.STL" />
    <mesh name="right_ring_DIP_Link_visual_0_right_ring_DIP_Link" file="../meshes/hands/visual/right/right_ring_DIP_Link.STL" />
    <mesh name="right_ring_DIP_Link_collision_0_right_ring_DIP_Link" file="../meshes/hands/collision/right/right_ring_DIP_Link.STL" />
    <mesh name="right_little_MPR_Link_visual_0_right_little_MPR_Link" file="../meshes/hands/visual/right/right_little_MPR_Link.STL" />
    <mesh name="right_little_MPR_Link_collision_0_right_little_MPR_Link" file="../meshes/hands/collision/right/right_little_MPR_Link.STL" />
    <mesh name="right_little_MCP_Link_visual_0_right_little_MCP_Link" file="../meshes/hands/visual/right/right_little_MCP_Link.STL" />
    <mesh name="right_little_MCP_Link_collision_0_right_little_MCP_Link" file="../meshes/hands/collision/right/right_little_MCP_Link.STL" />
    <mesh name="right_little_PIP_Link_visual_0_right_little_PIP_Link" file="../meshes/hands/visual/right/right_little_PIP_Link.STL" />
    <mesh name="right_little_PIP_Link_collision_0_right_little_PIP_Link" file="../meshes/hands/collision/right/right_little_PIP_Link.STL" />
    <mesh name="right_little_DIP_Link_visual_0_right_little_DIP_Link" file="../meshes/hands/visual/right/right_little_DIP_Link.STL" />
    <mesh name="right_little_DIP_Link_collision_0_right_little_DIP_Link" file="../meshes/hands/collision/right/right_little_DIP_Link.STL" />
  </asset>
  <worldbody>
    <body name="base_link">
      <inertial mass="20.9229828634" pos="0.00366369659918 -2.56673169996e-05 -0.6401483469" fullinertia="3.13550082094 3.13363525493 0.352520792674 -2.20161422074e-05 -0.0122674408678 8.21094464182e-05" />
      <geom name="base_link_visual_0" class="visual" mesh="base_link_visual_0_base_link" rgba="0.054902 0.054902 0.054902 1" />
      <geom name="base_link_collision_0" class="collision" mesh="base_link_collision_0_base_link" />
      <body name="left_base_link" pos="0.0055 0.10424 -0.038037" quat="0.996194825565 0.0871542857135 0 0">
        <body name="left_arm_link1">
          <inertial mass="0.99862" pos="0.00145589524176 0.0527165718617 -0.001274692537" fullinertia="0.0013455582137 0.000835877597536 0.00103394315647 -7.83153183344e-06 -1.15846408443e-06 -5.11169745924e-05" />
          <joint name="revoarm_left_joint1" type="hinge" axis="0 1 0" range="-4.1015 0.7854" actuatorfrcrange="-40 40" />
          <geom name="left_arm_link1_visual_0" class="visual" mesh="left_arm_link1_visual_0_left_arm_link1" rgba="1 1 1 1" />
          <geom name="left_arm_link1_collision_0" class="collision" mesh="left_arm_link1_collision_0_left_arm_link1" />
          <body name="left_arm_link2" pos="0 0.06 0" quat="0.996194825565 -0.0871542857135 0 0">
            <inertial mass="0.1942" pos="0.000352233546428 0.000380054519844 -0.0276718369676" fullinertia="0.000379846121944 0.000367869466548 0.000208453243267 -1.46309430499e-06 1.60311996102e-06 1.58239590757e-06" />
            <joint name="revoarm_left_joint2" type="hinge" axis="1 0 0" range="-0.1745 3.3161" actuatorfrcrange="-40 40" />
            <geom name="left_arm_link2_visual_0" class="visual" mesh="left_arm_link2_visual_0_left_arm_link2" rgba="1 1 1 1" />
            <geom name="left_arm_link2_collision_0" class="collision" mesh="left_arm_link2_collision_0_left_arm_link2" />
            <body name="left_arm_link3" pos="0 0 -0.099">
              <inertial mass="0.56897" pos="-0.000388567199254 -1.85684133796e-05 -0.0669511733196" fullinertia="0.00134702450955 0.00131837810042 0.0004885001058 3.82402964514e-07 -1.08091349719e-05 4.50889646437e-07" />
              <joint name="revoarm_left_joint3" type="hinge" axis="0 0 -1" range="-3.6652 0.5236" actuatorfrcrange="-27 27" />
              <geom name="left_arm_link3_visual_0" class="visual" mesh="left_arm_link3_visual_0_left_arm_link3" rgba="1 1 1 1" />
              <geom name="left_arm_link3_collision_0" class="collision" mesh="left_arm_link3_collision_0_left_arm_link3" />
              <body name="left_arm_link4" pos="0 0 -0.121">
                <inertial mass="0.43039" pos="-9.92890726825e-05 -0.000354021524004 -0.0253684032106" fullinertia="0.000471779353788 0.000474067782015 0.000276647751942 -1.24429020499e-07 -7.68857610764e-07 2.52611367384e-06" />
                <joint name="revoarm_left_joint4" type="hinge" axis="0 -1 0" range="-0.34907 2.2166" actuatorfrcrange="-27 27" />
                <geom name="left_arm_link4_visual_0" class="visual" mesh="left_arm_link4_visual_0_left_arm_link4" rgba="1 1 1 1" />
                <geom name="left_arm_link4_collision_0" class="collision" mesh="left_arm_link4_collision_0_left_arm_link4" />
                <body name="left_arm_link5" pos="0 0 -0.0635">
                  <inertial mass="0.80969" pos="0.000927310939411 -0.000140840890934 -0.0744269242701" fullinertia="0.00182621861674 0.00183389455605 0.000561624044255 1.42794413935e-08 2.78122930684e-05 -2.85482783549e-06" />
                  <joint name="revoarm_left_joint5" type="hinge" axis="0 0 -1" range="-3.1444 0.9044" actuatorfrcrange="-7 7" />
                  <geom name="left_arm_link5_visual_0" class="visual" mesh="left_arm_link5_visual_0_left_arm_link5" rgba="1 1 1 1" />
                  <geom name="left_arm_link5_collision_0" class="collision" mesh="left_arm_link5_collision_0_left_arm_link5" />
                  <body name="left_arm_link6" pos="0 0 -0.1525">
                    <inertial mass="0.31466" pos="0.000140526799188 -0.00104942724126 -2.24896287196e-05" fullinertia="0.000121008420212 0.000136729119341 0.000137816234187 -2.1489023912e-07 -6.95891723799e-08 -2.01066845192e-07" />
                    <joint name="revoarm_left_joint6" type="hinge" axis="-1 0 0" range="-0.64577 0.64577" actuatorfrcrange="-7 7" />
                    <geom name="left_arm_link6_visual_0" class="visual" mesh="left_arm_link6_visual_0_left_arm_link6" rgba="1 1 1 1" />
                    <geom name="left_arm_link6_collision_0" class="collision" mesh="left_arm_link6_collision_0_left_arm_link6" />
                    <body name="left_arm_link7" quat="0.999999529356 -0.000970199847794 0 0">
                      <joint name="revoarm_left_joint7" type="hinge" axis="0 -1 0" range="-1.5708 1.5708" actuatorfrcrange="-7 7" />
                      <body name="left_connector_link" pos="0 0 -0.06054" quat="0.000796326710733 0 0 0.999999682932">
                        <inertial mass="0.49311" pos="-0.000112789719115 3.15409595372e-05 0.0332550987036" fullinertia="0.000363541323954 0.000228003269421 0.000267966997878 -1.86964397359e-06 -1.25245784266e-06 -5.07776634422e-06" />
                        <geom name="left_connector_link_visual_0" class="visual" mesh="left_connector_link_visual_0_left_revo3_connector" rgba="1.0 1.0 1.0 1.0" />
                        <geom name="left_connector_link_collision_0" class="collision" mesh="left_connector_link_collision_0_left_revo3_connector" />
                        <body name="left_connector_tip" quat="6.34136230227e-07 -0.999999365864 0.000796326458243 0.000796326458243">
                          <body name="left_hand_base_link" pos="0 0 -0.0118">
                            <inertial mass="0.462" pos="-0.00143242 0.00300504 0.03174006" fullinertia="0.00068956 0.00052166 0.00038263 2.06e-06 1.674e-05 -1.226e-05" />
                            <geom name="left_hand_base_link_visual_0" class="visual" mesh="left_hand_base_link_visual_0_base_link" rgba="1 1 1 1" />
                            <geom name="left_hand_base_link_collision_0" class="collision" mesh="left_hand_base_link_collision_0_part_000" />
                            <geom name="left_hand_base_link_collision_1" class="collision" mesh="left_hand_base_link_collision_1_part_001" />
                            <geom name="left_hand_base_link_collision_2" class="collision" mesh="left_hand_base_link_collision_2_part_002" />
                            <geom name="left_hand_base_link_collision_3" class="collision" mesh="left_hand_base_link_collision_3_part_003" />
                            <geom name="left_hand_base_link_collision_4" class="collision" mesh="left_hand_base_link_collision_4_part_004" />
                            <geom name="left_hand_base_link_collision_5" class="collision" mesh="left_hand_base_link_collision_5_part_005" />
                            <geom name="left_hand_base_link_collision_6" class="collision" mesh="left_hand_base_link_collision_6_part_006" />
                            <geom name="left_hand_base_link_collision_7" class="collision" mesh="left_hand_base_link_collision_7_part_007" />
                            <geom name="left_hand_base_link_collision_8" class="collision" mesh="left_hand_base_link_collision_8_part_008" />
                            <geom name="left_hand_base_link_collision_9" class="collision" mesh="left_hand_base_link_collision_9_part_009" />
                            <geom name="left_hand_base_link_collision_10" class="collision" mesh="left_hand_base_link_collision_10_part_010" />
                            <geom name="left_hand_base_link_collision_11" class="collision" mesh="left_hand_base_link_collision_11_part_011" />
                            <geom name="left_hand_base_link_collision_12" class="collision" mesh="left_hand_base_link_collision_12_part_012" />
                            <geom name="left_hand_base_link_collision_13" class="collision" mesh="left_hand_base_link_collision_13_part_013" />
                            <geom name="left_hand_base_link_collision_14" class="collision" mesh="left_hand_base_link_collision_14_part_014" />
                            <geom name="left_hand_base_link_collision_15" class="collision" mesh="left_hand_base_link_collision_15_part_015" />
                            <geom name="left_hand_base_link_collision_16" class="collision" mesh="left_hand_base_link_collision_16_part_016" />
                            <geom name="left_hand_base_link_collision_17" class="collision" mesh="left_hand_base_link_collision_17_part_017" />
                            <geom name="left_hand_base_link_collision_18" class="collision" mesh="left_hand_base_link_collision_18_part_018" />
                            <geom name="left_hand_base_link_collision_19" class="collision" mesh="left_hand_base_link_collision_19_part_019" />
                            <geom name="left_hand_base_link_collision_20" class="collision" mesh="left_hand_base_link_collision_20_part_020" />
                            <geom name="left_hand_base_link_collision_21" class="collision" mesh="left_hand_base_link_collision_21_part_021" />
                            <geom name="left_hand_base_link_collision_22" class="collision" mesh="left_hand_base_link_collision_22_part_022" />
                            <geom name="left_hand_base_link_collision_23" class="collision" mesh="left_hand_base_link_collision_23_part_023" />
                            <geom name="left_hand_base_link_collision_24" class="collision" mesh="left_hand_base_link_collision_24_part_024" />
                            <body name="left_palm" pos="0.0155 0 0.055" />
                            <body name="left_thumb_CMP_Link" pos="0.002 -0.0195 0.051993">
                              <inertial mass="0.026" pos="0 0.00026731 0.00107805" diaginertia="2.03e-06 2.29e-06 2.22e-06" />
                              <joint name="left_thumb_CMP_joint" type="hinge" axis="0 0 1" range="0 1.9199" actuatorfrcrange="-0.35 0.35" />
                              <geom name="left_thumb_CMP_Link_visual_0" class="visual" mesh="left_thumb_CMP_Link_visual_0_left_thumb_CMP_Link" rgba="1 1 1 1" />
                              <geom name="left_thumb_CMP_Link_collision_0" class="collision" mesh="left_thumb_CMP_Link_collision_0_left_thumb_CMP_Link" />
                              <body name="left_thumb_CMR_Link" pos="0 -0.0095 0" quat="0.707388269167 0 0.706825181105 0">
                                <inertial mass="0.012" pos="0 -0.00601564 -0.00128632" fullinertia="5.7e-07 9.5e-07 9.3e-07 0 0 -2e-08" />
                                <joint name="left_thumb_CMR_joint" type="hinge" axis="0 -1 0" range="0 2.0071" actuatorfrcrange="-0.35 0.35" />
                                <geom name="left_thumb_CMR_Link_visual_0" class="visual" mesh="left_thumb_CMR_Link_visual_0_left_thumb_CMR_Link" rgba="1 1 1 1" />
                                <geom name="left_thumb_CMR_Link_collision_0" class="collision" mesh="left_thumb_CMR_Link_collision_0_left_thumb_CMR_Link" />
                                <body name="left_thumb_MCP_Link" pos="0 -0.0125 0">
                                  <inertial mass="0.067" pos="1.261e-05 -0.02200903 -0.00233774" fullinertia="1.46e-05 6.6e-06 1.422e-05 2e-08 0 -8e-07" />
                                  <joint name="left_thumb_MCP_joint" type="hinge" axis="-1 0 0" range="0 0.8727" actuatorfrcrange="-0.35 0.35" />
                                  <geom name="left_thumb_MCP_Link_visual_0" class="visual" mesh="left_thumb_MCP_Link_visual_0_left_thumb_MCP_Link" rgba="1 1 1 1" />
                                  <geom name="left_thumb_MCP_Link_collision_0" class="collision" mesh="left_thumb_MCP_Link_collision_0_left_thumb_MCP_Link" />
                                  <body name="left_thumb_PIP_Link" pos="0 -0.042087 -0.0013667">
                                    <inertial mass="0.035" pos="8.855e-05 -0.01915477 0.00035637" fullinertia="3.31e-06 2.69e-06 4.07e-06 3e-08 0 3e-08" />
                                    <joint name="left_thumb_PIP_joint" type="hinge" axis="-1 0 0" range="0 1.4835" actuatorfrcrange="-0.35 0.35" />
                                    <geom name="left_thumb_PIP_Link_visual_0" class="visual" mesh="left_thumb_PIP_Link_visual_0_left_thumb_PIP_Link" rgba="1 1 1 1" />
                                    <geom name="left_thumb_PIP_Link_collision_0" class="collision" mesh="left_thumb_PIP_Link_collision_0_left_thumb_PIP_Link" />
                                    <body name="left_thumb_DIP_Link" pos="0 -0.031985 -0.00087263">
                                      <inertial mass="0.01" pos="0.00015749 -0.01536012 -0.00123637" fullinertia="1.49e-06 9.6e-07 1.55e-06 -2e-08 0 2.4e-07" />
                                      <joint name="left_thumb_DIP_joint" type="hinge" axis="-1 0 0" range="0 1.4835" actuatorfrcrange="-0.35 0.35" />
                                      <geom name="left_thumb_DIP_Link_visual_0" class="visual" mesh="left_thumb_DIP_Link_visual_0_left_thumb_DIP_Link" rgba="1 1 1 1" />
                                      <geom name="left_thumb_DIP_Link_collision_0" class="collision" mesh="left_thumb_DIP_Link_collision_0_left_thumb_DIP_Link" />
                                      <body name="left_thumb_tip_Link" pos="0 -0.01 0.0098">
                                        <inertial mass="0.001" pos="0 0 0" diaginertia="1e-10 1e-10 1e-09" />
                                      </body>
                                    </body>
                                  </body>
                                </body>
                              </body>
                            </body>
                            <body name="left_index_MPR_Link" pos="-0.005442 -0.036871 0.097822">
                              <inertial mass="0.013" pos="-0.00256772 -0.00103533 0.00812466" fullinertia="1.01e-06 1.02e-06 1.14e-06 0 7e-08 0" />
                              <joint name="left_index_MPR_joint" type="hinge" axis="-0.99836 0.057297 0" range="-0.2618 0.2618" actuatorfrcrange="-0.35 0.35" />
                              <geom name="left_index_MPR_Link_visual_0" class="visual" mesh="left_index_MPR_Link_visual_0_left_index_MPR_Link" rgba="1 1 1 1" />
                              <geom name="left_index_MPR_Link_collision_0" class="collision" mesh="left_index_MPR_Link_collision_0_left_index_MPR_Link" />
                              <body name="left_index_MCP_Link" pos="5.6148e-05 -0.00097833 0.01597">
                                <inertial mass="0.0658" pos="0.00098089 -0.00138701 0.02348288" fullinertia="1.605e-05 1.571e-05 4.97e-06 5e-08 -4.6e-07 6.4e-07" />
                                <joint name="left_index_MCP_joint" type="hinge" axis="-0.05719 0.99648 0.061246" range="0 1.4835" actuatorfrcrange="-0.35 0.35" />
                                <geom name="left_index_MCP_Link_visual_0" class="visual" mesh="left_index_MCP_Link_visual_0_left_index_MCP_Link" rgba="1 1 1 1" />
                                <geom name="left_index_MCP_Link_collision_0" class="collision" mesh="left_index_MCP_Link_collision_0_left_index_MCP_Link" />
                                <body name="left_index_PIP_Link" pos="0.00074519 -0.0028408 0.046916">
                                  <inertial mass="0.031" pos="0.00221548 -0.00096377 0.01775048" fullinertia="3.09e-06 2.62e-06 2.36e-06 3e-08 -1e-07 1e-08" />
                                  <joint name="left_index_PIP_joint" type="hinge" axis="-0.05719 0.99648 0.061246" range="0 1.4835" actuatorfrcrange="-0.35 0.35" />
                                  <geom name="left_index_PIP_Link_visual_0" class="visual" mesh="left_index_PIP_Link_visual_0_left_index_PIP_Link" rgba="1 1 1 1" />
                                  <geom name="left_index_PIP_Link_collision_0" class="collision" mesh="left_index_PIP_Link_collision_0_left_index_PIP_Link" />
                                  <body name="left_index_DIP_Link" pos="0.0013649 -0.0017312 0.029441">
                                    <inertial mass="0.008" pos="-0.00043827 -0.00101802 0.01616508" fullinertia="5.6e-07 5.2e-07 4e-07 0 -4e-08 0" />
                                    <joint name="left_index_DIP_joint" type="hinge" axis="-0.05719 0.99648 0.061246" range="0 1.4835" actuatorfrcrange="-0.35 0.35" />
                                    <geom name="left_index_DIP_Link_visual_0" class="visual" mesh="left_index_DIP_Link_visual_0_left_index_DIP_Link" rgba="1 1 1 1" />
                                    <geom name="left_index_DIP_Link_collision_0" class="collision" mesh="left_index_DIP_Link_collision_0_left_index_DIP_Link" />
                                    <body name="left_index_tip_Link" pos="0.0084 -0.0005 0.01">
                                      <inertial mass="0.001" pos="0 0 0" diaginertia="1e-10 1e-10 1e-09" />
                                    </body>
                                  </body>
                                </body>
                              </body>
                            </body>
                            <body name="left_middle_MPR_Link" pos="-0.0060223 -0.012496 0.10793">
                              <inertial mass="0.012" pos="-0.00261177 -0.00060398 0.00815409" fullinertia="1.01e-06 1.02e-06 1.14e-06 0 7e-08 0" />
                              <joint name="left_middle_MPR_joint" type="hinge" axis="-0.99982 0.019105 0" range="-0.2618 0.2618" actuatorfrcrange="-0.35 0.35" />
                              <geom name="left_middle_MPR_Link_visual_0" class="visual" mesh="left_middle_MPR_Link_visual_0_left_middle_MPR_Link" rgba="1 1 1 1" />
                              <geom name="left_middle_MPR_Link_collision_0" class="collision" mesh="left_middle_MPR_Link_collision_0_left_middle_MPR_Link" />
                              <body name="left_middle_MCP_Link" pos="0 -0.00032687 0.015997">
                                <inertial mass="0.0658" pos="0.00090882 -0.00046345 0.02352214" fullinertia="1.605e-05 1.574e-05 4.93e-06 1e-08 -4.3e-07 2.1e-07" />
                                <joint name="left_middle_MCP_joint" type="hinge" axis="-0.019101 0.99961 0.020433" range="0 1.4835" actuatorfrcrange="-0.35 0.35" />
                                <geom name="left_middle_MCP_Link_visual_0" class="visual" mesh="left_middle_MCP_Link_visual_0_left_middle_MCP_Link" rgba="1 1 1 1" />
                                <geom name="left_middle_MCP_Link_collision_0" class="collision" mesh="left_middle_MCP_Link_collision_0_left_middle_MCP_Link" />
                                <body name="left_middle_PIP_Link" pos="0.00059944 -0.00094917 0.046994">
                                  <inertial mass="0.031" pos="0.00216316 -0.00032205 0.01778015" fullinertia="3.1e-06 2.62e-06 2.36e-06 1e-08 -1e-07 0" />
                                  <joint name="left_middle_PIP_joint" type="hinge" axis="-0.019101 0.99961 0.020433" range="0 1.4835" actuatorfrcrange="-0.35 0.35" />
                                  <geom name="left_middle_PIP_Link_visual_0" class="visual" mesh="left_middle_PIP_Link_visual_0_left_middle_PIP_Link" rgba="1 1 1 1" />
                                  <geom name="left_middle_PIP_Link_collision_0" class="collision" mesh="left_middle_PIP_Link_collision_0_left_middle_PIP_Link" />
                                  <body name="left_middle_DIP_Link" pos="0.0012747 -0.00057846 0.02949">
                                    <inertial mass="0.01" pos="-0.00048948 -0.00033967 0.01619208" fullinertia="5.6e-07 5.2e-07 4e-07 0 -4e-08 0" />
                                    <joint name="left_middle_DIP_joint" type="hinge" axis="-0.019101 0.99961 0.020433" range="0 1.4835" actuatorfrcrange="-0.35 0.35" />
                                    <geom name="left_middle_DIP_Link_visual_0" class="visual" mesh="left_middle_DIP_Link_visual_0_left_middle_DIP_Link" rgba="1 1 1 1" />
                                    <geom name="left_middle_DIP_Link_collision_0" class="collision" mesh="left_middle_DIP_Link_collision_0_left_middle_DIP_Link" />
                                    <body name="left_middle_tip_Link" pos="0.0084 0 0.01">
                                      <inertial mass="0.001" pos="0 0 0" diaginertia="1e-10 1e-10 1e-09" />
                                    </body>
                                  </body>
                                </body>
                              </body>
                            </body>
                            <body name="left_ring_MPR_Link" pos="-0.0061966 0.012414 0.10384">
                              <inertial mass="0.013" pos="-0.00262656 -0.0001702 0.00816992" fullinertia="1.01e-06 1.02e-06 1.14e-06 0 7e-08 0" />
                              <joint name="left_ring_MPR_joint" type="hinge" axis="-0.99982 -0.019105 0" range="-0.2618 0.2618" actuatorfrcrange="-0.35 0.35" />
                              <geom name="left_ring_MPR_Link_visual_0" class="visual" mesh="left_ring_MPR_Link_visual_0_left_ring_MPR_Link" rgba="1 1 1 1" />
                              <geom name="left_ring_MPR_Link_collision_0" class="collision" mesh="left_ring_MPR_Link_collision_0_left_ring_MPR_Link" />
                              <body name="left_ring_MCP_Link" pos="0 0.00032687 0.015997">
                                <inertial mass="0.0658" pos="0.00090883 0.00046347 0.02352212" fullinertia="1.605e-05 1.574e-05 4.93e-06 1e-08 -4.3e-07 2.1e-07" />
                                <joint name="left_ring_MCP_joint" type="hinge" axis="0.019101 0.99961 -0.020433" range="0 1.4835" actuatorfrcrange="-0.35 0.35" />
                                <geom name="left_ring_MCP_Link_visual_0" class="visual" mesh="left_ring_MCP_Link_visual_0_left_ring_MCP_Link" rgba="1 1 1 1" />
                                <geom name="left_ring_MCP_Link_collision_0" class="collision" mesh="left_ring_MCP_Link_collision_0_left_ring_MCP_Link" />
                                <body name="left_ring_PIP_Link" pos="0.00059944 0.00094917 0.046994">
                                  <inertial mass="0.0332" pos="0.00216317 0.00032218 0.01778015" fullinertia="3.1e-06 2.62e-06 2.36e-06 1e-08 -1e-07 0" />
                                  <joint name="left_ring_PIP_joint" type="hinge" axis="0.019101 0.99961 -0.020433" range="0 1.4835" actuatorfrcrange="-0.35 0.35" />
                                  <geom name="left_ring_PIP_Link_visual_0" class="visual" mesh="left_ring_PIP_Link_visual_0_left_ring_PIP_Link" rgba="1 1 1 1" />
                                  <geom name="left_ring_PIP_Link_collision_0" class="collision" mesh="left_ring_PIP_Link_collision_0_left_ring_PIP_Link" />
                                  <body name="left_ring_DIP_Link" pos="0.0012747 0.00057846 0.02949">
                                    <inertial mass="0.01" pos="-0.00048946 0.00034101 0.01619205" fullinertia="5.6e-07 5.2e-07 4e-07 0 -4e-08 0" />
                                    <joint name="left_ring_DIP_joint" type="hinge" axis="0.019101 0.99961 -0.020433" range="0 1.4835" actuatorfrcrange="-0.35 0.35" />
                                    <geom name="left_ring_DIP_Link_visual_0" class="visual" mesh="left_ring_DIP_Link_visual_0_left_ring_DIP_Link" rgba="1 1 1 1" />
                                    <geom name="left_ring_DIP_Link_collision_0" class="collision" mesh="left_ring_DIP_Link_collision_0_left_ring_DIP_Link" />
                                    <body name="left_ring_tip_Link" pos="0.0084 0.000185 0.01">
                                      <inertial mass="0.001" pos="0 0 0" diaginertia="1e-10 1e-10 1e-09" />
                                    </body>
                                  </body>
                                </body>
                              </body>
                            </body>
                            <body name="left_little_MPR_Link" pos="-0.0052198 0.036409 0.090532">
                              <inertial mass="0.013" pos="-0.00261202 0.00026358 0.0081721" diaginertia="4.2e-07 4.2e-07 4.2e-07" />
                              <joint name="left_little_MPR_joint" type="hinge" axis="-0.99836 -0.057297 0" range="-0.2618 0.2618" actuatorfrcrange="-0.35 0.35" />
                              <geom name="left_little_MPR_Link_visual_0" class="visual" mesh="left_little_MPR_Link_visual_0_left_little_MPR_Link" rgba="1 1 1 1" />
                              <geom name="left_little_MPR_Link_collision_0" class="collision" mesh="left_little_MPR_Link_collision_0_left_little_MPR_Link" />
                              <body name="left_little_MCP_Link" pos="5.6148e-05 0.00097833 0.01597">
                                <inertial mass="0.0658" pos="0.00098089 0.00138702 0.02348287" fullinertia="1.605e-05 1.574e-05 4.93e-06 1e-08 -4.3e-07 2.1e-07" />
                                <joint name="left_little_MCP_joint" type="hinge" axis="0.05719 0.99648 -0.061246" range="0 1.4835" actuatorfrcrange="-0.35 0.35" />
                                <geom name="left_little_MCP_Link_visual_0" class="visual" mesh="left_little_MCP_Link_visual_0_left_little_MCP_Link" rgba="1 1 1 1" />
                                <geom name="left_little_MCP_Link_collision_0" class="collision" mesh="left_little_MCP_Link_collision_0_left_little_MCP_Link" />
                                <body name="left_little_PIP_Link" pos="0.00074519 0.0028408 0.046916">
                                  <inertial mass="0.0332" pos="0.00221549 0.0009639 0.01775047" fullinertia="3.1e-06 2.62e-06 2.36e-06 1e-08 -1e-07 0" />
                                  <joint name="left_little_PIP_joint" type="hinge" axis="0.05719 0.99648 -0.061246" range="0 1.4835" actuatorfrcrange="-0.35 0.35" />
                                  <geom name="left_little_PIP_Link_visual_0" class="visual" mesh="left_little_PIP_Link_visual_0_left_little_PIP_Link" rgba="1 1 1 1" />
                                  <geom name="left_little_PIP_Link_collision_0" class="collision" mesh="left_little_PIP_Link_collision_0_left_little_PIP_Link" />
                                  <body name="left_little_DIP_Link" pos="0.0013649 0.0017312 0.029441">
                                    <inertial mass="0.01" pos="-0.0004382 0.00101936 0.016165" fullinertia="5.6e-07 5.2e-07 4e-07 0 -4e-08 0" />
                                    <joint name="left_little_DIP_joint" type="hinge" axis="0.05719 0.99648 -0.061246" range="0 1.4835" actuatorfrcrange="-0.35 0.35" />
                                    <geom name="left_little_DIP_Link_visual_0" class="visual" mesh="left_little_DIP_Link_visual_0_left_little_DIP_Link" rgba="1 1 1 1" />
                                    <geom name="left_little_DIP_Link_collision_0" class="collision" mesh="left_little_DIP_Link_collision_0_left_little_DIP_Link" />
                                    <body name="left_little_tip_Link" pos="0.0084 0.0012185 0.01">
                                      <inertial mass="0.001" pos="0 0 0" diaginertia="1e-10 1e-10 1e-09" />
                                    </body>
                                  </body>
                                </body>
                              </body>
                            </body>
                          </body>
                        </body>
                      </body>
                    </body>
                  </body>
                </body>
              </body>
            </body>
          </body>
        </body>
      </body>
      <body name="right_base_link" pos="0.0055 -0.10424 -0.038037" quat="0.996194825565 -0.0871542857135 0 0">
        <body name="right_arm_link1">
          <inertial mass="0.99862" pos="0.00138261246537 -0.0527123429468 -0.00121652148011" fullinertia="0.00134544913222 0.000834135586928 0.00103343870055 9.35736730946e-06 3.47820470915e-07 4.90367363186e-05" />
          <joint name="revoarm_right_joint1" type="hinge" axis="0 1 0" range="-4.1015 0.7854" actuatorfrcrange="-40 40" />
          <geom name="right_arm_link1_visual_0" class="visual" mesh="right_arm_link1_visual_0_right_arm_link1" rgba="1 1 1 1" />
          <geom name="right_arm_link1_collision_0" class="collision" mesh="right_arm_link1_collision_0_right_arm_link1" />
          <body name="right_arm_link2" pos="0 -0.06 0" quat="0.996194825565 0.0871542857135 0 0">
            <inertial mass="0.1942" pos="5.45283276618e-06 -0.000282431180944 -0.0268913421348" fullinertia="0.000382625514425 0.000369233743661 0.000207280501913 9.48679552051e-07 -2.1848535528e-06 2.31382379314e-06" />
            <joint name="revoarm_right_joint2" type="hinge" axis="-1 0 0" range="-0.1745 3.3161" actuatorfrcrange="-40 40" />
            <geom name="right_arm_link2_visual_0" class="visual" mesh="right_arm_link2_visual_0_right_arm_link2" rgba="1 1 1 1" />
            <geom name="right_arm_link2_collision_0" class="collision" mesh="right_arm_link2_collision_0_right_arm_link2" />
            <body name="right_arm_link3" pos="0 0 -0.099">
              <inertial mass="0.56897" pos="-0.000454569614792 3.12449787288e-05 -0.0666939671661" fullinertia="0.00134243655403 0.00131310898292 0.000492154320293 -1.10159695691e-06 -8.9867271334e-06 1.87663764445e-06" />
              <joint name="revoarm_right_joint3" type="hinge" axis="0 0 1" range="-3.6652 0.5236" actuatorfrcrange="-27 27" />
              <geom name="right_arm_link3_visual_0" class="visual" mesh="right_arm_link3_visual_0_right_arm_link3" rgba="1 1 1 1" />
              <geom name="right_arm_link3_collision_0" class="collision" mesh="right_arm_link3_collision_0_right_arm_link3" />
              <body name="right_arm_link4" pos="0 0 -0.121">
                <inertial mass="0.43039" pos="-7.58557077911e-06 0.000351070451149 -0.0253844870788" fullinertia="0.00047306084261 0.00047377939084 0.000275999880013 1.33236901297e-07 -1.09059920161e-06 -2.6711329621e-06" />
                <joint name="revoarm_right_joint4" type="hinge" axis="0 -1 0" range="-0.34907 2.2166" actuatorfrcrange="-27 27" />
                <geom name="right_arm_link4_visual_0" class="visual" mesh="right_arm_link4_visual_0_right_arm_link4" rgba="1 1 1 1" />
                <geom name="right_arm_link4_collision_0" class="collision" mesh="right_arm_link4_collision_0_right_arm_link4" />
                <body name="right_arm_link5" pos="0 0 -0.0635">
                  <inertial mass="0.80969" pos="0.000915076828994 1.83496866724e-05 -0.0751470282845" fullinertia="0.00182931151009 0.00183450989562 0.00056086991064 9.37494132217e-07 3.67371332139e-05 -1.6270176108e-06" />
                  <joint name="revoarm_right_joint5" type="hinge" axis="0 0 1" range="-3.1444 0.9044" actuatorfrcrange="-7 7" />
                  <geom name="right_arm_link5_visual_0" class="visual" mesh="right_arm_link5_visual_0_right_arm_link5" rgba="1 1 1 1" />
                  <geom name="right_arm_link5_collision_0" class="collision" mesh="right_arm_link5_collision_0_right_arm_link5" />
                  <body name="right_arm_link6" pos="0 0 -0.1525">
                    <inertial mass="0.31466" pos="0.000179459444033 0.00100056983205 -2.47524159457e-05" fullinertia="0.000120895453787 0.000136714381567 0.000137495744014 2.38559203994e-07 -7.17472862339e-08 2.58366532259e-07" />
                    <joint name="revoarm_right_joint6" type="hinge" axis="1 0 0" range="-0.64577 0.64577" actuatorfrcrange="-7 7" />
                    <geom name="right_arm_link6_visual_0" class="visual" mesh="right_arm_link6_visual_0_right_arm_link6" rgba="1 1 1 1" />
                    <geom name="right_arm_link6_collision_0" class="collision" mesh="right_arm_link6_collision_0_right_arm_link6" />
                    <body name="right_arm_link7" quat="0.999999529356 0.000970199847794 0 0">
                      <joint name="revoarm_right_joint7" type="hinge" axis="0 -1 0" range="-1.5708 1.5708" actuatorfrcrange="-7 7" />
                      <body name="right_connector_link" pos="0 0 -0.06054">
                        <inertial mass="0.49311" pos="-0.000112789719115 3.15409595372e-05 0.0332550987036" fullinertia="0.000363541323954 0.000228003269421 0.000267966997878 -1.86964397359e-06 -1.25245784266e-06 -5.07776634422e-06" />
                        <geom name="right_connector_link_visual_0" class="visual" mesh="right_connector_link_visual_0_right_revo3_connector" rgba="1.0 1.0 1.0 1.0" />
                        <geom name="right_connector_link_collision_0" class="collision" mesh="right_connector_link_collision_0_right_revo3_connector" />
                        <body name="right_connector_tip" quat="0.000796326710733 0 0.999999682932 0">
                          <body name="right_hand_base_link" pos="0 0 -0.0118">
                            <inertial mass="0.462" pos="-0.00345736 0.00054338 0.03983468" fullinertia="0.00080601 0.0006104 0.00041275 1.197e-05 5.633e-05 -1.657e-05" />
                            <geom name="right_hand_base_link_visual_0" class="visual" mesh="right_hand_base_link_visual_0_base_link" rgba="1 1 1 1" />
                            <geom name="right_hand_base_link_collision_0" class="collision" mesh="right_hand_base_link_collision_0_part_000" />
                            <geom name="right_hand_base_link_collision_1" class="collision" mesh="right_hand_base_link_collision_1_part_001" />
                            <geom name="right_hand_base_link_collision_2" class="collision" mesh="right_hand_base_link_collision_2_part_002" />
                            <geom name="right_hand_base_link_collision_3" class="collision" mesh="right_hand_base_link_collision_3_part_003" />
                            <geom name="right_hand_base_link_collision_4" class="collision" mesh="right_hand_base_link_collision_4_part_004" />
                            <geom name="right_hand_base_link_collision_5" class="collision" mesh="right_hand_base_link_collision_5_part_005" />
                            <geom name="right_hand_base_link_collision_6" class="collision" mesh="right_hand_base_link_collision_6_part_006" />
                            <geom name="right_hand_base_link_collision_7" class="collision" mesh="right_hand_base_link_collision_7_part_007" />
                            <geom name="right_hand_base_link_collision_8" class="collision" mesh="right_hand_base_link_collision_8_part_008" />
                            <geom name="right_hand_base_link_collision_9" class="collision" mesh="right_hand_base_link_collision_9_part_009" />
                            <geom name="right_hand_base_link_collision_10" class="collision" mesh="right_hand_base_link_collision_10_part_010" />
                            <geom name="right_hand_base_link_collision_11" class="collision" mesh="right_hand_base_link_collision_11_part_011" />
                            <geom name="right_hand_base_link_collision_12" class="collision" mesh="right_hand_base_link_collision_12_part_012" />
                            <geom name="right_hand_base_link_collision_13" class="collision" mesh="right_hand_base_link_collision_13_part_013" />
                            <geom name="right_hand_base_link_collision_14" class="collision" mesh="right_hand_base_link_collision_14_part_014" />
                            <geom name="right_hand_base_link_collision_15" class="collision" mesh="right_hand_base_link_collision_15_part_015" />
                            <geom name="right_hand_base_link_collision_16" class="collision" mesh="right_hand_base_link_collision_16_part_016" />
                            <geom name="right_hand_base_link_collision_17" class="collision" mesh="right_hand_base_link_collision_17_part_017" />
                            <geom name="right_hand_base_link_collision_18" class="collision" mesh="right_hand_base_link_collision_18_part_018" />
                            <geom name="right_hand_base_link_collision_19" class="collision" mesh="right_hand_base_link_collision_19_part_019" />
                            <geom name="right_hand_base_link_collision_20" class="collision" mesh="right_hand_base_link_collision_20_part_020" />
                            <geom name="right_hand_base_link_collision_21" class="collision" mesh="right_hand_base_link_collision_21_part_021" />
                            <geom name="right_hand_base_link_collision_22" class="collision" mesh="right_hand_base_link_collision_22_part_022" />
                            <geom name="right_hand_base_link_collision_23" class="collision" mesh="right_hand_base_link_collision_23_part_023" />
                            <geom name="right_hand_base_link_collision_24" class="collision" mesh="right_hand_base_link_collision_24_part_024" />
                            <geom name="right_hand_base_link_collision_25" class="collision" mesh="right_hand_base_link_collision_25_part_025" />
                            <geom name="right_hand_base_link_collision_26" class="collision" mesh="right_hand_base_link_collision_26_part_026" />
                            <geom name="right_hand_base_link_collision_27" class="collision" mesh="right_hand_base_link_collision_27_part_027" />
                            <body name="right_palm" pos="0.0155 0 0.055" />
                            <body name="right_thumb_CMP_Link" pos="0.002 0.0195 0.051993">
                              <inertial mass="0.026" pos="0 0 0" diaginertia="2.03e-06 2.29e-06 2.22e-06" />
                              <joint name="right_thumb_CMP_joint" type="hinge" axis="0 0 -1" range="0 1.9199" actuatorfrcrange="-0.35 0.35" />
                              <geom name="right_thumb_CMP_Link_visual_0" class="visual" mesh="right_thumb_CMP_Link_visual_0_right_thumb_CMP_Link" rgba="1 1 1 1" />
                              <geom name="right_thumb_CMP_Link_collision_0" class="collision" mesh="right_thumb_CMP_Link_collision_0_right_thumb_CMP_Link" />
                              <body name="right_thumb_CMR_Link" pos="0 0.0095 0" quat="0.707388269167 0 0.706825181105 0">
                                <inertial mass="0.012" pos="0 0.00601571 -0.00128638" fullinertia="5.7e-07 9.5e-07 9.3e-07 0 0 2e-08" />
                                <joint name="right_thumb_CMR_joint" type="hinge" axis="0 -1 0" range="0 2.0071" actuatorfrcrange="-0.35 0.35" />
                                <geom name="right_thumb_CMR_Link_visual_0" class="visual" mesh="right_thumb_CMR_Link_visual_0_right_thumb_CMR_Link" rgba="1 1 1 1" />
                                <geom name="right_thumb_CMR_Link_collision_0" class="collision" mesh="right_thumb_CMR_Link_collision_0_right_thumb_CMR_Link" />
                                <body name="right_thumb_MCP_Link" pos="0 0.0125 0">
                                  <inertial mass="0.067" pos="1.27e-05 0.02200879 -0.00233775" fullinertia="1.46e-05 6.6e-06 1.422e-05 -2e-08 0 8e-07" />
                                  <joint name="right_thumb_MCP_joint" type="hinge" axis="1 0 0" range="0 0.8727" actuatorfrcrange="-0.35 0.35" />
                                  <geom name="right_thumb_MCP_Link_visual_0" class="visual" mesh="right_thumb_MCP_Link_visual_0_right_thumb_MCP_Link" rgba="1 1 1 1" />
                                  <geom name="right_thumb_MCP_Link_collision_0" class="collision" mesh="right_thumb_MCP_Link_collision_0_right_thumb_MCP_Link" />
                                  <body name="right_thumb_PIP_Link" pos="0.0001 0.042087 -0.0013667">
                                    <inertial mass="0.035" pos="2.72468422551e-05 0.0196639755384 -0.000959024619273" fullinertia="3.31e-06 2.69e-06 4.07e-06 -3e-08 0 -3e-08" />
                                    <joint name="right_thumb_PIP_joint" type="hinge" axis="1 0 0" range="0 1.4835" actuatorfrcrange="-0.35 0.35" />
                                    <geom name="right_thumb_PIP_Link_visual_0" class="visual" mesh="right_thumb_PIP_Link_visual_0_right_thumb_PIP_Link" rgba="1 1 1 1" />
                                    <geom name="right_thumb_PIP_Link_collision_0" class="collision" mesh="right_thumb_PIP_Link_collision_0_right_thumb_PIP_Link" />
                                    <body name="right_thumb_DIP_Link" pos="0.000125 0.032 -0.00052077">
                                      <inertial mass="0.01" pos="-6.365e-05 0.015338 -0.00158245" fullinertia="1.49e-06 9.6e-07 1.55e-06 2e-08 0 -2.4e-07" />
                                      <joint name="right_thumb_DIP_joint" type="hinge" axis="1 0 0" range="0 1.4835" actuatorfrcrange="-0.35 0.35" />
                                      <geom name="right_thumb_DIP_Link_visual_0" class="visual" mesh="right_thumb_DIP_Link_visual_0_right_thumb_DIP_Link" rgba="1 1 1 1" />
                                      <geom name="right_thumb_DIP_Link_collision_0" class="collision" mesh="right_thumb_DIP_Link_collision_0_right_thumb_DIP_Link" />
                                      <body name="right_thumb_tip_Link" pos="0 0.01 0.0098">
                                        <inertial mass="0.001" pos="0 0 0" diaginertia="1e-10 1e-10 1e-09" />
                                      </body>
                                    </body>
                                  </body>
                                </body>
                              </body>
                            </body>
                            <body name="right_index_MPR_Link" pos="-0.005442 0.036871 0.097822">
                              <inertial mass="0.013" pos="-0.00223218743936 0.000719586142971 0.00541673485893" diaginertia="4.2e-07 4.2e-07 4.2e-07" />
                              <joint name="right_index_MPR_joint" type="hinge" axis="0.99836 -0.057297 0" range="-0.2618 0.2618" actuatorfrcrange="-0.35 0.35" />
                              <geom name="right_index_MPR_Link_visual_0" class="visual" mesh="right_index_MPR_Link_visual_0_right_index_MPR_Link" rgba="1 1 1 1" />
                              <geom name="right_index_MPR_Link_collision_0" class="collision" mesh="right_index_MPR_Link_collision_0_right_index_MPR_Link" />
                              <body name="right_index_MCP_Link" pos="5.6148e-05 0.00097833 0.01597">
                                <inertial mass="0.0658" pos="-2.4085643947e-05 0.00140938308495 0.0229088413323" fullinertia="1.192e-05 1.164e-05 3.76e-06 -1e-08 0 -4.9e-07" />
                                <joint name="right_index_MCP_joint" type="hinge" axis="0.05719 0.99648 -0.061246" range="0 1.4835" actuatorfrcrange="-0.35 0.35" />
                                <geom name="right_index_MCP_Link_visual_0" class="visual" mesh="right_index_MCP_Link_visual_0_right_index_MCP_Link" rgba="1 1 1 1" />
                                <geom name="right_index_MCP_Link_collision_0" class="collision" mesh="right_index_MCP_Link_collision_0_right_index_MCP_Link" />
                                <body name="right_index_PIP_Link" pos="0.00074566 0.0028407 0.046916">
                                  <inertial mass="0.0332" pos="0.000370302095447 0.00104638125778 0.0182492789782" fullinertia="2.52e-06 2.33e-06 1.84e-06 -1e-08 -3e-08 -3e-08" />
                                  <joint name="right_index_PIP_joint" type="hinge" axis="0.05719 0.99648 -0.061245" range="0 1.4835" actuatorfrcrange="-0.35 0.35" />
                                  <geom name="right_index_PIP_Link_visual_0" class="visual" mesh="right_index_PIP_Link_visual_0_right_index_PIP_Link" rgba="1 1 1 1" />
                                  <geom name="right_index_PIP_Link_collision_0" class="collision" mesh="right_index_PIP_Link_collision_0_right_index_PIP_Link" />
                                  <body name="right_index_DIP_Link" pos="0.0013627 0.0017313 0.029441">
                                    <inertial mass="0.01" pos="-0.000421264678793 0.000956967726906 0.0155551999344" fullinertia="6.4e-07 5.7e-07 4.8e-07 0 3e-08 0" />
                                    <joint name="right_index_DIP_joint" type="hinge" axis="0.05719 0.99648 -0.061255" range="0 1.4835" actuatorfrcrange="-0.35 0.35" />
                                    <geom name="right_index_DIP_Link_visual_0" class="visual" mesh="right_index_DIP_Link_visual_0_right_index_DIP_Link" rgba="1 1 1 1" />
                                    <geom name="right_index_DIP_Link_collision_0" class="collision" mesh="right_index_DIP_Link_collision_0_right_index_DIP_Link" />
                                    <body name="right_index_tip_Link" pos="0.0084 0.0005 0.01">
                                      <inertial mass="0.001" pos="0 0 0" diaginertia="1e-10 1e-10 1e-09" />
                                    </body>
                                  </body>
                                </body>
                              </body>
                            </body>
                            <body name="right_middle_MPR_Link" pos="-0.0060223 0.012496 0.10793">
                              <inertial mass="0.013" pos="-0.00226228401898 0.000412100759089 0.00543632642357" diaginertia="4.2e-07 4.2e-07 4.2e-07" />
                              <joint name="right_middle_MPR_joint" type="hinge" axis="0.99982 -0.019105 0" range="-0.2618 0.2618" actuatorfrcrange="-0.35 0.35" />
                              <geom name="right_middle_MPR_Link_visual_0" class="visual" mesh="right_middle_MPR_Link_visual_0_right_middle_MPR_Link" rgba="1 1 1 1" />
                              <geom name="right_middle_MPR_Link_collision_0" class="collision" mesh="right_middle_MPR_Link_collision_0_right_middle_MPR_Link" />
                              <body name="right_middle_MCP_Link" pos="0 0.00032687 0.015997">
                                <inertial mass="0.0658" pos="-9.58184291929e-05 0.000470872880033 0.0229471333965" fullinertia="1.192e-05 1.167e-05 3.74e-06 3e-08 3e-08 -1.4e-07" />
                                <joint name="right_middle_MCP_joint" type="hinge" axis="0.019101 0.99961 -0.020433" range="0 1.4835" actuatorfrcrange="-0.35 0.35" />
                                <geom name="right_middle_MCP_Link_visual_0" class="visual" mesh="right_middle_MCP_Link_visual_0_right_middle_MCP_Link" rgba="1 1 1 1" />
                                <geom name="right_middle_MCP_Link_collision_0" class="collision" mesh="right_middle_MCP_Link_collision_0_right_middle_MCP_Link" />
                                <body name="right_middle_PIP_Link" pos="0.00059991 0.00094912 0.046994">
                                  <inertial mass="0.0332" pos="0.000315792331514 0.00031374080626 0.0182775844652" fullinertia="2.52e-06 2.33e-06 1.83e-06 0 -3e-08 0" />
                                  <joint name="right_middle_PIP_joint" type="hinge" axis="0.019101 0.99961 -0.020432" range="0 1.4835" actuatorfrcrange="-0.35 0.35" />
                                  <geom name="right_middle_PIP_Link_visual_0" class="visual" mesh="right_middle_PIP_Link_visual_0_right_middle_PIP_Link" rgba="1 1 1 1" />
                                  <geom name="right_middle_PIP_Link_collision_0" class="collision" mesh="right_middle_PIP_Link_collision_0_right_middle_PIP_Link" />
                                  <body name="right_middle_DIP_Link" pos="0.0012725 0.00057847 0.02949">
                                    <inertial mass="0.01" pos="-0.000469437908234 0.000304801770128 0.0155807548985" fullinertia="6.4e-07 5.7e-07 4.8e-07 0 3e-08 0" />
                                    <joint name="right_middle_DIP_joint" type="hinge" axis="0.019101 0.99961 -0.020443" range="0 1.4835" actuatorfrcrange="-0.35 0.35" />
                                    <geom name="right_middle_DIP_Link_visual_0" class="visual" mesh="right_middle_DIP_Link_visual_0_right_middle_DIP_Link" rgba="1 1 1 1" />
                                    <geom name="right_middle_DIP_Link_collision_0" class="collision" mesh="right_middle_DIP_Link_collision_0_right_middle_DIP_Link" />
                                    <body name="right_middle_tip_Link" pos="0.0084 0 0.01">
                                      <inertial mass="0.001" pos="0 0 0" diaginertia="1e-10 1e-10 1e-09" />
                                    </body>
                                  </body>
                                </body>
                              </body>
                            </body>
                            <body name="right_ring_MPR_Link" pos="-0.0062466 -0.012415 0.10384">
                              <inertial mass="0.013" pos="-0.00222213402037 0.000103943894862 0.00544684832541" diaginertia="4.2e-07 4.2e-07 4.2e-07" />
                              <joint name="right_ring_MPR_joint" type="hinge" axis="0.99982 0.019105 0" range="-0.2618 0.2618" actuatorfrcrange="-0.35 0.35" />
                              <geom name="right_ring_MPR_Link_visual_0" class="visual" mesh="right_ring_MPR_Link_visual_0_right_ring_MPR_Link" rgba="1 1 1 1" />
                              <geom name="right_ring_MPR_Link_collision_0" class="collision" mesh="right_ring_MPR_Link_collision_0_right_ring_MPR_Link" />
                              <body name="right_ring_MCP_Link" pos="0 -0.00032687 0.015997">
                                <inertial mass="0.0658" pos="-4.58227668414e-05 -0.000469969862117 0.0229471407955" fullinertia="1.192e-05 1.166e-05 3.74e-06 0 3e-08 1.6e-07" />
                                <joint name="right_ring_MCP_joint" type="hinge" axis="-0.019101 0.99961 0.020433" range="0 1.4835" actuatorfrcrange="-0.35 0.35" />
                                <geom name="right_ring_MCP_Link_visual_0" class="visual" mesh="right_ring_MCP_Link_visual_0_right_ring_MCP_Link" rgba="1 1 1 1" />
                                <geom name="right_ring_MCP_Link_collision_0" class="collision" mesh="right_ring_MCP_Link_collision_0_right_ring_MCP_Link" />
                                <body name="right_ring_PIP_Link" pos="0.0006499 -0.00094821 0.046994">
                                  <inertial mass="0.0332" pos="0.000317847616006 -0.000421387078381 0.0182753825948" fullinertia="2.52e-06 2.33e-06 1.83e-06 0 -3e-08 0" />
                                  <joint name="right_ring_PIP_joint" type="hinge" axis="-0.019101 0.99961 0.020434" range="0 1.4835" actuatorfrcrange="-0.35 0.35" />
                                  <geom name="right_ring_PIP_Link_visual_0" class="visual" mesh="right_ring_PIP_Link_visual_0_right_ring_PIP_Link" rgba="1 1 1 1" />
                                  <geom name="right_ring_PIP_Link_collision_0" class="collision" mesh="right_ring_PIP_Link_collision_0_right_ring_PIP_Link" />
                                  <body name="right_ring_DIP_Link" pos="0.0012725 -0.00057823 0.02949">
                                    <inertial mass="0.01" pos="-0.000468578428745 -0.000349896977336 0.0155798440444" fullinertia="6.4e-07 5.7e-07 4.8e-07 0 3e-08 0" />
                                    <joint name="right_ring_DIP_joint" type="hinge" axis="-0.019101 0.99961 0.020424" range="0 1.4835" actuatorfrcrange="-0.35 0.35" />
                                    <geom name="right_ring_DIP_Link_visual_0" class="visual" mesh="right_ring_DIP_Link_visual_0_right_ring_DIP_Link" rgba="1 1 1 1" />
                                    <geom name="right_ring_DIP_Link_collision_0" class="collision" mesh="right_ring_DIP_Link_collision_0_right_ring_DIP_Link" />
                                    <body name="right_ring_tip_Link" pos="0.0084 -0.000185 0.01">
                                      <inertial mass="0.001" pos="0 0 0" diaginertia="1e-10 1e-10 1e-09" />
                                    </body>
                                  </body>
                                </body>
                              </body>
                            </body>
                            <body name="right_little_MPR_Link" pos="-0.0052697 -0.036412 0.090532">
                              <inertial mass="0.013" pos="-0.002211739492 -0.000203240251326 0.00544829709322" diaginertia="4.2e-07 4.2e-07 4.2e-07" />
                              <joint name="right_little_MPR_joint" type="hinge" axis="0.99836 0.057297 0" range="-0.2618 0.2618" actuatorfrcrange="-0.35 0.35" />
                              <geom name="right_little_MPR_Link_visual_0" class="visual" mesh="right_little_MPR_Link_visual_0_right_little_MPR_Link" rgba="1 1 1 1" />
                              <geom name="right_little_MPR_Link_collision_0" class="collision" mesh="right_little_MPR_Link_collision_0_right_little_MPR_Link" />
                              <body name="right_little_MCP_Link" pos="5.6148e-05 -0.00097833 0.01597">
                                <inertial mass="0.0658" pos="2.58235094345e-05 -0.00140652628093 0.0229088448634" fullinertia="1.192e-05 1.164e-05 3.76e-06 1e-08 0 4.9e-07" />
                                <joint name="right_little_MCP_joint" type="hinge" axis="-0.05719 0.99648 0.061246" range="0 1.4835" actuatorfrcrange="-0.35 0.35" />
                                <geom name="right_little_MCP_Link_visual_0" class="visual" mesh="right_little_MCP_Link_visual_0_right_little_MCP_Link" rgba="1 1 1 1" />
                                <geom name="right_little_MCP_Link_collision_0" class="collision" mesh="right_little_MCP_Link_collision_0_right_little_MCP_Link" />
                                <body name="right_little_PIP_Link" pos="0.00079558 -0.0028379 0.046916">
                                  <inertial mass="0.0332" pos="0.000376458559588 -0.00115364512767 0.0182426815291" fullinertia="2.52e-06 2.33e-06 1.84e-06 1e-08 -3e-08 3e-08" />
                                  <joint name="right_little_PIP_joint" type="hinge" axis="-0.05719 0.99648 0.061247" range="0 1.4835" actuatorfrcrange="-0.35 0.35" />
                                  <geom name="right_little_PIP_Link_visual_0" class="visual" mesh="right_little_PIP_Link_visual_0_right_little_PIP_Link" rgba="1 1 1 1" />
                                  <geom name="right_little_PIP_Link_collision_0" class="collision" mesh="right_little_PIP_Link_collision_0_right_little_PIP_Link" />
                                  <body name="right_little_DIP_Link" pos="0.0013627 -0.0017313 0.029441">
                                    <inertial mass="0.01" pos="-0.000418722273889 -0.0010015814001 0.0155525044851" fullinertia="6.4e-07 5.7e-07 4.8e-07 0 3e-08 0" />
                                    <joint name="right_little_DIP_joint" type="hinge" axis="-0.057189 0.99648 0.061237" range="0 1.4835" actuatorfrcrange="-0.35 0.35" />
                                    <geom name="right_little_DIP_Link_visual_0" class="visual" mesh="right_little_DIP_Link_visual_0_right_little_DIP_Link" rgba="1 1 1 1" />
                                    <geom name="right_little_DIP_Link_collision_0" class="collision" mesh="right_little_DIP_Link_collision_0_right_little_DIP_Link" />
                                    <body name="right_little_tip_Link" pos="0.0084 -0.0012185 0.01">
                                      <inertial mass="0.001" pos="0 0 0" diaginertia="1e-10 1e-10 1e-09" />
                                    </body>
                                  </body>
                                </body>
                              </body>
                            </body>
                          </body>
                        </body>
                      </body>
                    </body>
                  </body>
                </body>
              </body>
            </body>
          </body>
        </body>
      </body>
    </body>
  </worldbody>
</mujoco>